Workbook

Sheet CCE Calculation
A1: CONSTANT COMPOSITION EXPANSION (CCE) — PVT LAB CALCULATION SHEET v3 Final
B4: LAB MEASUREMENT INPUTS | H4: AUTO-CALCULATED PARAMETERS | V4: Macro-Ready Controls (1st Tab)
B5: Reservoir Pressure (psig) | D5: 3938.73 | E5: ← INPUT | V5: Error Limit (%) | W5: 2 | Z5: Start Pressure (psig) | AA5: =ROUND(B22,0) -> 4029 | AB5: =MATCH(AA5,B16:B55,-1)+15 -> 22
B6: Temperature (°F): | D6: 256 | H6: Volume at Working Pressure (cc) | J6: =C16 -> 94.088229 | V6: i value | W6: 0 | Z6: End Pressure (psig) | AA6: =ROUND(B34,0) -> 1175 | AB6: =MATCH(AA6,B16:B55,-1)+15 -> 33
B7: Working Pressure (psig): | D7: 7014.73 | H7: Sample Mass (g) | J7: =D8*J6 -> 68.560211 | V7: j value | W7: 0 | Z7: Dynamic Mean Comp (×10⁻⁶ psi⁻¹) | AA7: =IF(OR(AA5="",AA6="",AB5="",AB6="",AB5=AB6),"",((INDEX(D:D,AB6)-INDEX(D:D,AB5))/((INDEX(D:D,AB5)+INDEX(D:D,AB6))/2)*1/(INDEX(B:B,AB5)-INDEX(B:B,AB6))*1000000)) -> 12.25064
B8: Measured HPHT Density (g/cm³): | D8: 0.72868 | H8: V_sat at Bubble Point (cc) | J8: =INDEX(C16:C55,$D$10) -> 100 | V8: k value | W8: 0 | Z8: Reservoir Pressure (psig) | AA8: =D5 -> 3938.73
B9: Visual Bubble Point (psig): | D9: 1155.73 | H9: Psat from Data (psig) | J9: =INDEX(B16:B55,$D$10) -> 1155.73
B10: Bubble Point Step #: | D10: 20 | H10: Density at Psat (g/cm³) | J10: =J7/J8 -> 0.68560211 | V10: Macro Button Area | W10: OPEN-SAFE version: macro-ready layout only. Real VBA is not embedded. Use this workbook to finalize structure and later attach VBA in Excel if needed.
H11: Pb Check |Visual−Data| | J11: =ABS(D9-J9) -> 0 | K11: =IF(J11<10,"✓ OK","⚠ CHECK") -> ✓ OK
A14: CCE DATA TABLE | O14: PVTsim Comparison & Final Accepted Values | V14: Graphical representation and tuning | AF14: Graphical representation and tuning
A15: Step | B15: Pressure (psig) | C15: Volume (cc) | D15: Relative Volume | E15: Density (g/cm³) | F15: Inst. Compressibility (×10⁻⁶ psi⁻¹) | G15: Y-Function | H15: Phase | I15: Fitted Value | J15: Residual | K15: Deviation (%) | L15: QC Flag | O15: Step | P15: Pressure | Q15: PVTsim RelVol | R15: PVTsim Density | S15: PVTsim Y | T15: PVTsim Inst Comp | U15: Measured RelVol | V15: Upper Limit | W15: Lower Limit | X15: Out of Band? | Y15: Suggested ΔV (i/j/k)
A16: 1 | B16: 7014.73 | C16: 94.088229 | D16: =C16/$J$8 -> 0.94088229 | E16: =IF(A16<=$D$10,$J$7/C16,"") -> 0.72868 | F16: =IF(A16<=$D$10,(C17-C16)/C16/(B16-B17)*1000000,"") -> 7.6804854 | G16: =IF(A16>$D$10,($J$9-B16)/(B16*(D16-1)),"") | H16: =IF(A16<$D$10,"Single Phase",IF(A16=$D$10,"Bubble Point","Two Phase")) -> Single Phase | I16: =IF(A16<=$D$10,'QC Protocol'!$C$7+'QC Protocol'!$C$8*B16+'QC Protocol'!$C$9*B16^2+'QC Protocol'!$C$10*B16^3,'QC Protocol'!$C$18+'QC Protocol'!$C$19*B16+'QC Protocol'!$C$20*B16^2) -> 0.94080051 | J16: =IF(A16<=$D$10,D16-I16,IF(A16>$D$10,G16-I16,"")) -> 8.1784426e-05 | K16: =IF(OR(J16="",J16=0),"",IF(A16<=$D$10,ABS(J16/D16)*100,ABS(J16/G16)*100)) -> 0.0086923122 | L16: =IF(K16="","",IF(A16<=$D$10,IF(K16<'QC Protocol'!$C$26,"PASS",IF(K16<'QC Protocol'!$C$27,"WARN","FAIL")),IF(K16<'QC Protocol'!$C$28,"PASS",IF(K16<'QC Protocol'!$C$29,"WARN","FAIL")))) -> PASS | O16: =A16 -> 1 | P16: =B16 -> 7014.73 | Q16: =D16 -> 0.94088229 | R16: =E16 -> 0.72868 | S16: =G16 | T16: =F16 -> 7.6804854 | U16: =D16 -> 0.94088229 | V16: =IF(Q16="","",Q16*(1+$W$5/100)) -> 0.95969994 | W16: =IF(Q16="","",Q16*(1-$W$5/100)) -> 0.92206464 | X16: =IF(OR(U16="",V16="",W16=""),"",IF(OR(U16>V16,U16<W16),"OUT","OK")) -> OK | Y16: =IF(X16<>"OUT","",($W$6+$W$7*(P16/$D$7)+$W$8*(P16/$D$7)^2))
A17: 2 | B17: 6525.9808 | C17: 94.44142 | D17: =C17/$J$8 -> 0.9444142 | E17: =IF(A17<=$D$10,$J$7/C17,"") -> 0.72595489 | F17: =IF(A17<=$D$10,(C18-C16)/C17/(B16-B18)*1000000,"") -> 7.8223487 | G17: =IF(A17>$D$10,($J$9-B17)/(B17*(D17-1)),"") | H17: =IF(A17<$D$10,"Single Phase",IF(A17=$D$10,"Bubble Point","Two Phase")) -> Single Phase | I17: =IF(A17<=$D$10,'QC Protocol'!$C$7+'QC Protocol'!$C$8*B17+'QC Protocol'!$C$9*B17^2+'QC Protocol'!$C$10*B17^3,'QC Protocol'!$C$18+'QC Protocol'!$C$19*B17+'QC Protocol'!$C$20*B17^2) -> 0.94445797 | J17: =IF(A17<=$D$10,D17-I17,IF(A17>$D$10,G17-I17,"")) -> -4.3768999e-05 | K17: =IF(OR(J17="",J17=0),"",IF(A17<=$D$10,ABS(J17/D17)*100,ABS(J17/G17)*100)) -> 0.004634513 | L17: =IF(K17="","",IF(A17<=$D$10,IF(K17<'QC Protocol'!$C$26,"PASS",IF(K17<'QC Protocol'!$C$27,"WARN","FAIL")),IF(K17<'QC Protocol'!$C$28,"PASS",IF(K17<'QC Protocol'!$C$29,"WARN","FAIL")))) -> PASS | O17: =A17 -> 2 | P17: =B17 -> 6525.9808 | Q17: =D17 -> 0.9444142 | R17: =E17 -> 0.72595489 | S17: =G17 | T17: =F17 -> 7.8223487 | U17: =D17 -> 0.9444142 | V17: =IF(Q17="","",Q17*(1+$W$5/100)) -> 0.96330249 | W17: =IF(Q17="","",Q17*(1-$W$5/100)) -> 0.92552592 | X17: =IF(OR(U17="",V17="",W17=""),"",IF(OR(U17>V17,U17<W17),"OUT","OK")) -> OK | Y17: =IF(X17<>"OUT","",($W$6+$W$7*(P17/$D$7)+$W$8*(P17/$D$7)^2))
A18: 3 | B18: 6029.4923 | C18: 94.816077 | D18: =C18/$J$8 -> 0.94816077 | E18: =IF(A18<=$D$10,$J$7/C18,"") -> 0.72308635 | F18: =IF(A18<=$D$10,(C19-C17)/C18/(B17-B19)*1000000,"") -> 8.1481553 | G18: =IF(A18>$D$10,($J$9-B18)/(B18*(D18-1)),"") | H18: =IF(A18<$D$10,"Single Phase",IF(A18=$D$10,"Bubble Point","Two Phase")) -> Single Phase | I18: =IF(A18<=$D$10,'QC Protocol'!$C$7+'QC Protocol'!$C$8*B18+'QC Protocol'!$C$9*B18^2+'QC Protocol'!$C$10*B18^3,'QC Protocol'!$C$18+'QC Protocol'!$C$19*B18+'QC Protocol'!$C$20*B18^2) -> 0.94824046 | J18: =IF(A18<=$D$10,D18-I18,IF(A18>$D$10,G18-I18,"")) -> -7.9694491e-05 | K18: =IF(OR(J18="",J18=0),"",IF(A18<=$D$10,ABS(J18/D18)*100,ABS(J18/G18)*100)) -> 0.0084051664 | L18: =IF(K18="","",IF(A18<=$D$10,IF(K18<'QC Protocol'!$C$26,"PASS",IF(K18<'QC Protocol'!$C$27,"WARN","FAIL")),IF(K18<'QC Protocol'!$C$28,"PASS",IF(K18<'QC Protocol'!$C$29,"WARN","FAIL")))) -> PASS | O18: =A18 -> 3 | P18: =B18 -> 6029.4923 | Q18: =D18 -> 0.94816077 | R18: =E18 -> 0.72308635 | S18: =G18 | T18: =F18 -> 8.1481553 | U18: =D18 -> 0.94816077 | V18: =IF(Q18="","",Q18*(1+$W$5/100)) -> 0.96712399 | W18: =IF(Q18="","",Q18*(1-$W$5/100)) -> 0.92919756 | X18: =IF(OR(U18="",V18="",W18=""),"",IF(OR(U18>V18,U18<W18),"OUT","OK")) -> OK | Y18: =IF(X18<>"OUT","",($W$6+$W$7*(P18/$D$7)+$W$8*(P18/$D$7)^2)) | AF18: Macro button to adjust the values using ijk Value
A19: 4 | B19: 5531.1266 | C19: 95.210021 | D19: =C19/$J$8 -> 0.95210021 | E19: =IF(A19<=$D$10,$J$7/C19,"") -> 0.72009448 | F19: =IF(A19<=$D$10,(C20-C18)/C19/(B18-B20)*1000000,"") -> 8.5164101 | G19: =IF(A19>$D$10,($J$9-B19)/(B19*(D19-1)),"") | H19: =IF(A19<$D$10,"Single Phase",IF(A19=$D$10,"Bubble Point","Two Phase")) -> Single Phase | I19: =IF(A19<=$D$10,'QC Protocol'!$C$7+'QC Protocol'!$C$8*B19+'QC Protocol'!$C$9*B19^2+'QC Protocol'!$C$10*B19^3,'QC Protocol'!$C$18+'QC Protocol'!$C$19*B19+'QC Protocol'!$C$20*B19^2) -> 0.95215804 | J19: =IF(A19<=$D$10,D19-I19,IF(A19>$D$10,G19-I19,"")) -> -5.7829969e-05 | K19: =IF(OR(J19="",J19=0),"",IF(A19<=$D$10,ABS(J19/D19)*100,ABS(J19/G19)*100)) -> 0.0060739372 | L19: =IF(K19="","",IF(A19<=$D$10,IF(K19<'QC Protocol'!$C$26,"PASS",IF(K19<'QC Protocol'!$C$27,"WARN","FAIL")),IF(K19<'QC Protocol'!$C$28,"PASS",IF(K19<'QC Protocol'!$C$29,"WARN","FAIL")))) -> PASS | O19: =A19 -> 4 | P19: =B19 -> 5531.1266 | Q19: =D19 -> 0.95210021 | R19: =E19 -> 0.72009448 | S19: =G19 | T19: =F19 -> 8.5164101 | U19: =D19 -> 0.95210021 | V19: =IF(Q19="","",Q19*(1+$W$5/100)) -> 0.97114221 | W19: =IF(Q19="","",Q19*(1-$W$5/100)) -> 0.93305821 | X19: =IF(OR(U19="",V19="",W19=""),"",IF(OR(U19>V19,U19<W19),"OUT","OK")) -> OK | Y19: =IF(X19<>"OUT","",($W$6+$W$7*(P19/$D$7)+$W$8*(P19/$D$7)^2))
A20: 5 | B20: 5026.7011 | C20: 95.629188 | D20: =C20/$J$8 -> 0.95629188 | E20: =IF(A20<=$D$10,$J$7/C20,"") -> 0.71693813 | F20: =IF(A20<=$D$10,(C21-C19)/C20/(B19-B21)*1000000,"") -> 8.9279778 | G20: =IF(A20>$D$10,($J$9-B20)/(B20*(D20-1)),"") | H20: =IF(A20<$D$10,"Single Phase",IF(A20=$D$10,"Bubble Point","Two Phase")) -> Single Phase | I20: =IF(A20<=$D$10,'QC Protocol'!$C$7+'QC Protocol'!$C$8*B20+'QC Protocol'!$C$9*B20^2+'QC Protocol'!$C$10*B20^3,'QC Protocol'!$C$18+'QC Protocol'!$C$19*B20+'QC Protocol'!$C$20*B20^2) -> 0.95630087 | J20: =IF(A20<=$D$10,D20-I20,IF(A20>$D$10,G20-I20,"")) -> -8.9902605e-06 | K20: =IF(OR(J20="",J20=0),"",IF(A20<=$D$10,ABS(J20/D20)*100,ABS(J20/G20)*100)) -> 0.00094011679 | L20: =IF(K20="","",IF(A20<=$D$10,IF(K20<'QC Protocol'!$C$26,"PASS",IF(K20<'QC Protocol'!$C$27,"WARN","FAIL")),IF(K20<'QC Protocol'!$C$28,"PASS",IF(K20<'QC Protocol'!$C$29,"WARN","FAIL")))) -> PASS | O20: =A20 -> 5 | P20: =B20 -> 5026.7011 | Q20: =D20 -> 0.95629188 | R20: =E20 -> 0.71693813 | S20: =G20 | T20: =F20 -> 8.9279778 | U20: =D20 -> 0.95629188 | V20: =IF(Q20="","",Q20*(1+$W$5/100)) -> 0.97541772 | W20: =IF(Q20="","",Q20*(1-$W$5/100)) -> 0.93716604 | X20: =IF(OR(U20="",V20="",W20=""),"",IF(OR(U20>V20,U20<W20),"OUT","OK")) -> OK | Y20: =IF(X20<>"OUT","",($W$6+$W$7*(P20/$D$7)+$W$8*(P20/$D$7)^2))
A21: 6 | B21: 4527.747 | C21: 96.066682 | D21: =C21/$J$8 -> 0.96066682 | E21: =IF(A21<=$D$10,$J$7/C21,"") -> 0.71367314 | F21: =IF(A21<=$D$10,(C22-C20)/C21/(B20-B22)*1000000,"") -> 9.3980839 | G21: =IF(A21>$D$10,($J$9-B21)/(B21*(D21-1)),"") | H21: =IF(A21<$D$10,"Single Phase",IF(A21=$D$10,"Bubble Point","Two Phase")) -> Single Phase | I21: =IF(A21<=$D$10,'QC Protocol'!$C$7+'QC Protocol'!$C$8*B21+'QC Protocol'!$C$9*B21^2+'QC Protocol'!$C$10*B21^3,'QC Protocol'!$C$18+'QC Protocol'!$C$19*B21+'QC Protocol'!$C$20*B21^2) -> 0.96062848 | J21: =IF(A21<=$D$10,D21-I21,IF(A21>$D$10,G21-I21,"")) -> 3.8332519e-05 | K21: =IF(OR(J21="",J21=0),"",IF(A21<=$D$10,ABS(J21/D21)*100,ABS(J21/G21)*100)) -> 0.0039901991 | L21: =IF(K21="","",IF(A21<=$D$10,IF(K21<'QC Protocol'!$C$26,"PASS",IF(K21<'QC Protocol'!$C$27,"WARN","FAIL")),IF(K21<'QC Protocol'!$C$28,"PASS",IF(K21<'QC Protocol'!$C$29,"WARN","FAIL")))) -> PASS | O21: =A21 -> 6 | P21: =B21 -> 4527.747 | Q21: =D21 -> 0.96066682 | R21: =E21 -> 0.71367314 | S21: =G21 | T21: =F21 -> 9.3980839 | U21: =D21 -> 0.96066682 | V21: =IF(Q21="","",Q21*(1+$W$5/100)) -> 0.97988015 | W21: =IF(Q21="","",Q21*(1-$W$5/100)) -> 0.94145348 | X21: =IF(OR(U21="",V21="",W21=""),"",IF(OR(U21>V21,U21<W21),"OUT","OK")) -> OK | Y21: =IF(X21<>"OUT","",($W$6+$W$7*(P21/$D$7)+$W$8*(P21/$D$7)^2))
A22: 7 | B22: 4029.4572 | C22: 96.529542 | D22: =C22/$J$8 -> 0.96529542 | E22: =IF(A22<=$D$10,$J$7/C22,"") -> 0.71025107 | F22: =IF(A22<=$D$10,(C23-C21)/C22/(B21-B23)*1000000,"") -> 9.6773324 | G22: =IF(A22>$D$10,($J$9-B22)/(B22*(D22-1)),"") | H22: =IF(A22<$D$10,"Single Phase",IF(A22=$D$10,"Bubble Point","Two Phase")) -> Single Phase | I22: =IF(A22<=$D$10,'QC Protocol'!$C$7+'QC Protocol'!$C$8*B22+'QC Protocol'!$C$9*B22^2+'QC Protocol'!$C$10*B22^3,'QC Protocol'!$C$18+'QC Protocol'!$C$19*B22+'QC Protocol'!$C$20*B22^2) -> 0.96523187 | J22: =IF(A22<=$D$10,D22-I22,IF(A22>$D$10,G22-I22,"")) -> 6.3550932e-05 | K22: =IF(OR(J22="",J22=0),"",IF(A22<=$D$10,ABS(J22/D22)*100,ABS(J22/G22)*100)) -> 0.0065835734 | L22: =IF(K22="","",IF(A22<=$D$10,IF(K22<'QC Protocol'!$C$26,"PASS",IF(K22<'QC Protocol'!$C$27,"WARN","FAIL")),IF(K22<'QC Protocol'!$C$28,"PASS",IF(K22<'QC Protocol'!$C$29,"WARN","FAIL")))) -> PASS | O22: =A22 -> 7 | P22: =B22 -> 4029.4572 | Q22: =D22 -> 0.96529542 | R22: =E22 -> 0.71025107 | S22: =G22 | T22: =F22 -> 9.6773324 | U22: =D22 -> 0.96529542 | V22: =IF(Q22="","",Q22*(1+$W$5/100)) -> 0.98460133 | W22: =IF(Q22="","",Q22*(1-$W$5/100)) -> 0.94598951 | X22: =IF(OR(U22="",V22="",W22=""),"",IF(OR(U22>V22,U22<W22),"OUT","OK")) -> OK | Y22: =IF(X22<>"OUT","",($W$6+$W$7*(P22/$D$7)+$W$8*(P22/$D$7)^2))
A23: 8 | B23: 3938.73 | C23: 96.616911 | D23: =C23/$J$8 -> 0.96616911 | E23: =IF(A23<=$D$10,$J$7/C23,"") -> 0.7096088 | F23: =IF(A23<=$D$10,(C24-C22)/C23/(B22-B24)*1000000,"") -> 10.236258 | G23: =IF(A23>$D$10,($J$9-B23)/(B23*(D23-1)),"") | H23: =IF(A23<$D$10,"Single Phase",IF(A23=$D$10,"Bubble Point","Two Phase")) -> Single Phase | I23: =IF(A23<=$D$10,'QC Protocol'!$C$7+'QC Protocol'!$C$8*B23+'QC Protocol'!$C$9*B23^2+'QC Protocol'!$C$10*B23^3,'QC Protocol'!$C$18+'QC Protocol'!$C$19*B23+'QC Protocol'!$C$20*B23^2) -> 0.96610449 | J23: =IF(A23<=$D$10,D23-I23,IF(A23>$D$10,G23-I23,"")) -> 6.4618684e-05 | K23: =IF(OR(J23="",J23=0),"",IF(A23<=$D$10,ABS(J23/D23)*100,ABS(J23/G23)*100)) -> 0.0066881339 | L23: =IF(K23="","",IF(A23<=$D$10,IF(K23<'QC Protocol'!$C$26,"PASS",IF(K23<'QC Protocol'!$C$27,"WARN","FAIL")),IF(K23<'QC Protocol'!$C$28,"PASS",IF(K23<'QC Protocol'!$C$29,"WARN","FAIL")))) -> PASS | O23: =A23 -> 8 | P23: =B23 -> 3938.73 | Q23: =D23 -> 0.96616911 | R23: =E23 -> 0.7096088 | S23: =G23 | T23: =F23 -> 10.236258 | U23: =D23 -> 0.96616911 | V23: =IF(Q23="","",Q23*(1+$W$5/100)) -> 0.98549249 | W23: =IF(Q23="","",Q23*(1-$W$5/100)) -> 0.94684573 | X23: =IF(OR(U23="",V23="",W23=""),"",IF(OR(U23>V23,U23<W23),"OUT","OK")) -> OK | Y23: =IF(X23<>"OUT","",($W$6+$W$7*(P23/$D$7)+$W$8*(P23/$D$7)^2))
A24: 9 | B24: 3532.4847 | C24: 97.021046 | D24: =C24/$J$8 -> 0.97021046 | E24: =IF(A24<=$D$10,$J$7/C24,"") -> 0.70665297 | F24: =IF(A24<=$D$10,(C25-C23)/C24/(B23-B25)*1000000,"") -> 10.623103 | G24: =IF(A24>$D$10,($J$9-B24)/(B24*(D24-1)),"") | H24: =IF(A24<$D$10,"Single Phase",IF(A24=$D$10,"Bubble Point","Two Phase")) -> Single Phase | I24: =IF(A24<=$D$10,'QC Protocol'!$C$7+'QC Protocol'!$C$8*B24+'QC Protocol'!$C$9*B24^2+'QC Protocol'!$C$10*B24^3,'QC Protocol'!$C$18+'QC Protocol'!$C$19*B24+'QC Protocol'!$C$20*B24^2) -> 0.97015633 | J24: =IF(A24<=$D$10,D24-I24,IF(A24>$D$10,G24-I24,"")) -> 5.4126797e-05 | K24: =IF(OR(J24="",J24=0),"",IF(A24<=$D$10,ABS(J24/D24)*100,ABS(J24/G24)*100)) -> 0.0055788718 | L24: =IF(K24="","",IF(A24<=$D$10,IF(K24<'QC Protocol'!$C$26,"PASS",IF(K24<'QC Protocol'!$C$27,"WARN","FAIL")),IF(K24<'QC Protocol'!$C$28,"PASS",IF(K24<'QC Protocol'!$C$29,"WARN","FAIL")))) -> PASS | O24: =A24 -> 9 | P24: =B24 -> 3532.4847 | Q24: =D24 -> 0.97021046 | R24: =E24 -> 0.70665297 | S24: =G24 | T24: =F24 -> 10.623103 | U24: =D24 -> 0.97021046 | V24: =IF(Q24="","",Q24*(1+$W$5/100)) -> 0.98961467 | W24: =IF(Q24="","",Q24*(1-$W$5/100)) -> 0.95080625 | X24: =IF(OR(U24="",V24="",W24=""),"",IF(OR(U24>V24,U24<W24),"OUT","OK")) -> OK | Y24: =IF(X24<>"OUT","",($W$6+$W$7*(P24/$D$7)+$W$8*(P24/$D$7)^2))
A25: 10 | B25: 3031.1977 | C25: 97.552272 | D25: =C25/$J$8 -> 0.97552272 | E25: =IF(A25<=$D$10,$J$7/C25,"") -> 0.70280486 | F25: =IF(A25<=$D$10,(C26-C24)/C25/(B24-B26)*1000000,"") -> 11.298114 | G25: =IF(A25>$D$10,($J$9-B25)/(B25*(D25-1)),"") | H25: =IF(A25<$D$10,"Single Phase",IF(A25=$D$10,"Bubble Point","Two Phase")) -> Single Phase | I25: =IF(A25<=$D$10,'QC Protocol'!$C$7+'QC Protocol'!$C$8*B25+'QC Protocol'!$C$9*B25^2+'QC Protocol'!$C$10*B25^3,'QC Protocol'!$C$18+'QC Protocol'!$C$19*B25+'QC Protocol'!$C$20*B25^2) -> 0.97551441 | J25: =IF(A25<=$D$10,D25-I25,IF(A25>$D$10,G25-I25,"")) -> 8.3158792e-06 | K25: =IF(OR(J25="",J25=0),"",IF(A25<=$D$10,ABS(J25/D25)*100,ABS(J25/G25)*100)) -> 0.00085245367 | L25: =IF(K25="","",IF(A25<=$D$10,IF(K25<'QC Protocol'!$C$26,"PASS",IF(K25<'QC Protocol'!$C$27,"WARN","FAIL")),IF(K25<'QC Protocol'!$C$28,"PASS",IF(K25<'QC Protocol'!$C$29,"WARN","FAIL")))) -> PASS | O25: =A25 -> 10 | P25: =B25 -> 3031.1977 | Q25: =D25 -> 0.97552272 | R25: =E25 -> 0.70280486 | S25: =G25 | T25: =F25 -> 11.298114 | U25: =D25 -> 0.97552272 | V25: =IF(Q25="","",Q25*(1+$W$5/100)) -> 0.99503318 | W25: =IF(Q25="","",Q25*(1-$W$5/100)) -> 0.95601227 | X25: =IF(OR(U25="",V25="",W25=""),"",IF(OR(U25>V25,U25<W25),"OUT","OK")) -> OK | Y25: =IF(X25<>"OUT","",($W$6+$W$7*(P25/$D$7)+$W$8*(P25/$D$7)^2))
A26: 11 | B26: 2529.5335 | C26: 98.126455 | D26: =C26/$J$8 -> 0.98126455 | E26: =IF(A26<=$D$10,$J$7/C26,"") -> 0.69869242 | F26: =IF(A26<=$D$10,(C27-C25)/C26/(B25-B27)*1000000,"") -> 12.186544 | G26: =IF(A26>$D$10,($J$9-B26)/(B26*(D26-1)),"") | H26: =IF(A26<$D$10,"Single Phase",IF(A26=$D$10,"Bubble Point","Two Phase")) -> Single Phase | I26: =IF(A26<=$D$10,'QC Protocol'!$C$7+'QC Protocol'!$C$8*B26+'QC Protocol'!$C$9*B26^2+'QC Protocol'!$C$10*B26^3,'QC Protocol'!$C$18+'QC Protocol'!$C$19*B26+'QC Protocol'!$C$20*B26^2) -> 0.98132364 | J26: =IF(A26<=$D$10,D26-I26,IF(A26>$D$10,G26-I26,"")) -> -5.9084942e-05 | K26: =IF(OR(J26="",J26=0),"",IF(A26<=$D$10,ABS(J26/D26)*100,ABS(J26/G26)*100)) -> 0.0060213061 | L26: =IF(K26="","",IF(A26<=$D$10,IF(K26<'QC Protocol'!$C$26,"PASS",IF(K26<'QC Protocol'!$C$27,"WARN","FAIL")),IF(K26<'QC Protocol'!$C$28,"PASS",IF(K26<'QC Protocol'!$C$29,"WARN","FAIL")))) -> PASS | O26: =A26 -> 11 | P26: =B26 -> 2529.5335 | Q26: =D26 -> 0.98126455 | R26: =E26 -> 0.69869242 | S26: =G26 | T26: =F26 -> 12.186544 | U26: =D26 -> 0.98126455 | V26: =IF(Q26="","",Q26*(1+$W$5/100)) -> 1.0008898 | W26: =IF(Q26="","",Q26*(1-$W$5/100)) -> 0.96163926 | X26: =IF(OR(U26="",V26="",W26=""),"",IF(OR(U26>V26,U26<W26),"OUT","OK")) -> OK | Y26: =IF(X26<>"OUT","",($W$6+$W$7*(P26/$D$7)+$W$8*(P26/$D$7)^2))
A27: 12 | B27: 2031.2057 | C27: 98.748085 | D27: =C27/$J$8 -> 0.98748085 | E27: =IF(A27<=$D$10,$J$7/C27,"") -> 0.69429408 | F27: =IF(A27<=$D$10,(C28-C26)/C27/(B26-B28)*1000000,"") -> 13.279019 | G27: =IF(A27>$D$10,($J$9-B27)/(B27*(D27-1)),"") | H27: =IF(A27<$D$10,"Single Phase",IF(A27=$D$10,"Bubble Point","Two Phase")) -> Single Phase | I27: =IF(A27<=$D$10,'QC Protocol'!$C$7+'QC Protocol'!$C$8*B27+'QC Protocol'!$C$9*B27^2+'QC Protocol'!$C$10*B27^3,'QC Protocol'!$C$18+'QC Protocol'!$C$19*B27+'QC Protocol'!$C$20*B27^2) -> 0.98759073 | J27: =IF(A27<=$D$10,D27-I27,IF(A27>$D$10,G27-I27,"")) -> -0.00010988163 | K27: =IF(OR(J27="",J27=0),"",IF(A27<=$D$10,ABS(J27/D27)*100,ABS(J27/G27)*100)) -> 0.01112747 | L27: =IF(K27="","",IF(A27<=$D$10,IF(K27<'QC Protocol'!$C$26,"PASS",IF(K27<'QC Protocol'!$C$27,"WARN","FAIL")),IF(K27<'QC Protocol'!$C$28,"PASS",IF(K27<'QC Protocol'!$C$29,"WARN","FAIL")))) -> PASS | O27: =A27 -> 12 | P27: =B27 -> 2031.2057 | Q27: =D27 -> 0.98748085 | R27: =E27 -> 0.69429408 | S27: =G27 | T27: =F27 -> 13.279019 | U27: =D27 -> 0.98748085 | V27: =IF(Q27="","",Q27*(1+$W$5/100)) -> 1.0072305 | W27: =IF(Q27="","",Q27*(1-$W$5/100)) -> 0.96773123 | X27: =IF(OR(U27="",V27="",W27=""),"",IF(OR(U27>V27,U27<W27),"OUT","OK")) -> OK | Y27: =IF(X27<>"OUT","",($W$6+$W$7*(P27/$D$7)+$W$8*(P27/$D$7)^2))
A28: 13 | B28: 1528.4731 | C28: 99.439123 | D28: =C28/$J$8 -> 0.99439123 | E28: =IF(A28<=$D$10,$J$7/C28,"") -> 0.68946918 | F28: =IF(A28<=$D$10,(C29-C27)/C28/(B27-B29)*1000000,"") -> 14.172776 | G28: =IF(A28>$D$10,($J$9-B28)/(B28*(D28-1)),"") | H28: =IF(A28<$D$10,"Single Phase",IF(A28=$D$10,"Bubble Point","Two Phase")) -> Single Phase | I28: =IF(A28<=$D$10,'QC Protocol'!$C$7+'QC Protocol'!$C$8*B28+'QC Protocol'!$C$9*B28^2+'QC Protocol'!$C$10*B28^3,'QC Protocol'!$C$18+'QC Protocol'!$C$19*B28+'QC Protocol'!$C$20*B28^2) -> 0.99446889 | J28: =IF(A28<=$D$10,D28-I28,IF(A28>$D$10,G28-I28,"")) -> -7.7656117e-05 | K28: =IF(OR(J28="",J28=0),"",IF(A28<=$D$10,ABS(J28/D28)*100,ABS(J28/G28)*100)) -> 0.0078094129 | L28: =IF(K28="","",IF(A28<=$D$10,IF(K28<'QC Protocol'!$C$26,"PASS",IF(K28<'QC Protocol'!$C$27,"WARN","FAIL")),IF(K28<'QC Protocol'!$C$28,"PASS",IF(K28<'QC Protocol'!$C$29,"WARN","FAIL")))) -> PASS | O28: =A28 -> 13 | P28: =B28 -> 1528.4731 | Q28: =D28 -> 0.99439123 | R28: =E28 -> 0.68946918 | S28: =G28 | T28: =F28 -> 14.172776 | U28: =D28 -> 0.99439123 | V28: =IF(Q28="","",Q28*(1+$W$5/100)) -> 1.0142791 | W28: =IF(Q28="","",Q28*(1-$W$5/100)) -> 0.97450341 | X28: =IF(OR(U28="",V28="",W28=""),"",IF(OR(U28>V28,U28<W28),"OUT","OK")) -> OK | Y28: =IF(X28<>"OUT","",($W$6+$W$7*(P28/$D$7)+$W$8*(P28/$D$7)^2))
A29: 14 | B29: 1295.073 | C29: 99.785538 | D29: =C29/$J$8 -> 0.99785538 | E29: =IF(A29<=$D$10,$J$7/C29,"") -> 0.68707562 | F29: =IF(A29<=$D$10,(C30-C28)/C29/(B28-B30)*1000000,"") -> 14.944624 | G29: =IF(A29>$D$10,($J$9-B29)/(B29*(D29-1)),"") | H29: =IF(A29<$D$10,"Single Phase",IF(A29=$D$10,"Bubble Point","Two Phase")) -> Single Phase | I29: =IF(A29<=$D$10,'QC Protocol'!$C$7+'QC Protocol'!$C$8*B29+'QC Protocol'!$C$9*B29^2+'QC Protocol'!$C$10*B29^3,'QC Protocol'!$C$18+'QC Protocol'!$C$19*B29+'QC Protocol'!$C$20*B29^2) -> 0.99786708 | J29: =IF(A29<=$D$10,D29-I29,IF(A29>$D$10,G29-I29,"")) -> -1.170136e-05 | K29: =IF(OR(J29="",J29=0),"",IF(A29<=$D$10,ABS(J29/D29)*100,ABS(J29/G29)*100)) -> 0.0011726509 | L29: =IF(K29="","",IF(A29<=$D$10,IF(K29<'QC Protocol'!$C$26,"PASS",IF(K29<'QC Protocol'!$C$27,"WARN","FAIL")),IF(K29<'QC Protocol'!$C$28,"PASS",IF(K29<'QC Protocol'!$C$29,"WARN","FAIL")))) -> PASS | O29: =A29 -> 14 | P29: =B29 -> 1295.073 | Q29: =D29 -> 0.99785538 | R29: =E29 -> 0.68707562 | S29: =G29 | T29: =F29 -> 14.944624 | U29: =D29 -> 0.99785538 | V29: =IF(Q29="","",Q29*(1+$W$5/100)) -> 1.0178125 | W29: =IF(Q29="","",Q29*(1-$W$5/100)) -> 0.97789827 | X29: =IF(OR(U29="",V29="",W29=""),"",IF(OR(U29>V29,U29<W29),"OUT","OK")) -> OK | Y29: =IF(X29<>"OUT","",($W$6+$W$7*(P29/$D$7)+$W$8*(P29/$D$7)^2))
A30: 15 | B30: 1249.8194 | C30: 99.854668 | D30: =C30/$J$8 -> 0.99854668 | E30: =IF(A30<=$D$10,$J$7/C30,"") -> 0.68659996 | F30: =IF(A30<=$D$10,(C31-C29)/C30/(B29-B31)*1000000,"") -> 15.32829 | G30: =IF(A30>$D$10,($J$9-B30)/(B30*(D30-1)),"") | H30: =IF(A30<$D$10,"Single Phase",IF(A30=$D$10,"Bubble Point","Two Phase")) -> Single Phase | I30: =IF(A30<=$D$10,'QC Protocol'!$C$7+'QC Protocol'!$C$8*B30+'QC Protocol'!$C$9*B30^2+'QC Protocol'!$C$10*B30^3,'QC Protocol'!$C$18+'QC Protocol'!$C$19*B30+'QC Protocol'!$C$20*B30^2) -> 0.9985417 | J30: =IF(A30<=$D$10,D30-I30,IF(A30>$D$10,G30-I30,"")) -> 4.9823293e-06 | K30: =IF(OR(J30="",J30=0),"",IF(A30<=$D$10,ABS(J30/D30)*100,ABS(J30/G30)*100)) -> 0.00049895807 | L30: =IF(K30="","",IF(A30<=$D$10,IF(K30<'QC Protocol'!$C$26,"PASS",IF(K30<'QC Protocol'!$C$27,"WARN","FAIL")),IF(K30<'QC Protocol'!$C$28,"PASS",IF(K30<'QC Protocol'!$C$29,"WARN","FAIL")))) -> PASS | O30: =A30 -> 15 | P30: =B30 -> 1249.8194 | Q30: =D30 -> 0.99854668 | R30: =E30 -> 0.68659996 | S30: =G30 | T30: =F30 -> 15.32829 | U30: =D30 -> 0.99854668 | V30: =IF(Q30="","",Q30*(1+$W$5/100)) -> 1.0185176 | W30: =IF(Q30="","",Q30*(1-$W$5/100)) -> 0.97857574 | X30: =IF(OR(U30="",V30="",W30=""),"",IF(OR(U30>V30,U30<W30),"OUT","OK")) -> OK | Y30: =IF(X30<>"OUT","",($W$6+$W$7*(P30/$D$7)+$W$8*(P30/$D$7)^2))
... A37: 22 | B37: 1151.5456 | C37: 100.18066 | D37: =C37/$J$8 -> 1.0018066 | E37: =IF(A37<=$D$10,$J$7/C37,"") | F37: =IF(A37<=$D$10,(C38-C36)/C37/(B36-B38)*1000000,"") | G37: =IF(A37>$D$10,($J$9-B37)/(B37*(D37-1)),"") -> 2.0113991 | H37: =IF(A37<$D$10,"Single Phase",IF(A37=$D$10,"Bubble Point","Two Phase")) -> Two Phase | I37: =IF(A37<=$D$10,'QC Protocol'!$C$7+'QC Protocol'!$C$8*B37+'QC Protocol'!$C$9*B37^2+'QC Protocol'!$C$10*B37^3,'QC Protocol'!$C$18+'QC Protocol'!$C$19*B37+'QC Protocol'!$C$20*B37^2) -> 2.0099402 | J37: =IF(A37<=$D$10,D37-I37,IF(A37>$D$10,G37-I37,"")) -> 0.0014588367 | K37: =IF(OR(J37="",J37=0),"",IF(A37<=$D$10,ABS(J37/D37)*100,ABS(J37/G37)*100)) -> 0.072528456 | L37: =IF(K37="","",IF(A37<=$D$10,IF(K37<'QC Protocol'!$C$26,"PASS",IF(K37<'QC Protocol'!$C$27,"WARN","FAIL")),IF(K37<'QC Protocol'!$C$28,"PASS",IF(K37<'QC Protocol'!$C$29,"WARN","FAIL")))) -> PASS | O37: =A37 -> 22 | P37: =B37 -> 1151.5456 | Q37: =D37 -> 1.0018066 | R37: =E37 | S37: =G37 -> 2.0113991 | T37: =F37 | U37: =D37 -> 1.0018066 | V37: =IF(Q37="","",Q37*(1+$W$5/100)) -> 1.0218427 | W37: =IF(Q37="","",Q37*(1-$W$5/100)) -> 0.98177043 | X37: =IF(OR(U37="",V37="",W37=""),"",IF(OR(U37>V37,U37<W37),"OUT","OK")) -> OK | Y37: =IF(X37<>"OUT","",($W$6+$W$7*(P37/$D$7)+$W$8*(P37/$D$7)^2))
A38: 23 | B38: 1150.7911 | C38: 100.2134 | D38: =C38/$J$8 -> 1.002134 | E38: =IF(A38<=$D$10,$J$7/C38,"") | F38: =IF(A38<=$D$10,(C39-C37)/C38/(B37-B39)*1000000,"") | G38: =IF(A38>$D$10,($J$9-B38)/(B38*(D38-1)),"") -> 2.0111041 | H38: =IF(A38<$D$10,"Single Phase",IF(A38=$D$10,"Bubble Point","Two Phase")) -> Two Phase | I38: =IF(A38<=$D$10,'QC Protocol'!$C$7+'QC Protocol'!$C$8*B38+'QC Protocol'!$C$9*B38^2+'QC Protocol'!$C$10*B38^3,'QC Protocol'!$C$18+'QC Protocol'!$C$19*B38+'QC Protocol'!$C$20*B38^2) -> 2.0096892 | J38: =IF(A38<=$D$10,D38-I38,IF(A38>$D$10,G38-I38,"")) -> 0.0014148361 | K38: =IF(OR(J38="",J38=0),"",IF(A38<=$D$10,ABS(J38/D38)*100,ABS(J38/G38)*100)) -> 0.070351214 | L38: =IF(K38="","",IF(A38<=$D$10,IF(K38<'QC Protocol'!$C$26,"PASS",IF(K38<'QC Protocol'!$C$27,"WARN","FAIL")),IF(K38<'QC Protocol'!$C$28,"PASS",IF(K38<'QC Protocol'!$C$29,"WARN","FAIL")))) -> PASS | O38: =A38 -> 23 | P38: =B38 -> 1150.7911 | Q38: =D38 -> 1.002134 | R38: =E38 | S38: =G38 -> 2.0111041 | T38: =F38 | U38: =D38 -> 1.002134 | V38: =IF(Q38="","",Q38*(1+$W$5/100)) -> 1.0221767 | W38: =IF(Q38="","",Q38*(1-$W$5/100)) -> 0.98209134 | X38: =IF(OR(U38="",V38="",W38=""),"",IF(OR(U38>V38,U38<W38),"OUT","OK")) -> OK | Y38: =IF(X38<>"OUT","",($W$6+$W$7*(P38/$D$7)+$W$8*(P38/$D$7)^2)) | AF38: Macro button to adjust the values using ijk Value
A39: 24 | B39: 1148.6789 | C39: 100.30535 | D39: =C39/$J$8 -> 1.0030535 | E39: =IF(A39<=$D$10,$J$7/C39,"") | F39: =IF(A39<=$D$10,(C40-C38)/C39/(B38-B40)*1000000,"") | G39: =IF(A39>$D$10,($J$9-B39)/(B39*(D39-1)),"") -> 2.0102778 | H39: =IF(A39<$D$10,"Single Phase",IF(A39=$D$10,"Bubble Point","Two Phase")) -> Two Phase | I39: =IF(A39<=$D$10,'QC Protocol'!$C$7+'QC Protocol'!$C$8*B39+'QC Protocol'!$C$9*B39^2+'QC Protocol'!$C$10*B39^3,'QC Protocol'!$C$18+'QC Protocol'!$C$19*B39+'QC Protocol'!$C$20*B39^2) -> 2.0089852 | J39: =IF(A39<=$D$10,D39-I39,IF(A39>$D$10,G39-I39,"")) -> 0.0012926612 | K39: =IF(OR(J39="",J39=0),"",IF(A39<=$D$10,ABS(J39/D39)*100,ABS(J39/G39)*100)) -> 0.064302614 | L39: =IF(K39="","",IF(A39<=$D$10,IF(K39<'QC Protocol'!$C$26,"PASS",IF(K39<'QC Protocol'!$C$27,"WARN","FAIL")),IF(K39<'QC Protocol'!$C$28,"PASS",IF(K39<'QC Protocol'!$C$29,"WARN","FAIL")))) -> PASS | O39: =A39 -> 24 | P39: =B39 -> 1148.6789 | Q39: =D39 -> 1.0030535 | R39: =E39 | S39: =G39 -> 2.0102778 | T39: =F39 | U39: =D39 -> 1.0030535 | V39: =IF(Q39="","",Q39*(1+$W$5/100)) -> 1.0231146 | W39: =IF(Q39="","",Q39*(1-$W$5/100)) -> 0.98299246 | X39: =IF(OR(U39="",V39="",W39=""),"",IF(OR(U39>V39,U39<W39),"OUT","OK")) -> OK | Y39: =IF(X39<>"OUT","",($W$6+$W$7*(P39/$D$7)+$W$8*(P39/$D$7)^2))
A40: 25 | B40: 1147.4116 | C40: 100.36072 | D40: =C40/$J$8 -> 1.0036072 | E40: =IF(A40<=$D$10,$J$7/C40,"") | F40: =IF(A40<=$D$10,(C41-C39)/C40/(B39-B41)*1000000,"") | G40: =IF(A40>$D$10,($J$9-B40)/(B40*(D40-1)),"") -> 2.0097817 | H40: =IF(A40<$D$10,"Single Phase",IF(A40=$D$10,"Bubble Point","Two Phase")) -> Two Phase | I40: =IF(A40<=$D$10,'QC Protocol'!$C$7+'QC Protocol'!$C$8*B40+'QC Protocol'!$C$9*B40^2+'QC Protocol'!$C$10*B40^3,'QC Protocol'!$C$18+'QC Protocol'!$C$19*B40+'QC Protocol'!$C$20*B40^2) -> 2.0085618 | J40: =IF(A40<=$D$10,D40-I40,IF(A40>$D$10,G40-I40,"")) -> 0.0012199509 | K40: =IF(OR(J40="",J40=0),"",IF(A40<=$D$10,ABS(J40/D40)*100,ABS(J40/G40)*100)) -> 0.060700665 | L40: =IF(K40="","",IF(A40<=$D$10,IF(K40<'QC Protocol'!$C$26,"PASS",IF(K40<'QC Protocol'!$C$27,"WARN","FAIL")),IF(K40<'QC Protocol'!$C$28,"PASS",IF(K40<'QC Protocol'!$C$29,"WARN","FAIL")))) -> PASS | O40: =A40 -> 25 | P40: =B40 -> 1147.4116 | Q40: =D40 -> 1.0036072 | R40: =E40 | S40: =G40 -> 2.0097817 | T40: =F40 | U40: =D40 -> 1.0036072 | V40: =IF(Q40="","",Q40*(1+$W$5/100)) -> 1.0236794 | W40: =IF(Q40="","",Q40*(1-$W$5/100)) -> 0.98353507 | X40: =IF(OR(U40="",V40="",W40=""),"",IF(OR(U40>V40,U40<W40),"OUT","OK")) -> OK | Y40: =IF(X40<>"OUT","",($W$6+$W$7*(P40/$D$7)+$W$8*(P40/$D$7)^2))
A41: 26 | B41: 1142.4438 | C41: 100.57921 | D41: =C41/$J$8 -> 1.0057921 | E41: =IF(A41<=$D$10,$J$7/C41,"") | F41: =IF(A41<=$D$10,(C42-C40)/C41/(B40-B42)*1000000,"") | G41: =IF(A41>$D$10,($J$9-B41)/(B41*(D41-1)),"") -> 2.0078343 | H41: =IF(A41<$D$10,"Single Phase",IF(A41=$D$10,"Bubble Point","Two Phase")) -> Two Phase | I41: =IF(A41<=$D$10,'QC Protocol'!$C$7+'QC Protocol'!$C$8*B41+'QC Protocol'!$C$9*B41^2+'QC Protocol'!$C$10*B41^3,'QC Protocol'!$C$18+'QC Protocol'!$C$19*B41+'QC Protocol'!$C$20*B41^2) -> 2.0068953 | J41: =IF(A41<=$D$10,D41-I41,IF(A41>$D$10,G41-I41,"")) -> 0.00093900091 | K41: =IF(OR(J41="",J41=0),"",IF(A41<=$D$10,ABS(J41/D41)*100,ABS(J41/G41)*100)) -> 0.046766852 | L41: =IF(K41="","",IF(A41<=$D$10,IF(K41<'QC Protocol'!$C$26,"PASS",IF(K41<'QC Protocol'!$C$27,"WARN","FAIL")),IF(K41<'QC Protocol'!$C$28,"PASS",IF(K41<'QC Protocol'!$C$29,"WARN","FAIL")))) -> PASS | O41: =A41 -> 26 | P41: =B41 -> 1142.4438 | Q41: =D41 -> 1.0057921 | R41: =E41 | S41: =G41 -> 2.0078343 | T41: =F41 | U41: =D41 -> 1.0057921 | V41: =IF(Q41="","",Q41*(1+$W$5/100)) -> 1.025908 | W41: =IF(Q41="","",Q41*(1-$W$5/100)) -> 0.98567628 | X41: =IF(OR(U41="",V41="",W41=""),"",IF(OR(U41>V41,U41<W41),"OUT","OK")) -> OK | Y41: =IF(X41<>"OUT","",($W$6+$W$7*(P41/$D$7)+$W$8*(P41/$D$7)^2))
A42: 27 | B42: 1138.6956 | C42: 100.74561 | D42: =C42/$J$8 -> 1.0074561 | E42: =IF(A42<=$D$10,$J$7/C42,"") | F42: =IF(A42<=$D$10,(C43-C41)/C42/(B41-B43)*1000000,"") | G42: =IF(A42>$D$10,($J$9-B42)/(B42*(D42-1)),"") -> 2.0063623 | H42: =IF(A42<$D$10,"Single Phase",IF(A42=$D$10,"Bubble Point","Two Phase")) -> Two Phase | I42: =IF(A42<=$D$10,'QC Protocol'!$C$7+'QC Protocol'!$C$8*B42+'QC Protocol'!$C$9*B42^2+'QC Protocol'!$C$10*B42^3,'QC Protocol'!$C$18+'QC Protocol'!$C$19*B42+'QC Protocol'!$C$20*B42^2) -> 2.0056308 | J42: =IF(A42<=$D$10,D42-I42,IF(A42>$D$10,G42-I42,"")) -> 0.0007314538 | K42: =IF(OR(J42="",J42=0),"",IF(A42<=$D$10,ABS(J42/D42)*100,ABS(J42/G42)*100)) -> 0.036456716 | L42: =IF(K42="","",IF(A42<=$D$10,IF(K42<'QC Protocol'!$C$26,"PASS",IF(K42<'QC Protocol'!$C$27,"WARN","FAIL")),IF(K42<'QC Protocol'!$C$28,"PASS",IF(K42<'QC Protocol'!$C$29,"WARN","FAIL")))) -> PASS | O42: =A42 -> 27 | P42: =B42 -> 1138.6956 | Q42: =D42 -> 1.0074561 | R42: =E42 | S42: =G42 -> 2.0063623 | T42: =F42 | U42: =D42 -> 1.0074561 | V42: =IF(Q42="","",Q42*(1+$W$5/100)) -> 1.0276052 | W42: =IF(Q42="","",Q42*(1-$W$5/100)) -> 0.98730695 | X42: =IF(OR(U42="",V42="",W42=""),"",IF(OR(U42>V42,U42<W42),"OUT","OK")) -> OK | Y42: =IF(X42<>"OUT","",($W$6+$W$7*(P42/$D$7)+$W$8*(P42/$D$7)^2))
A43: 28 | B43: 1127.7299 | C43: 101.24017 | D43: =C43/$J$8 -> 1.0124017 | E43: =IF(A43<=$D$10,$J$7/C43,"") | F43: =IF(A43<=$D$10,(C44-C42)/C43/(B42-B44)*1000000,"") | G43: =IF(A43>$D$10,($J$9-B43)/(B43*(D43-1)),"") -> 2.0020414 | H43: =IF(A43<$D$10,"Single Phase",IF(A43=$D$10,"Bubble Point","Two Phase")) -> Two Phase | I43: =IF(A43<=$D$10,'QC Protocol'!$C$7+'QC Protocol'!$C$8*B43+'QC Protocol'!$C$9*B43^2+'QC Protocol'!$C$10*B43^3,'QC Protocol'!$C$18+'QC Protocol'!$C$19*B43+'QC Protocol'!$C$20*B43^2) -> 2.0018957 | J43: =IF(A43<=$D$10,D43-I43,IF(A43>$D$10,G43-I43,"")) -> 0.00014578924 | K43: =IF(OR(J43="",J43=0),"",IF(A43<=$D$10,ABS(J43/D43)*100,ABS(J43/G43)*100)) -> 0.0072820292 | L43: =IF(K43="","",IF(A43<=$D$10,IF(K43<'QC Protocol'!$C$26,"PASS",IF(K43<'QC Protocol'!$C$27,"WARN","FAIL")),IF(K43<'QC Protocol'!$C$28,"PASS",IF(K43<'QC Protocol'!$C$29,"WARN","FAIL")))) -> PASS | O43: =A43 -> 28 | P43: =B43 -> 1127.7299 | Q43: =D43 -> 1.0124017 | R43: =E43 | S43: =G43 -> 2.0020414 | T43: =F43 | U43: =D43 -> 1.0124017 | V43: =IF(Q43="","",Q43*(1+$W$5/100)) -> 1.0326497 | W43: =IF(Q43="","",Q43*(1-$W$5/100)) -> 0.99215367 | X43: =IF(OR(U43="",V43="",W43=""),"",IF(OR(U43>V43,U43<W43),"OUT","OK")) -> OK | Y43: =IF(X43<>"OUT","",($W$6+$W$7*(P43/$D$7)+$W$8*(P43/$D$7)^2))
A44: 29 | B44: 1107.0789 | C44: 102.20405 | D44: =C44/$J$8 -> 1.0220405 | E44: =IF(A44<=$D$10,$J$7/C44,"") | F44: =IF(A44<=$D$10,(C45-C43)/C44/(B43-B45)*1000000,"") | G44: =IF(A44>$D$10,($J$9-B44)/(B44*(D44-1)),"") -> 1.9938466 | H44: =IF(A44<$D$10,"Single Phase",IF(A44=$D$10,"Bubble Point","Two Phase")) -> Two Phase | I44: =IF(A44<=$D$10,'QC Protocol'!$C$7+'QC Protocol'!$C$8*B44+'QC Protocol'!$C$9*B44^2+'QC Protocol'!$C$10*B44^3,'QC Protocol'!$C$18+'QC Protocol'!$C$19*B44+'QC Protocol'!$C$20*B44^2) -> 1.9947173 | J44: =IF(A44<=$D$10,D44-I44,IF(A44>$D$10,G44-I44,"")) -> -0.0008707375 | K44: =IF(OR(J44="",J44=0),"",IF(A44<=$D$10,ABS(J44/D44)*100,ABS(J44/G44)*100)) -> 0.043671238 | L44: =IF(K44="","",IF(A44<=$D$10,IF(K44<'QC Protocol'!$C$26,"PASS",IF(K44<'QC Protocol'!$C$27,"WARN","FAIL")),IF(K44<'QC Protocol'!$C$28,"PASS",IF(K44<'QC Protocol'!$C$29,"WARN","FAIL")))) -> PASS | O44: =A44 -> 29 | P44: =B44 -> 1107.0789 | Q44: =D44 -> 1.0220405 | R44: =E44 | S44: =G44 -> 1.9938466 | T44: =F44 | U44: =D44 -> 1.0220405 | V44: =IF(Q44="","",Q44*(1+$W$5/100)) -> 1.0424814 | W44: =IF(Q44="","",Q44*(1-$W$5/100)) -> 1.0015997 | X44: =IF(OR(U44="",V44="",W44=""),"",IF(OR(U44>V44,U44<W44),"OUT","OK")) -> OK | Y44: =IF(X44<>"OUT","",($W$6+$W$7*(P44/$D$7)+$W$8*(P44/$D$7)^2))
A45: 30 | B45: 1066.4923 | C45: 104.23127 | D45: =C45/$J$8 -> 1.0423127 | E45: =IF(A45<=$D$10,$J$7/C45,"") | F45: =IF(A45<=$D$10,(C46-C44)/C45/(B44-B46)*1000000,"") | G45: =IF(A45>$D$10,($J$9-B45)/(B45*(D45-1)),"") -> 1.9775137 | H45: =IF(A45<$D$10,"Single Phase",IF(A45=$D$10,"Bubble Point","Two Phase")) -> Two Phase | I45: =IF(A45<=$D$10,'QC Protocol'!$C$7+'QC Protocol'!$C$8*B45+'QC Protocol'!$C$9*B45^2+'QC Protocol'!$C$10*B45^3,'QC Protocol'!$C$18+'QC Protocol'!$C$19*B45+'QC Protocol'!$C$20*B45^2) -> 1.9800606 | J45: =IF(A45<=$D$10,D45-I45,IF(A45>$D$10,G45-I45,"")) -> -0.0025469294 | K45: =IF(OR(J45="",J45=0),"",IF(A45<=$D$10,ABS(J45/D45)*100,ABS(J45/G45)*100)) -> 0.12879453 | L45: =IF(K45="","",IF(A45<=$D$10,IF(K45<'QC Protocol'!$C$26,"PASS",IF(K45<'QC Protocol'!$C$27,"WARN","FAIL")),IF(K45<'QC Protocol'!$C$28,"PASS",IF(K45<'QC Protocol'!$C$29,"WARN","FAIL")))) -> PASS | O45: =A45 -> 30 | P45: =B45 -> 1066.4923 | Q45: =D45 -> 1.0423127 | R45: =E45 | S45: =G45 -> 1.9775137 | T45: =F45 | U45: =D45 -> 1.0423127 | V45: =IF(Q45="","",Q45*(1+$W$5/100)) -> 1.063159 | W45: =IF(Q45="","",Q45*(1-$W$5/100)) -> 1.0214665 | X45: =IF(OR(U45="",V45="",W45=""),"",IF(OR(U45>V45,U45<W45),"OUT","OK")) -> OK | Y45: =IF(X45<>"OUT","",($W$6+$W$7*(P45/$D$7)+$W$8*(P45/$D$7)^2))
A46: 31 | B46: 996.222 | C46: 108.21733 | D46: =C46/$J$8 -> 1.0821733 | E46: =IF(A46<=$D$10,$J$7/C46,"") | F46: =IF(A46<=$D$10,(C47-C45)/C46/(B45-B47)*1000000,"") | G46: =IF(A46>$D$10,($J$9-B46)/(B46*(D46-1)),"") -> 1.948478 | H46: =IF(A46<$D$10,"Single Phase",IF(A46=$D$10,"Bubble Point","Two Phase")) -> Two Phase | I46: =IF(A46<=$D$10,'QC Protocol'!$C$7+'QC Protocol'!$C$8*B46+'QC Protocol'!$C$9*B46^2+'QC Protocol'!$C$10*B46^3,'QC Protocol'!$C$18+'QC Protocol'!$C$19*B46+'QC Protocol'!$C$20*B46^2) -> 1.9529648 | J46: =IF(A46<=$D$10,D46-I46,IF(A46>$D$10,G46-I46,"")) -> -0.004486738 | K46: =IF(OR(J46="",J46=0),"",IF(A46<=$D$10,ABS(J46/D46)*100,ABS(J46/G46)*100)) -> 0.23026886 | L46: =IF(K46="","",IF(A46<=$D$10,IF(K46<'QC Protocol'!$C$26,"PASS",IF(K46<'QC Protocol'!$C$27,"WARN","FAIL")),IF(K46<'QC Protocol'!$C$28,"PASS",IF(K46<'QC Protocol'!$C$29,"WARN","FAIL")))) -> PASS | O46: =A46 -> 31 | P46: =B46 -> 996.222 | Q46: =D46 -> 1.0821733 | R46: =E46 | S46: =G46 -> 1.948478 | T46: =F46 | U46: =D46 -> 1.0821733 | V46: =IF(Q46="","",Q46*(1+$W$5/100)) -> 1.1038168 | W46: =IF(Q46="","",Q46*(1-$W$5/100)) -> 1.0605299 | X46: =IF(OR(U46="",V46="",W46=""),"",IF(OR(U46>V46,U46<W46),"OUT","OK")) -> OK | Y46: =IF(X46<>"OUT","",($W$6+$W$7*(P46/$D$7)+$W$8*(P46/$D$7)^2))
A47: 32 | B47: 883.0476 | C47: 116.25715 | D47: =C47/$J$8 -> 1.1625715 | E47: =IF(A47<=$D$10,$J$7/C47,"") | F47: =IF(A47<=$D$10,(C48-C46)/C47/(B46-B48)*1000000,"") | G47: =IF(A47>$D$10,($J$9-B47)/(B47*(D47-1)),"") -> 1.8994534 | H47: =IF(A47<$D$10,"Single Phase",IF(A47=$D$10,"Bubble Point","Two Phase")) -> Two Phase | I47: =IF(A47<=$D$10,'QC Protocol'!$C$7+'QC Protocol'!$C$8*B47+'QC Protocol'!$C$9*B47^2+'QC Protocol'!$C$10*B47^3,'QC Protocol'!$C$18+'QC Protocol'!$C$19*B47+'QC Protocol'!$C$20*B47^2) -> 1.9047418 | J47: =IF(A47<=$D$10,D47-I47,IF(A47>$D$10,G47-I47,"")) -> -0.0052883419 | K47: =IF(OR(J47="",J47=0),"",IF(A47<=$D$10,ABS(J47/D47)*100,ABS(J47/G47)*100)) -> 0.27841388 | L47: =IF(K47="","",IF(A47<=$D$10,IF(K47<'QC Protocol'!$C$26,"PASS",IF(K47<'QC Protocol'!$C$27,"WARN","FAIL")),IF(K47<'QC Protocol'!$C$28,"PASS",IF(K47<'QC Protocol'!$C$29,"WARN","FAIL")))) -> PASS | O47: =A47 -> 32 | P47: =B47 -> 883.0476 | Q47: =D47 -> 1.1625715 | R47: =E47 | S47: =G47 -> 1.8994534 | T47: =F47 | U47: =D47 -> 1.1625715 | V47: =IF(Q47="","",Q47*(1+$W$5/100)) -> 1.1858229 | W47: =IF(Q47="","",Q47*(1-$W$5/100)) -> 1.13932 | X47: =IF(OR(U47="",V47="",W47=""),"",IF(OR(U47>V47,U47<W47),"OUT","OK")) -> OK | Y47: =IF(X47<>"OUT","",($W$6+$W$7*(P47/$D$7)+$W$8*(P47/$D$7)^2))
A48: 33 | B48: 726.8798 | C48: 132.30582 | D48: =C48/$J$8 -> 1.3230582 | E48: =IF(A48<=$D$10,$J$7/C48,"") | F48: =IF(A48<=$D$10,(C49-C47)/C48/(B47-B49)*1000000,"") | G48: =IF(A48>$D$10,($J$9-B48)/(B48*(D48-1)),"") -> 1.8262587 | H48: =IF(A48<$D$10,"Single Phase",IF(A48=$D$10,"Bubble Point","Two Phase")) -> Two Phase | I48: =IF(A48<=$D$10,'QC Protocol'!$C$7+'QC Protocol'!$C$8*B48+'QC Protocol'!$C$9*B48^2+'QC Protocol'!$C$10*B48^3,'QC Protocol'!$C$18+'QC Protocol'!$C$19*B48+'QC Protocol'!$C$20*B48^2) -> 1.8289133 | J48: =IF(A48<=$D$10,D48-I48,IF(A48>$D$10,G48-I48,"")) -> -0.0026546117 | K48: =IF(OR(J48="",J48=0),"",IF(A48<=$D$10,ABS(J48/D48)*100,ABS(J48/G48)*100)) -> 0.14535792 | L48: =IF(K48="","",IF(A48<=$D$10,IF(K48<'QC Protocol'!$C$26,"PASS",IF(K48<'QC Protocol'!$C$27,"WARN","FAIL")),IF(K48<'QC Protocol'!$C$28,"PASS",IF(K48<'QC Protocol'!$C$29,"WARN","FAIL")))) -> PASS | O48: =A48 -> 33 | P48: =B48 -> 726.8798 | Q48: =D48 -> 1.3230582 | R48: =E48 | S48: =G48 -> 1.8262587 | T48: =F48 | U48: =D48 -> 1.3230582 | V48: =IF(Q48="","",Q48*(1+$W$5/100)) -> 1.3495193 | W48: =IF(Q48="","",Q48*(1-$W$5/100)) -> 1.296597 | X48: =IF(OR(U48="",V48="",W48=""),"",IF(OR(U48>V48,U48<W48),"OUT","OK")) -> OK | Y48: =IF(X48<>"OUT","",($W$6+$W$7*(P48/$D$7)+$W$8*(P48/$D$7)^2))
A49: 34 | B49: 581.8544 | C49: 156.33539 | D49: =C49/$J$8 -> 1.5633539 | E49: =IF(A49<=$D$10,$J$7/C49,"") | F49: =IF(A49<=$D$10,(C50-C48)/C49/(B48-B50)*1000000,"") | G49: =IF(A49>$D$10,($J$9-B49)/(B49*(D49-1)),"") -> 1.750742 | H49: =IF(A49<$D$10,"Single Phase",IF(A49=$D$10,"Bubble Point","Two Phase")) -> Two Phase | I49: =IF(A49<=$D$10,'QC Protocol'!$C$7+'QC Protocol'!$C$8*B49+'QC Protocol'!$C$9*B49^2+'QC Protocol'!$C$10*B49^3,'QC Protocol'!$C$18+'QC Protocol'!$C$19*B49+'QC Protocol'!$C$20*B49^2) -> 1.7488518 | J49: =IF(A49<=$D$10,D49-I49,IF(A49>$D$10,G49-I49,"")) -> 0.001890236 | K49: =IF(OR(J49="",J49=0),"",IF(A49<=$D$10,ABS(J49/D49)*100,ABS(J49/G49)*100)) -> 0.10796771 | L49: =IF(K49="","",IF(A49<=$D$10,IF(K49<'QC Protocol'!$C$26,"PASS",IF(K49<'QC Protocol'!$C$27,"WARN","FAIL")),IF(K49<'QC Protocol'!$C$28,"PASS",IF(K49<'QC Protocol'!$C$29,"WARN","FAIL")))) -> PASS | O49: =A49 -> 34 | P49: =B49 -> 581.8544 | Q49: =D49 -> 1.5633539 | R49: =E49 | S49: =G49 -> 1.750742 | T49: =F49 | U49: =D49 -> 1.5633539 | V49: =IF(Q49="","",Q49*(1+$W$5/100)) -> 1.594621 | W49: =IF(Q49="","",Q49*(1-$W$5/100)) -> 1.5320868 | X49: =IF(OR(U49="",V49="",W49=""),"",IF(OR(U49>V49,U49<W49),"OUT","OK")) -> OK | Y49: =IF(X49<>"OUT","",($W$6+$W$7*(P49/$D$7)+$W$8*(P49/$D$7)^2))
A50: 35 | B50: 464.6811 | C50: 188.39575 | D50: =C50/$J$8 -> 1.8839575 | E50: =IF(A50<=$D$10,$J$7/C50,"") | F50: =IF(A50<=$D$10,(C51-C49)/C50/(B49-B51)*1000000,"") | G50: =IF(A50>$D$10,($J$9-B50)/(B50*(D50-1)),"") -> 1.6823733 | H50: =IF(A50<$D$10,"Single Phase",IF(A50=$D$10,"Bubble Point","Two Phase")) -> Two Phase | I50: =IF(A50<=$D$10,'QC Protocol'!$C$7+'QC Protocol'!$C$8*B50+'QC Protocol'!$C$9*B50^2+'QC Protocol'!$C$10*B50^3,'QC Protocol'!$C$18+'QC Protocol'!$C$19*B50+'QC Protocol'!$C$20*B50^2) -> 1.6773833 | J50: =IF(A50<=$D$10,D50-I50,IF(A50>$D$10,G50-I50,"")) -> 0.0049899709 | K50: =IF(OR(J50="",J50=0),"",IF(A50<=$D$10,ABS(J50/D50)*100,ABS(J50/G50)*100)) -> 0.29660307 | L50: =IF(K50="","",IF(A50<=$D$10,IF(K50<'QC Protocol'!$C$26,"PASS",IF(K50<'QC Protocol'!$C$27,"WARN","FAIL")),IF(K50<'QC Protocol'!$C$28,"PASS",IF(K50<'QC Protocol'!$C$29,"WARN","FAIL")))) -> PASS | O50: =A50 -> 35 | P50: =B50 -> 464.6811 | Q50: =D50 -> 1.8839575 | R50: =E50 | S50: =G50 -> 1.6823733 | T50: =F50 | U50: =D50 -> 1.8839575 | V50: =IF(Q50="","",Q50*(1+$W$5/100)) -> 1.9216367 | W50: =IF(Q50="","",Q50*(1-$W$5/100)) -> 1.8462784 | X50: =IF(OR(U50="",V50="",W50=""),"",IF(OR(U50>V50,U50<W50),"OUT","OK")) -> OK | Y50: =IF(X50<>"OUT","",($W$6+$W$7*(P50/$D$7)+$W$8*(P50/$D$7)^2))
...

Sheet QC Protocol
B1: CCE QC PROTOCOL & DATA VALIDATION
B4: A. SINGLE-PHASE RELATIVE VOLUME FIT
B5: Fit Type: | C5: 3rd Order Polynomial
B6: Equation: | C6: RelVol = a₀ + a₁×P + a₂×P² + a₃×P³
B7: a₀ (Constant): | C7: 1.0193719
B8: a₁ (P coeff): | C8: -1.8480382e-05
B9: a₂ (P² coeff): | C9: 1.5408723e-09
B10: a₃ (P³ coeff): | C10: -7.172523e-14
B11: R-squared: | C11: =1-SUMPRODUCT(('CCE Calculation'!J16:J35)^2)/SUMPRODUCT(('CCE Calculation'!D16:D35-AVERAGE('CCE Calculation'!D16:D35))^2) -> 0.99999345
B12: Max Deviation (%): | C12: =MAX('CCE Calculation'!K16:K35) -> 0.01112747
B13: Mean Deviation (%): | C13: =AVERAGE('CCE Calculation'!K16:K35) -> 0.0046182161
B15: B. TWO-PHASE Y-FUNCTION FIT
B16: Fit Type: | C16: 2nd Order Polynomial
B17: Equation: | C17: Y = b₀ + b₁×P + b₂×P²
B18: b₀ (Constant): | C18: 1.3342654
B19: b₁ (P coeff): | C19: 0.00084098244
B20: b₂ (P² coeff): | C20: -2.2077087e-07
B21: R-squared: | C21: =1-SUMPRODUCT(('CCE Calculation'!J36:J55)^2)/SUMPRODUCT(('CCE Calculation'!G36:G55-AVERAGE('CCE Calculation'!G36:G55))^2) -> 0.99971814
B22: Max Deviation (%): | C22: =MAX('CCE Calculation'!K36:K55) -> 0.47254691
B23: Mean Deviation (%): | C23: =AVERAGE('CCE Calculation'!K36:K55) -> 0.14633352
B25: C. QC THRESHOLDS
B26: SP PASS threshold (%) | C26: 0.05
B27: SP WARN threshold (%) | C27: 0.1
B28: TP PASS threshold (%) | C28: 1
B29: TP WARN threshold (%) | C29: 2
B31: D. QC SUMMARY DASHBOARD
B32: SP Points PASS: | C32: =COUNTIF('CCE Calculation'!L16:L35,"PASS") -> 20
B33: SP Points WARN: | C33: =COUNTIF('CCE Calculation'!L16:L35,"WARN") -> 0
B34: SP Points FAIL: | C34: =COUNTIF('CCE Calculation'!L16:L35,"FAIL") -> 0
B36: TP Points PASS: | C36: =COUNTIF('CCE Calculation'!L36:L55,"PASS") -> 20
B37: TP Points WARN: | C37: =COUNTIF('CCE Calculation'!L36:L55,"WARN") -> 0
B38: TP Points FAIL: | C38: =COUNTIF('CCE Calculation'!L36:L55,"FAIL") -> 0
B40: OVERALL QC STATUS: | C40: =IF(OR(C34>0,C38>0),"CHECK FAILS",IF(OR(C33>0,C37>0),"REVIEW WARNINGS","ALL PASSED")) -> ALL PASSED
B43: Note | C43: These yellow coefficients are optional manual tuning inputs. Normal routine use does not require changing them unless refining the fit or comparing against simulation.

Sheet Mean Compressibility
A1: MEAN SINGLE-PHASE COMPRESSIBILITIES | G1: Dynamic Mean Compressibility (Any Selected Range)
A3: Range | B3: P_initial (psig) | C3: P_final (psig) | D3: Mean Comp (×10⁻⁶ psi⁻¹) | E3: Unit | G3: Start Pressure (psig) | H3: ='CCE Calculation'!AA5 -> 4029
A4: Range 1 | B4: =ROUND('CCE Calculation'!B16,0) -> 7015 | C4: =ROUND('CCE Calculation'!B19,0) -> 5531 | D4: =((('CCE Calculation'!D19-'CCE Calculation'!D16)/((('CCE Calculation'!D16+'CCE Calculation'!D19)/2))*1/('CCE Calculation'!B16-'CCE Calculation'!B19))*1000000) -> 7.9887326 | E4: ×10⁻⁶ psi⁻¹ | G4: End Pressure (psig) | H4: ='CCE Calculation'!AA6 -> 1175
A5: Range 2 | B5: =ROUND('CCE Calculation'!B19,0) -> 5531 | C5: =ROUND('CCE Calculation'!B23,0) -> 3939 | D5: =((('CCE Calculation'!D23-'CCE Calculation'!D19)/((('CCE Calculation'!D19+'CCE Calculation'!D23)/2))*1/('CCE Calculation'!B19-'CCE Calculation'!B23))*1000000) -> 9.2114781 | E5: ×10⁻⁶ psi⁻¹ | G5: Dynamic Mean Comp | H5: ='CCE Calculation'!AA7 -> 12.25064 | I5: ×10⁻⁶ psi⁻¹
A6: Range 3 | B6: =ROUND('CCE Calculation'!B23,0) -> 3939 | C6: =ROUND('CCE Calculation'!B27,0) -> 2031 | D6: =((('CCE Calculation'!D27-'CCE Calculation'!D23)/((('CCE Calculation'!D23+'CCE Calculation'!D27)/2))*1/('CCE Calculation'!B23-'CCE Calculation'!B27))*1000000) -> 11.437526 | E6: ×10⁻⁶ psi⁻¹
A7: Range 4 | B7: =ROUND('CCE Calculation'!B27,0) -> 2031 | C7: =ROUND('CCE Calculation'!B35,0) -> 1156 | D7: =((('CCE Calculation'!D35-'CCE Calculation'!D27)/((('CCE Calculation'!D27+'CCE Calculation'!D35)/2))*1/('CCE Calculation'!B27-'CCE Calculation'!B35))*1000000) -> 14.389899 | E7: ×10⁻⁶ psi⁻¹ | G7: Reservoir Pressure (psig) | H7: ='CCE Calculation'!D5 -> 3938.73
G8: Mean Comp from Reservoir Pressure to Psat | H8: =IF(OR(H7="",'CCE Calculation'!J9=""),"",((INDEX('CCE Calculation'!D:D,MATCH(H7,'CCE Calculation'!B:B,-1))-INDEX('CCE Calculation'!D:D,MATCH('CCE Calculation'!J9,'CCE Calculation'!B:B,-1)))/((INDEX('CCE Calculation'!D:D,MATCH(H7,'CCE Calculation'!B:B,-1))+INDEX('CCE Calculation'!D:D,MATCH('CCE Calculation'!J9,'CCE Calculation'!B:B,-1)))/2)*1/(INDEX('CCE Calculation'!B:B,MATCH(H7,'CCE Calculation'!B:B,-1))-'CCE Calculation'!J9)*1000000)) -> -12.365434 | I8: ×10⁻⁶ psi⁻¹
A9: Average (3939–1156 psig): | D9: =((('CCE Calculation'!D35-'CCE Calculation'!D23)/((('CCE Calculation'!D23+'CCE Calculation'!D35)/2))*1/('CCE Calculation'!B23-'CCE Calculation'!B35))*1000000) -> 12.365434

Sheet Summary
A1: CCE EXPERIMENT — SUMMARY
B3: SAMPLE INFO
B4: Client: | C4: ADNOC Onshore
B5: Well: | C5: SA 372 (Kharaib-2)
B6: Sample: | C6: #3, Chamber RF1168636
B7: Depth: | C7: 9105.00 MD (ft.)
B8: Temperature: | C8: ='CCE Calculation'!D6&" °F" -> 256 °F
B11: KEY RESULTS (linked)
B12: Psat (psig): | C12: ='CCE Calculation'!J9 -> 1155.73
B13: Density at Psat: | C13: ='CCE Calculation'!J10 -> 0.68560211
B14: SP Fit R² | C14: ='QC Protocol'!C11 -> 0.99999345
B15: TP Fit R² | C15: ='QC Protocol'!C21 -> 0.99971814
B16: Overall QC | C16: ='QC Protocol'!C40 -> ALL PASSED
B18: Open-safe corrected file | C18: Use this version

Sheet PVTsim Compare
A1: PVTsim Comparison & Final Accepted Values
A4: Fluid Type | B4: Black Oil
A6: Step | B6: Pressure | C6: Measured RelVol | D6: PVTsim RelVol | E6: ΔRelVol % | F6: Measured Density | G6: PVTsim Density | H6: ΔDensity % | I6: Measured Y | J6: PVTsim Y | K6: ΔY % | L6: Measured Inst Comp | M6: PVTsim Inst Comp | N6: ΔComp % | O6: Accepted Note
A7: ='CCE Calculation'!A16 -> 1 | B7: ='CCE Calculation'!B16 -> 7014.73 | C7: ='CCE Calculation'!D16 -> 0.94088229 | D7: 0.94088229 | E7: =IF(OR(D7="",C7="",C7=0),"",ABS(D7-C7)/C7*100) -> 0 | F7: ='CCE Calculation'!E16 -> 0.72868 | G7: 0.72868 | H7: =IF(OR(G7="",F7="",F7=0),"",ABS(G7-F7)/F7*100) -> 0 | I7: ='CCE Calculation'!G16 | K7: =IF(OR(J7="",I7="",I7=0),"",ABS(J7-I7)/ABS(I7)*100) | L7: ='CCE Calculation'!F16 -> 7.6804854 | M7: 7.6804854 | N7: =IF(OR(M7="",L7="",L7=0),"",ABS(M7-L7)/ABS(L7)*100) -> 0
A8: ='CCE Calculation'!A17 -> 2 | B8: ='CCE Calculation'!B17 -> 6525.9808 | C8: ='CCE Calculation'!D17 -> 0.9444142 | D8: 0.9444142 | E8: =IF(OR(D8="",C8="",C8=0),"",ABS(D8-C8)/C8*100) -> 0 | F8: ='CCE Calculation'!E17 -> 0.72595489 | G8: 0.72595489 | H8: =IF(OR(G8="",F8="",F8=0),"",ABS(G8-F8)/F8*100) -> 0 | I8: ='CCE Calculation'!G17 | K8: =IF(OR(J8="",I8="",I8=0),"",ABS(J8-I8)/ABS(I8)*100) | L8: ='CCE Calculation'!F17 -> 7.8223487 | M8: 7.8223487 | N8: =IF(OR(M8="",L8="",L8=0),"",ABS(M8-L8)/ABS(L8)*100) -> 0
A9: ='CCE Calculation'!A18 -> 3 | B9: ='CCE Calculation'!B18 -> 6029.4923 | C9: ='CCE Calculation'!D18 -> 0.94816077 | D9: 0.94816077 | E9: =IF(OR(D9="",C9="",C9=0),"",ABS(D9-C9)/C9*100) -> 0 | F9: ='CCE Calculation'!E18 -> 0.72308635 | G9: 0.72308635 | H9: =IF(OR(G9="",F9="",F9=0),"",ABS(G9-F9)/F9*100) -> 0 | I9: ='CCE Calculation'!G18 | K9: =IF(OR(J9="",I9="",I9=0),"",ABS(J9-I9)/ABS(I9)*100) | L9: ='CCE Calculation'!F18 -> 8.1481553 | M9: 8.1481553 | N9: =IF(OR(M9="",L9="",L9=0),"",ABS(M9-L9)/ABS(L9)*100) -> 0
A10: ='CCE Calculation'!A19 -> 4 | B10: ='CCE Calculation'!B19 -> 5531.1266 | C10: ='CCE Calculation'!D19 -> 0.95210021 | D10: 0.95210021 | E10: =IF(OR(D10="",C10="",C10=0),"",ABS(D10-C10)/C10*100) -> 0 | F10: ='CCE Calculation'!E19 -> 0.72009448 | G10: 0.72009448 | H10: =IF(OR(G10="",F10="",F10=0),"",ABS(G10-F10)/F10*100) -> 0 | I10: ='CCE Calculation'!G19 | K10: =IF(OR(J10="",I10="",I10=0),"",ABS(J10-I10)/ABS(I10)*100) | L10: ='CCE Calculation'!F19 -> 8.5164101 | M10: 8.5164101 | N10: =IF(OR(M10="",L10="",L10=0),"",ABS(M10-L10)/ABS(L10)*100) -> 0
A11: ='CCE Calculation'!A20 -> 5 | B11: ='CCE Calculation'!B20 -> 5026.7011 | C11: ='CCE Calculation'!D20 -> 0.95629188 | D11: 0.95629188 | E11: =IF(OR(D11="",C11="",C11=0),"",ABS(D11-C11)/C11*100) -> 0 | F11: ='CCE Calculation'!E20 -> 0.71693813 | G11: 0.71693813 | H11: =IF(OR(G11="",F11="",F11=0),"",ABS(G11-F11)/F11*100) -> 0 | I11: ='CCE Calculation'!G20 | K11: =IF(OR(J11="",I11="",I11=0),"",ABS(J11-I11)/ABS(I11)*100) | L11: ='CCE Calculation'!F20 -> 8.9279778 | M11: 8.9279778 | N11: =IF(OR(M11="",L11="",L11=0),"",ABS(M11-L11)/ABS(L11)*100) -> 0
A12: ='CCE Calculation'!A21 -> 6 | B12: ='CCE Calculation'!B21 -> 4527.747 | C12: ='CCE Calculation'!D21 -> 0.96066682 | D12: 0.96066682 | E12: =IF(OR(D12="",C12="",C12=0),"",ABS(D12-C12)/C12*100) -> 0 | F12: ='CCE Calculation'!E21 -> 0.71367314 | G12: 0.71367314 | H12: =IF(OR(G12="",F12="",F12=0),"",ABS(G12-F12)/F12*100) -> 0 | I12: ='CCE Calculation'!G21 | K12: =IF(OR(J12="",I12="",I12=0),"",ABS(J12-I12)/ABS(I12)*100) | L12: ='CCE Calculation'!F21 -> 9.3980839 | M12: 9.3980839 | N12: =IF(OR(M12="",L12="",L12=0),"",ABS(M12-L12)/ABS(L12)*100) -> 0
A13: ='CCE Calculation'!A22 -> 7 | B13: ='CCE Calculation'!B22 -> 4029.4572 | C13: ='CCE Calculation'!D22 -> 0.96529542 | D13: 0.96529542 | E13: =IF(OR(D13="",C13="",C13=0),"",ABS(D13-C13)/C13*100) -> 0 | F13: ='CCE Calculation'!E22 -> 0.71025107 | G13: 0.71025107 | H13: =IF(OR(G13="",F13="",F13=0),"",ABS(G13-F13)/F13*100) -> 0 | I13: ='CCE Calculation'!G22 | K13: =IF(OR(J13="",I13="",I13=0),"",ABS(J13-I13)/ABS(I13)*100) | L13: ='CCE Calculation'!F22 -> 9.6773324 | M13: 9.6773324 | N13: =IF(OR(M13="",L13="",L13=0),"",ABS(M13-L13)/ABS(L13)*100) -> 0
A14: ='CCE Calculation'!A23 -> 8 | B14: ='CCE Calculation'!B23 -> 3938.73 | C14: ='CCE Calculation'!D23 -> 0.96616911 | D14: 0.96616911 | E14: =IF(OR(D14="",C14="",C14=0),"",ABS(D14-C14)/C14*100) -> 0 | F14: ='CCE Calculation'!E23 -> 0.7096088 | G14: 0.7096088 | H14: =IF(OR(G14="",F14="",F14=0),"",ABS(G14-F14)/F14*100) -> 0 | I14: ='CCE Calculation'!G23 | K14: =IF(OR(J14="",I14="",I14=0),"",ABS(J14-I14)/ABS(I14)*100) | L14: ='CCE Calculation'!F23 -> 10.236258 | M14: 10.236258 | N14: =IF(OR(M14="",L14="",L14=0),"",ABS(M14-L14)/ABS(L14)*100) -> 1.7353576e-14
A15: ='CCE Calculation'!A24 -> 9 | B15: ='CCE Calculation'!B24 -> 3532.4847 | C15: ='CCE Calculation'!D24 -> 0.97021046 | D15: 0.97021046 | E15: =IF(OR(D15="",C15="",C15=0),"",ABS(D15-C15)/C15*100) -> 0 | F15: ='CCE Calculation'!E24 -> 0.70665297 | G15: 0.70665297 | H15: =IF(OR(G15="",F15="",F15=0),"",ABS(G15-F15)/F15*100) -> 0 | I15: ='CCE Calculation'!G24 | K15: =IF(OR(J15="",I15="",I15=0),"",ABS(J15-I15)/ABS(I15)*100) | L15: ='CCE Calculation'!F24 -> 10.623103 | M15: 10.623103 | N15: =IF(OR(M15="",L15="",L15=0),"",ABS(M15-L15)/ABS(L15)*100) -> 0
A16: ='CCE Calculation'!A25 -> 10 | B16: ='CCE Calculation'!B25 -> 3031.1977 | C16: ='CCE Calculation'!D25 -> 0.97552272 | D16: 0.97552272 | E16: =IF(OR(D16="",C16="",C16=0),"",ABS(D16-C16)/C16*100) -> 0 | F16: ='CCE Calculation'!E25 -> 0.70280486 | G16: 0.70280486 | H16: =IF(OR(G16="",F16="",F16=0),"",ABS(G16-F16)/F16*100) -> 0 | I16: ='CCE Calculation'!G25 | K16: =IF(OR(J16="",I16="",I16=0),"",ABS(J16-I16)/ABS(I16)*100) | L16: ='CCE Calculation'!F25 -> 11.298114 | M16: 11.298114 | N16: =IF(OR(M16="",L16="",L16=0),"",ABS(M16-L16)/ABS(L16)*100) -> 4.7167788e-14
A17: ='CCE Calculation'!A26 -> 11 | B17: ='CCE Calculation'!B26 -> 2529.5335 | C17: ='CCE Calculation'!D26 -> 0.98126455 | D17: 0.98126455 | E17: =IF(OR(D17="",C17="",C17=0),"",ABS(D17-C17)/C17*100) -> 0 | F17: ='CCE Calculation'!E26 -> 0.69869242 | G17: 0.69869242 | H17: =IF(OR(G17="",F17="",F17=0),"",ABS(G17-F17)/F17*100) -> 0 | I17: ='CCE Calculation'!G26 | K17: =IF(OR(J17="",I17="",I17=0),"",ABS(J17-I17)/ABS(I17)*100) | L17: ='CCE Calculation'!F26 -> 12.186544 | N17: =IF(OR(M17="",L17="",L17=0),"",ABS(M17-L17)/ABS(L17)*100)
A18: ='CCE Calculation'!A27 -> 12 | B18: ='CCE Calculation'!B27 -> 2031.2057 | C18: ='CCE Calculation'!D27 -> 0.98748085 | D18: 0.98748085 | E18: =IF(OR(D18="",C18="",C18=0),"",ABS(D18-C18)/C18*100) -> 0 | F18: ='CCE Calculation'!E27 -> 0.69429408 | G18: 0.69429408 | H18: =IF(OR(G18="",F18="",F18=0),"",ABS(G18-F18)/F18*100) -> 0 | I18: ='CCE Calculation'!G27 | K18: =IF(OR(J18="",I18="",I18=0),"",ABS(J18-I18)/ABS(I18)*100) | L18: ='CCE Calculation'!F27 -> 13.279019 | N18: =IF(OR(M18="",L18="",L18=0),"",ABS(M18-L18)/ABS(L18)*100)
A19: ='CCE Calculation'!A28 -> 13 | B19: ='CCE Calculation'!B28 -> 1528.4731 | C19: ='CCE Calculation'!D28 -> 0.99439123 | D19: 0.99439123 | E19: =IF(OR(D19="",C19="",C19=0),"",ABS(D19-C19)/C19*100) -> 0 | F19: ='CCE Calculation'!E28 -> 0.68946918 | G19: 0.68946918 | H19: =IF(OR(G19="",F19="",F19=0),"",ABS(G19-F19)/F19*100) -> 0 | I19: ='CCE Calculation'!G28 | K19: =IF(OR(J19="",I19="",I19=0),"",ABS(J19-I19)/ABS(I19)*100) | L19: ='CCE Calculation'!F28 -> 14.172776 | N19: =IF(OR(M19="",L19="",L19=0),"",ABS(M19-L19)/ABS(L19)*100)
A20: ='CCE Calculation'!A29 -> 14 | B20: ='CCE Calculation'!B29 -> 1295.073 | C20: ='CCE Calculation'!D29 -> 0.99785538 | D20: 0.99785538 | E20: =IF(OR(D20="",C20="",C20=0),"",ABS(D20-C20)/C20*100) -> 0 | F20: ='CCE Calculation'!E29 -> 0.68707562 | G20: 0.68707562 | H20: =IF(OR(G20="",F20="",F20=0),"",ABS(G20-F20)/F20*100) -> 0 | I20: ='CCE Calculation'!G29 | K20: =IF(OR(J20="",I20="",I20=0),"",ABS(J20-I20)/ABS(I20)*100) | L20: ='CCE Calculation'!F29 -> 14.944624 | N20: =IF(OR(M20="",L20="",L20=0),"",ABS(M20-L20)/ABS(L20)*100)
A21: ='CCE Calculation'!A30 -> 15 | B21: ='CCE Calculation'!B30 -> 1249.8194 | C21: ='CCE Calculation'!D30 -> 0.99854668 | D21: 0.99854668 | E21: =IF(OR(D21="",C21="",C21=0),"",ABS(D21-C21)/C21*100) -> 0 | F21: ='CCE Calculation'!E30 -> 0.68659996 | G21: 0.68659996 | H21: =IF(OR(G21="",F21="",F21=0),"",ABS(G21-F21)/F21*100) -> 0 | I21: ='CCE Calculation'!G30 | K21: =IF(OR(J21="",I21="",I21=0),"",ABS(J21-I21)/ABS(I21)*100) | L21: ='CCE Calculation'!F30 -> 15.32829 | N21: =IF(OR(M21="",L21="",L21=0),"",ABS(M21-L21)/ABS(L21)*100)
A22: ='CCE Calculation'!A31 -> 16 | B22: ='CCE Calculation'!B31 -> 1229.3027 | C22: ='CCE Calculation'!D31 -> 0.99886206 | D22: 0.99886206 | E22: =IF(OR(D22="",C22="",C22=0),"",ABS(D22-C22)/C22*100) -> 0 | F22: ='CCE Calculation'!E31 -> 0.68638317 | G22: 0.68638317 | H22: =IF(OR(G22="",F22="",F22=0),"",ABS(G22-F22)/F22*100) -> 0 | I22: ='CCE Calculation'!G31 | K22: =IF(OR(J22="",I22="",I22=0),"",ABS(J22-I22)/ABS(I22)*100) | L22: ='CCE Calculation'!F31 -> 15.415463 | N22: =IF(OR(M22="",L22="",L22=0),"",ABS(M22-L22)/ABS(L22)*100)
A23: ='CCE Calculation'!A32 -> 17 | B23: ='CCE Calculation'!B32 -> 1209.9316 | C23: ='CCE Calculation'!D32 -> 0.99916087 | D23: 0.99916087 | E23: =IF(OR(D23="",C23="",C23=0),"",ABS(D23-C23)/C23*100) -> 0 | F23: ='CCE Calculation'!E32 -> 0.6861779 | G23: 0.6861779 | H23: =IF(OR(G23="",F23="",F23=0),"",ABS(G23-F23)/F23*100) -> 0 | I23: ='CCE Calculation'!G32 | K23: =IF(OR(J23="",I23="",I23=0),"",ABS(J23-I23)/ABS(I23)*100) | L23: ='CCE Calculation'!F32 -> 15.461318 | N23: =IF(OR(M23="",L23="",L23=0),"",ABS(M23-L23)/ABS(L23)*100)
A24: ='CCE Calculation'!A33 -> 18 | B24: ='CCE Calculation'!B33 -> 1190.466 | C24: ='CCE Calculation'!D33 -> 0.99946202 | D24: 0.99946202 | E24: =IF(OR(D24="",C24="",C24=0),"",ABS(D24-C24)/C24*100) -> 0 | F24: ='CCE Calculation'!E33 -> 0.68597114 | G24: 0.68597114 | H24: =IF(OR(G24="",F24="",F24=0),"",ABS(G24-F24)/F24*100) -> 0 | I24: ='CCE Calculation'!G33 | K24: =IF(OR(J24="",I24="",I24=0),"",ABS(J24-I24)/ABS(I24)*100) | L24: ='CCE Calculation'!F33 -> 15.492726 | N24: =IF(OR(M24="",L24="",L24=0),"",ABS(M24-L24)/ABS(L24)*100)
A25: ='CCE Calculation'!A34 -> 19 | B25: ='CCE Calculation'!B34 -> 1174.8298 | C25: ='CCE Calculation'!D34 -> 0.9997044 | D25: 0.9997044 | E25: =IF(OR(D25="",C25="",C25=0),"",ABS(D25-C25)/C25*100) -> 0 | F25: ='CCE Calculation'!E34 -> 0.68580483 | H25: =IF(OR(G25="",F25="",F25=0),"",ABS(G25-F25)/F25*100) | I25: ='CCE Calculation'!G34 | K25: =IF(OR(J25="",I25="",I25=0),"",ABS(J25-I25)/ABS(I25)*100) | L25: ='CCE Calculation'!F34 -> 15.492189 | N25: =IF(OR(M25="",L25="",L25=0),"",ABS(M25-L25)/ABS(L25)*100)
A26: ='CCE Calculation'!A35 -> 20 | B26: ='CCE Calculation'!B35 -> 1155.73 | C26: ='CCE Calculation'!D35 -> 1 | D26: 1 | E26: =IF(OR(D26="",C26="",C26=0),"",ABS(D26-C26)/C26*100) -> 0 | F26: ='CCE Calculation'!E35 -> 0.68560211 | H26: =IF(OR(G26="",F26="",F26=0),"",ABS(G26-F26)/F26*100) | I26: ='CCE Calculation'!G35 | K26: =IF(OR(J26="",I26="",I26=0),"",ABS(J26-I26)/ABS(I26)*100) | L26: ='CCE Calculation'!F35 -> 85.16668 | N26: =IF(OR(M26="",L26="",L26=0),"",ABS(M26-L26)/ABS(L26)*100)
A27: ='CCE Calculation'!A36 -> 21 | B27: ='CCE Calculation'!B36 -> 1151.8876 | C27: ='CCE Calculation'!D36 -> 1.0016583 | D27: 1.0016583 | E27: =IF(OR(D27="",C27="",C27=0),"",ABS(D27-C27)/C27*100) -> 0 | F27: ='CCE Calculation'!E36 | H27: =IF(OR(G27="",F27="",F27=0),"",ABS(G27-F27)/F27*100) | I27: ='CCE Calculation'!G36 -> 2.0115327 | J27: 2.0115327 | K27: =IF(OR(J27="",I27="",I27=0),"",ABS(J27-I27)/ABS(I27)*100) -> 2.2077156e-14 | L27: ='CCE Calculation'!F36 | N27: =IF(OR(M27="",L27="",L27=0),"",ABS(M27-L27)/ABS(L27)*100)
A28: ='CCE Calculation'!A37 -> 22 | B28: ='CCE Calculation'!B37 -> 1151.5456 | C28: ='CCE Calculation'!D37 -> 1.0018066 | D28: 1.0018066 | E28: =IF(OR(D28="",C28="",C28=0),"",ABS(D28-C28)/C28*100) -> 0 | F28: ='CCE Calculation'!E37 | H28: =IF(OR(G28="",F28="",F28=0),"",ABS(G28-F28)/F28*100) | I28: ='CCE Calculation'!G37 -> 2.0113991 | J28: 2.0113991 | K28: =IF(OR(J28="",I28="",I28=0),"",ABS(J28-I28)/ABS(I28)*100) -> 0 | L28: ='CCE Calculation'!F37 | N28: =IF(OR(M28="",L28="",L28=0),"",ABS(M28-L28)/ABS(L28)*100)
A29: ='CCE Calculation'!A38 -> 23 | B29: ='CCE Calculation'!B38 -> 1150.7911 | C29: ='CCE Calculation'!D38 -> 1.002134 | D29: 1.002134 | E29: =IF(OR(D29="",C29="",C29=0),"",ABS(D29-C29)/C29*100) -> 0 | F29: ='CCE Calculation'!E38 | H29: =IF(OR(G29="",F29="",F29=0),"",ABS(G29-F29)/F29*100) | I29: ='CCE Calculation'!G38 -> 2.0111041 | J29: 2.0111041 | K29: =IF(OR(J29="",I29="",I29=0),"",ABS(J29-I29)/ABS(I29)*100) -> 2.2081861e-14 | L29: ='CCE Calculation'!F38 | N29: =IF(OR(M29="",L29="",L29=0),"",ABS(M29-L29)/ABS(L29)*100)
A30: ='CCE Calculation'!A39 -> 24 | B30: ='CCE Calculation'!B39 -> 1148.6789 | C30: ='CCE Calculation'!D39 -> 1.0030535 | D30: 1.0030535 | E30: =IF(OR(D30="",C30="",C30=0),"",ABS(D30-C30)/C30*100) -> 0 | F30: ='CCE Calculation'!E39 | H30: =IF(OR(G30="",F30="",F30=0),"",ABS(G30-F30)/F30*100) | I30: ='CCE Calculation'!G39 -> 2.0102778 | J30: 2.0102778 | K30: =IF(OR(J30="",I30="",I30=0),"",ABS(J30-I30)/ABS(I30)*100) -> 2.2090937e-14 | L30: ='CCE Calculation'!F39 | N30: =IF(OR(M30="",L30="",L30=0),"",ABS(M30-L30)/ABS(L30)*100)
A31: ='CCE Calculation'!A40 -> 25 | B31: ='CCE Calculation'!B40 -> 1147.4116 | C31: ='CCE Calculation'!D40 -> 1.0036072 | D31: 1.0036072 | E31: =IF(OR(D31="",C31="",C31=0),"",ABS(D31-C31)/C31*100) -> 0 | F31: ='CCE Calculation'!E40 | H31: =IF(OR(G31="",F31="",F31=0),"",ABS(G31-F31)/F31*100) | I31: ='CCE Calculation'!G40 -> 2.0097817 | J31: 2.0097817 | K31: =IF(OR(J31="",I31="",I31=0),"",ABS(J31-I31)/ABS(I31)*100) -> 0 | L31: ='CCE Calculation'!F40 | N31: =IF(OR(M31="",L31="",L31=0),"",ABS(M31-L31)/ABS(L31)*100)
A32: ='CCE Calculation'!A41 -> 26 | B32: ='CCE Calculation'!B41 -> 1142.4438 | C32: ='CCE Calculation'!D41 -> 1.0057921 | D32: 1.0057921 | E32: =IF(OR(D32="",C32="",C32=0),"",ABS(D32-C32)/C32*100) -> 0 | F32: ='CCE Calculation'!E41 | H32: =IF(OR(G32="",F32="",F32=0),"",ABS(G32-F32)/F32*100) | I32: ='CCE Calculation'!G41 -> 2.0078343 | J32: 2.0078343 | K32: =IF(OR(J32="",I32="",I32=0),"",ABS(J32-I32)/ABS(I32)*100) -> 0 | L32: ='CCE Calculation'!F41 | N32: =IF(OR(M32="",L32="",L32=0),"",ABS(M32-L32)/ABS(L32)*100)
A33: ='CCE Calculation'!A42 -> 27 | B33: ='CCE Calculation'!B42 -> 1138.6956 | C33: ='CCE Calculation'!D42 -> 1.0074561 | E33: =IF(OR(D33="",C33="",C33=0),"",ABS(D33-C33)/C33*100) | F33: ='CCE Calculation'!E42 | H33: =IF(OR(G33="",F33="",F33=0),"",ABS(G33-F33)/F33*100) | I33: ='CCE Calculation'!G42 -> 2.0063623 | J33: 2.0063623 | K33: =IF(OR(J33="",I33="",I33=0),"",ABS(J33-I33)/ABS(I33)*100) -> 2.2134049e-14 | L33: ='CCE Calculation'!F42 | N33: =IF(OR(M33="",L33="",L33=0),"",ABS(M33-L33)/ABS(L33)*100)
