Workbook
Name Bo_fb: Sample_Info!$E$14
Name MB_error: DV_Calc!$B$47
Name MB_status: DV_Calc!$B$48
Name MolarBalance_QC: Material_Balance_QC!$B$85
Name Psat: Sample_Info!$B$13
Name RhoAtPsat: Sample_Info!$E$13
Name Rs_fb: Sample_Info!$B$14
Name V_at_Psat: DV_Input!$E$9
Name V_at_ResP: DV_Input!$B$9
Name V_sto: DV_Input!$B$8

Sheet Sample_Info
A1: ADRIC — DIFFERENTIAL VAPORIZATION CALCULATION (v6.2, Water Pump Method)
A2: Live-formula DV calc sheet. Yellow = inputs. Purple = key deliverables. All calcs link across tabs.
A4: BLOCK A — PROJECT & SAMPLE INFORMATION
A5: Client | B5: ADNOC Onshore | D5: Field | E5: Upper Zakum
A6: Well | B6: WELL-X | D6: Reservoir | E6: Kharaib-2
A7: Sample ID | B7: SA-372 | D7: Chamber / Cylinder No. | E7: RF1168636
A8: Sampling Depth (MD ft) | B8: 9105 | D8: Sampling Date | E8: 2026-04-12
A9: Fluid Type | B9: Black Oil | D9: Project No. | E9: ADRIC-PVT-2026-014
A11: BLOCK B — FLUID REFERENCE DATA (from CCE, HPHT and Flash tests)
A12: Reservoir Pressure (psig) | B12: 3939 | D12: Reservoir Temperature (°F) | E12: 256
A13: Bubble Point Psat from CCE (psig) | B13: 1156 | D13: Density at Psat from CCE (g/cc) | E13: 0.6856
A14: Flash GOR Rs_fb (surface separator) (scf/STB) | B14: 521 | D14: Flash Bo_fb (surface separator) (rb/STB) | E14: 1.331
A15: Field GOR Rsi (scf/STB) | B15: 521 | D15: STO API (°) | E15: 35.43
A16: STO Density @ 60°F (g/cc) | B16: 0.8479 | D16: STO MW (g/mol) | E16: 195
A18: BLOCK C — PREPARATION TEAM
A19: Analyst | B19: M. Athif | D19: Reviewer | E19: A. Abbas
A20: Approver | B20: M. S. Alhammadi | D20: Test Date | E20: 2026-07-04

Sheet DV_Input
A1: DIFFERENTIAL VAPORIZATION — STAGE MEASUREMENTS (v6.2, Water Pump Method)
A2: Enter yellow measurements at each stage. Row 23 = Bubble Point (Stage 1). Depletion below Psat = gas liberation.
A4: BLOCK A — TEST REFERENCE (linked from Sample_Info + new inputs)
A5: Bubble Point Psat (psig) | B5: =Sample_Info!B13 -> 1156 | D5: Density @ Psat (g/cc) | E5: =Sample_Info!E13 -> 0.6856
A6: Reservoir Temperature (°F) | B6: =Sample_Info!E12 -> 256 | D6: Reservoir Pressure (psig) | E6: =Sample_Info!B12 -> 3939
A7: Flash Rs_fb (surface, scf/STB) | B7: =Sample_Info!B14 -> 521 | D7: Flash Bo_fb (surface, rb/STB) | E7: =Sample_Info!E14 -> 1.331
A8: Residual Oil Volume V_sto @ 60°F (cc) | B8: 476 | D8: Bubble Point Stage No. | E8: 1
A9: 🟣 Volume at Working (Reservoir) Pressure (cc) | B9: 350 | D9: 🟣 Volume of Oil at Psat (cc) | E9: 633.5
A10: STO Density from Composition (Compositions_Master X66) | B10: =Compositions_Master!X66 -> 0.84409943 | D10: STO Density Override (manual, g/cc) | E10: 0.8479
A11: STO MW from Composition (Compositions_Master X64) | B11: =Compositions_Master!X64 -> 219.62955 | D11: STO MW Override (manual, g/mol) | E11: 195
A12: 🟣 Reservoir Fluid MW (Compositions_Master F64) | B12: =Compositions_Master!F64 -> 0 | D12: 🟣 Reservoir Fluid Density (Compositions_Master F66) | E12: =Compositions_Master!F66 -> 0
A14: BLOCK B — GASOMETER / BASE CONDITIONS (Constants)
A15: Barometric pressure (mbar) | B15: 1013.25 | D15: Back pressure (mbar) | E15: 0
A16: Standard pressure P_std (mbar) | B16: 1015.5981 | D16: Standard temperature T_std (K) | E16: 288.7056
A17: Air MW (g/mol) | B17: 28.964 | D17: scf per lbmol @ std | E17: 379.482
A18: cc per scf | B18: 28316.85 | D18: cc per STB | E18: 158987.29
A20: BLOCK C — STAGE MEASUREMENTS (Enter yellow inputs per stage; row 23 = Bubble Point)
A22: Stage # | B22: P (psia) | C22: T (°F) | D22: V_oil BEFORE gas removal (cc) | E22: V_oil AFTER gas removal (cc) | F22: V_gas init (cc) | G22: V_gas final (cc) | H22: V_gas_meas (cc) | I22: P_meas (mbar) | J22: T_meas (°C) | K22: V_gas_std (cc) | L22: V_gas_std (scf) | M22: Gas gravity (linked) | N22: Gas Z (input) | O22: Oil viscosity (cP, opt) | P22: Notes
A23: 1 | B23: 1156 | C23: =$B$6 -> 256 | D23: 633.5 | E23: 633.5 | F23: 0 | G23: 0 | H23: =IF(AND(F23="",G23=""),"",IF(F23="",0,G23-F23)) -> 0 | I23: =$B$15 -> 1013.25 | J23: 20 | K23: =IF(OR(H23="",H23=0),0,H23*(I23/$B$16)*($E$16/(273.15+J23))) -> 0 | L23: =K23/$B$18 -> 0 | M23: 0 | N23: 1 | P23: Bubble Point
A24: 2 | C24: =$B$6 -> 256 | H24: =IF(AND(F24="",G24=""),"",IF(F24="",0,G24-F24)) | I24: =$B$15 -> 1013.25 | J24: 20 | K24: =IF(OR(H24="",H24=0),0,H24*(I24/$B$16)*($E$16/(273.15+J24))) -> 0 | L24: =K24/$B$18 -> 0 | M24: =Compositions_Master!H67 -> 0.8847653 | N24: 1
A25: 3 | C25: =$B$6 -> 256 | H25: =IF(AND(F25="",G25=""),"",IF(F25="",0,G25-F25)) | I25: =$B$15 -> 1013.25 | J25: 20 | K25: =IF(OR(H25="",H25=0),0,H25*(I25/$B$16)*($E$16/(273.15+J25))) -> 0 | L25: =K25/$B$18 -> 0 | M25: =Compositions_Master!J67 -> 0.92152059 | N25: 1
A26: 4 | C26: =$B$6 -> 256 | H26: =IF(AND(F26="",G26=""),"",IF(F26="",0,G26-F26)) | I26: =$B$15 -> 1013.25 | J26: 20 | K26: =IF(OR(H26="",H26=0),0,H26*(I26/$B$16)*($E$16/(273.15+J26))) -> 0 | L26: =K26/$B$18 -> 0 | M26: =Compositions_Master!L67 -> 0.97527698 | N26: 1
A27: 5 | C27: =$B$6 -> 256 | H27: =IF(AND(F27="",G27=""),"",IF(F27="",0,G27-F27)) | I27: =$B$15 -> 1013.25 | J27: 20 | K27: =IF(OR(H27="",H27=0),0,H27*(I27/$B$16)*($E$16/(273.15+J27))) -> 0 | L27: =K27/$B$18 -> 0 | M27: =Compositions_Master!N67 -> 1.0843268 | N27: 1
A28: 6 | C28: =$B$6 -> 256 | H28: =IF(AND(F28="",G28=""),"",IF(F28="",0,G28-F28)) | I28: =$B$15 -> 1013.25 | J28: 20 | K28: =IF(OR(H28="",H28=0),0,H28*(I28/$B$16)*($E$16/(273.15+J28))) -> 0 | L28: =K28/$B$18 -> 0 | M28: =Compositions_Master!P67 -> 1.3658778 | N28: 1
A29: 7 | C29: =$B$6 -> 256 | H29: =IF(AND(F29="",G29=""),"",IF(F29="",0,G29-F29)) | I29: =$B$15 -> 1013.25 | J29: 20 | K29: =IF(OR(H29="",H29=0),0,H29*(I29/$B$16)*($E$16/(273.15+J29))) -> 0 | L29: =K29/$B$18 -> 0 | M29: =Compositions_Master!R67 -> 2.3076994 | N29: 1
A30: 8 | C30: =$B$6 -> 256 | H30: =IF(AND(F30="",G30=""),"",IF(F30="",0,G30-F30)) | I30: =$B$15 -> 1013.25 | J30: 20 | K30: =IF(OR(H30="",H30=0),0,H30*(I30/$B$16)*($E$16/(273.15+J30))) -> 0 | L30: =K30/$B$18 -> 0 | M30: =Compositions_Master!T67 -> 0 | N30: 1
A31: 9 | C31: =$B$6 -> 256 | H31: =IF(AND(F31="",G31=""),"",IF(F31="",0,G31-F31)) | I31: =$B$15 -> 1013.25 | J31: 20 | K31: =IF(OR(H31="",H31=0),0,H31*(I31/$B$16)*($E$16/(273.15+J31))) -> 0 | L31: =K31/$B$18 -> 0 | M31: =Compositions_Master!V67 -> 0 | N31: 1
A32: 10 | C32: =$B$6 -> 256 | H32: =IF(AND(F32="",G32=""),"",IF(F32="",0,G32-F32)) | I32: =$B$15 -> 1013.25 | J32: 20 | K32: =IF(OR(H32="",H32=0),0,H32*(I32/$B$16)*($E$16/(273.15+J32))) -> 0 | L32: =K32/$B$18 -> 0 | M32: 0 | N32: 1
A33: 11 | C33: =$B$6 -> 256 | H33: =IF(AND(F33="",G33=""),"",IF(F33="",0,G33-F33)) | I33: =$B$15 -> 1013.25 | J33: 20 | K33: =IF(OR(H33="",H33=0),0,H33*(I33/$B$16)*($E$16/(273.15+J33))) -> 0 | L33: =K33/$B$18 -> 0 | M33: 0 | N33: 1
A34: 12 | C34: =$B$6 -> 256 | H34: =IF(AND(F34="",G34=""),"",IF(F34="",0,G34-F34)) | I34: =$B$15 -> 1013.25 | J34: 20 | K34: =IF(OR(H34="",H34=0),0,H34*(I34/$B$16)*($E$16/(273.15+J34))) -> 0 | L34: =K34/$B$18 -> 0 | M34: 0 | N34: 1
A35: 13 | C35: =$B$6 -> 256 | H35: =IF(AND(F35="",G35=""),"",IF(F35="",0,G35-F35)) | I35: =$B$15 -> 1013.25 | J35: 20 | K35: =IF(OR(H35="",H35=0),0,H35*(I35/$B$16)*($E$16/(273.15+J35))) -> 0 | L35: =K35/$B$18 -> 0 | M35: 0 | N35: 1
A36: 14 | C36: =$B$6 -> 256 | H36: =IF(AND(F36="",G36=""),"",IF(F36="",0,G36-F36)) | I36: =$B$15 -> 1013.25 | J36: 20 | K36: =IF(OR(H36="",H36=0),0,H36*(I36/$B$16)*($E$16/(273.15+J36))) -> 0 | L36: =K36/$B$18 -> 0 | M36: 0 | N36: 1
A37: 15 | C37: =$B$6 -> 256 | H37: =IF(AND(F37="",G37=""),"",IF(F37="",0,G37-F37)) | I37: =$B$15 -> 1013.25 | J37: 20 | K37: =IF(OR(H37="",H37=0),0,H37*(I37/$B$16)*($E$16/(273.15+J37))) -> 0 | L37: =K37/$B$18 -> 0 | M37: 0 | N37: 1
A38: 16 | C38: =$B$6 -> 256 | H38: =IF(AND(F38="",G38=""),"",IF(F38="",0,G38-F38)) | I38: =$B$15 -> 1013.25 | J38: 20 | K38: =IF(OR(H38="",H38=0),0,H38*(I38/$B$16)*($E$16/(273.15+J38))) -> 0 | L38: =K38/$B$18 -> 0 | M38: 0 | N38: 1
A39: 17 | C39: =$B$6 -> 256 | H39: =IF(AND(F39="",G39=""),"",IF(F39="",0,G39-F39)) | I39: =$B$15 -> 1013.25 | J39: 20 | K39: =IF(OR(H39="",H39=0),0,H39*(I39/$B$16)*($E$16/(273.15+J39))) -> 0 | L39: =K39/$B$18 -> 0 | M39: 0 | N39: 1
A40: 18 | C40: =$B$6 -> 256 | H40: =IF(AND(F40="",G40=""),"",IF(F40="",0,G40-F40)) | I40: =$B$15 -> 1013.25 | J40: 20 | K40: =IF(OR(H40="",H40=0),0,H40*(I40/$B$16)*($E$16/(273.15+J40))) -> 0 | L40: =K40/$B$18 -> 0 | M40: 0 | N40: 1
A41: 19 | C41: =$B$6 -> 256 | H41: =IF(AND(F41="",G41=""),"",IF(F41="",0,G41-F41)) | I41: =$B$15 -> 1013.25 | J41: 20 | K41: =IF(OR(H41="",H41=0),0,H41*(I41/$B$16)*($E$16/(273.15+J41))) -> 0 | L41: =K41/$B$18 -> 0 | M41: 0 | N41: 1
A42: 20 | C42: =$B$6 -> 256 | H42: =IF(AND(F42="",G42=""),"",IF(F42="",0,G42-F42)) | I42: =$B$15 -> 1013.25 | J42: 20 | K42: =IF(OR(H42="",H42=0),0,H42*(I42/$B$16)*($E$16/(273.15+J42))) -> 0 | L42: =K42/$B$18 -> 0 | M42: 0 | N42: 1
A43: 21 | C43: =$B$6 -> 256 | H43: =IF(AND(F43="",G43=""),"",IF(F43="",0,G43-F43)) | I43: =$B$15 -> 1013.25 | J43: 20 | K43: =IF(OR(H43="",H43=0),0,H43*(I43/$B$16)*($E$16/(273.15+J43))) -> 0 | L43: =K43/$B$18 -> 0 | M43: 0 | N43: 1
... A48: 26 | C48: =$B$6 -> 256 | H48: =IF(AND(F48="",G48=""),"",IF(F48="",0,G48-F48)) | I48: =$B$15 -> 1013.25 | J48: 20 | K48: =IF(OR(H48="",H48=0),0,H48*(I48/$B$16)*($E$16/(273.15+J48))) -> 0 | L48: =K48/$B$18 -> 0 | M48: 0 | N48: 1

Sheet Component_Properties
A1: COMPONENT PROPERTIES — KATZ-FIROOZABADI STANDARDS (52 components to C36+)
A2: Reference values. All locked (grey) EXCEPT C36+ MW (D56, yellow) which varies per sample.
A4: # | B4: Code | C4: Name | D4: MW (g/mol) | E4: Density (g/cc) | F4: Tb (°R) | G4: Pc (psia) | H4: Tc (°R) | I4: Molar Vol (cc/gmol)
A5: 1 | B5: H2 | C5: Hydrogen | D5: 2.016 | E5: 0.0711 | F5: 36.7 | G5: 188 | H5: 59.4 | I5: =D5/E5 -> 28.35443
A6: 2 | B6: H2S | C6: Hydrogen Sulfide | D6: 34.0809 | E6: 0.8006 | F6: 383.1 | G6: 1300 | H6: 672.4 | I6: =D6/E6 -> 42.569198
A7: 3 | B7: CO2 | C7: Carbon Dioxide | D7: 44.0095 | E7: 0.818 | F7: 350 | G7: 1071 | H7: 547.6 | I7: =D7/E7 -> 53.801345
A8: 4 | B8: N2 | C8: Nitrogen | D8: 28.0134 | E8: 0.8094 | F8: 139.3 | G8: 493 | H8: 227.2 | I8: =D8/E8 -> 34.610082
A9: 5 | B9: C1 | C9: Methane | D9: 16.043 | E9: 0.3 | F9: 200.7 | G9: 666.4 | H9: 343 | I9: =D9/E9 -> 53.476667
A10: 6 | B10: C2 | C10: Ethane | D10: 30.07 | E10: 0.3562 | F10: 332.2 | G10: 706.5 | H10: 549.6 | I10: =D10/E10 -> 84.418866
A11: 7 | B11: C3 | C11: Propane | D11: 44.097 | E11: 0.507 | F11: 415.9 | G11: 616 | H11: 665.7 | I11: =D11/E11 -> 86.976331
A12: 8 | B12: iC4 | C12: i-Butane | D12: 58.123 | E12: 0.5629 | F12: 470.6 | G12: 527.9 | H12: 734.1 | I12: =D12/E12 -> 103.25635
A13: 9 | B13: nC4 | C13: n-Butane | D13: 58.123 | E13: 0.584 | F13: 490.7 | G13: 550.6 | H13: 765.3 | I13: =D13/E13 -> 99.525685
A14: 10 | B14: NeoC5 | C14: Neo-Pentane | D14: 72.151 | E14: 0.5967 | F14: 482.6 | G14: 464 | H14: 734.6 | I14: =D14/E14 -> 120.91671
A15: 11 | B15: iC5 | C15: i-Pentane | D15: 72.151 | E15: 0.6244 | F15: 541.7 | G15: 490.4 | H15: 828.7 | I15: =D15/E15 -> 115.55253
A16: 12 | B16: nC5 | C16: n-Pentane | D16: 72.151 | E16: 0.6311 | F16: 556.6 | G16: 488.6 | H16: 845.5 | I16: =D16/E16 -> 114.32578
... A56: 52 | B56: C36+ | C56: Hexatriacontanes plus | D56: 636.4 | E56: 0.94 | F56: 1490 | G56: 80 | H56: 1700 | I56: =D56/E56 -> 677.02128

Sheet Compositions_Master
A1: COMPOSITIONS MASTER — Reservoir | Stage 1-8 Gas (7-8 optional) | STO Residue
A2: Unified page. Enter Mol% AND Wt% in yellow. Stages 7-8 optional for extra samples.
A4: STAGE PRESSURES (linked from DV_Input) — up to 8 gas liberation stages
A5: Stream: | F5: Reservoir Fluid | H5: Stage 1 Gas | J5: Stage 2 Gas | L5: Stage 3 Gas | N5: Stage 4 Gas | P5: Stage 5 Gas | R5: Stage 6 Gas | T5: Stage 7 Gas (opt) | V5: Stage 8 Gas (opt) | X5: STO Residue
A6: Pressure (psia): | F6: =Sample_Info!B13 -> 1156 | H6: =DV_Input!B24 -> 0 | J6: =DV_Input!B25 -> 0 | L6: =DV_Input!B26 -> 0 | N6: =DV_Input!B27 -> 0 | P6: =DV_Input!B28 -> 0 | R6: =DV_Input!B29 -> 0 | T6: =DV_Input!B30 -> 0 | V6: =DV_Input!B31 -> 0 | X6: 14.73
A7: # | B7: Code | C7: Component | D7: MW (KF) | E7: Density (KF) | F7: Mol% | G7: Wt% | H7: Mol% | I7: Wt% | J7: Mol% | K7: Wt% | L7: Mol% | M7: Wt% | N7: Mol% | O7: Wt% | P7: Mol% | Q7: Wt% | R7: Mol% | S7: Wt% | T7: Mol% | U7: Wt% | V7: Mol% | W7: Wt% | X7: Mol% | Y7: Wt%
A8: 1 | B8: H2 | C8: Hydrogen | D8: =Component_Properties!D5 -> 2.016 | E8: =Component_Properties!E5 -> 0.0711 | F8: 0 | G8: 0 | H8: 0 | I8: 0 | J8: 0 | K8: 0 | L8: 0 | M8: 0 | N8: 0 | O8: 0 | P8: 0 | Q8: 0 | R8: 0 | S8: 0 | T8: 0 | U8: 0 | V8: 0 | W8: 0 | X8: 0 | Y8: 0
A9: 2 | B9: H2S | C9: Hydrogen Sulfide | D9: =Component_Properties!D6 -> 34.0809 | E9: =Component_Properties!E6 -> 0.8006 | F9: 0 | G9: 0 | H9: 0 | I9: 0 | J9: 0 | K9: 0 | L9: 0 | M9: 0 | N9: 0 | O9: 0 | P9: 0 | Q9: 0 | R9: 0 | S9: 0 | T9: 0 | U9: 0 | V9: 0 | W9: 0 | X9: 0 | Y9: 0
A10: 3 | B10: CO2 | C10: Carbon Dioxide | D10: =Component_Properties!D7 -> 44.0095 | E10: =Component_Properties!E7 -> 0.818 | F10: 0 | G10: 0 | H10: 4.06 | I10: 0 | J10: 4.23 | K10: 0 | L10: 4.48 | M10: 0 | N10: 4.68 | O10: 0 | P10: 4.17 | Q10: 0 | R10: 1.054 | S10: 0 | T10: 0 | U10: 0 | V10: 0 | W10: 0 | X10: 0 | Y10: 0
A11: 4 | B11: N2 | C11: Nitrogen | D11: =Component_Properties!D8 -> 28.0134 | E11: =Component_Properties!E8 -> 0.8094 | F11: 0 | G11: 0 | H11: 1.6 | I11: 0 | J11: 1.18 | K11: 0 | L11: 0.76 | M11: 0 | N11: 0.41 | O11: 0 | P11: 0.1 | Q11: 0 | R11: 0.006 | S11: 0 | T11: 0 | U11: 0 | V11: 0 | W11: 0 | X11: 0 | Y11: 0
A12: 5 | B12: C1 | C12: Methane | D12: =Component_Properties!D9 -> 16.043 | E12: =Component_Properties!E9 -> 0.3 | F12: 0 | G12: 0 | H12: 69.09 | I12: 0 | J12: 66.36 | K12: 0 | L12: 61.77 | M12: 0 | N12: 53.03 | O12: 0 | P12: 34.22 | Q12: 0 | R12: 5.496 | S12: 0 | T12: 0 | U12: 0 | V12: 0 | W12: 0 | X12: 0 | Y12: 0
A13: 6 | B13: C2 | C13: Ethane | D13: =Component_Properties!D10 -> 30.07 | E13: =Component_Properties!E10 -> 0.3562 | F13: 0 | G13: 0 | H13: 9.71 | I13: 0 | J13: 10.68 | K13: 0 | L13: 12.2 | M13: 0 | N13: 14.48 | O13: 0 | P13: 17.02 | Q13: 0 | R13: 7.388 | S13: 0 | T13: 0 | U13: 0 | V13: 0 | W13: 0 | X13: 0.01 | Y13: 0
A14: 7 | B14: C3 | C14: Propane | D14: =Component_Properties!D11 -> 44.097 | E14: =Component_Properties!E11 -> 0.507 | F14: 0 | G14: 0 | H14: 6.71 | I14: 0 | J14: 7.54 | K14: 0 | L14: 9.02 | M14: 0 | N14: 11.73 | O14: 0 | P14: 17.33 | Q14: 0 | R14: 14.762 | S14: 0 | T14: 0 | U14: 0 | V14: 0 | W14: 0 | X14: 0.07 | Y14: 0.02
A15: 8 | B15: iC4 | C15: i-Butane | D15: =Component_Properties!D12 -> 58.123 | E15: =Component_Properties!E12 -> 0.5629 | F15: 0 | G15: 0 | H15: 1.38 | I15: 0 | J15: 1.57 | K15: 0 | L15: 1.89 | M15: 0 | N15: 2.52 | O15: 0 | P15: 4.08 | Q15: 0 | R15: 5.454 | S15: 0 | T15: 0 | U15: 0 | V15: 0 | W15: 0 | X15: 0.1 | Y15: 0.03
A16: 9 | B16: nC4 | C16: n-Butane | D16: =Component_Properties!D13 -> 58.123 | E16: =Component_Properties!E13 -> 0.584 | F16: 0 | G16: 0 | H16: 2.82 | I16: 0 | J16: 3.19 | K16: 0 | L16: 3.85 | M16: 0 | N16: 5.18 | O16: 0 | P16: 8.7 | Q16: 0 | R16: 14.248 | S16: 0 | T16: 0 | U16: 0 | V16: 0 | W16: 0 | X16: 0.45 | Y16: 0.12
A17: 10 | B17: NeoC5 | C17: Neo-Pentane | D17: =Component_Properties!D14 -> 72.151 | E17: =Component_Properties!E14 -> 0.5967 | F17: 0 | G17: 0 | H17: 0.01 | I17: 0 | J17: 0.01 | K17: 0 | L17: 0.02 | M17: 0 | N17: 0.02 | O17: 0 | P17: 0.04 | Q17: 0 | R17: 0.066 | S17: 0 | T17: 0 | U17: 0 | V17: 0 | W17: 0 | X17: 0 | Y17: 0
A18: 11 | B18: iC5 | C18: i-Pentane | D18: =Component_Properties!D15 -> 72.151 | E18: =Component_Properties!E15 -> 0.6244 | F18: 0 | G18: 0 | H18: 0.98 | I18: 0 | J18: 1.12 | K18: 0 | L18: 1.31 | M18: 0 | N18: 1.81 | O18: 0 | P18: 3.3 | Q18: 0 | R18: 9.348 | S18: 0 | T18: 0 | U18: 0 | V18: 0 | W18: 0 | X18: 0.44 | Y18: 0.15
A19: 12 | B19: nC5 | C19: n-Pentane | D19: =Component_Properties!D16 -> 72.151 | E19: =Component_Properties!E16 -> 0.6311 | F19: 0 | G19: 0 | H19: 1.14 | I19: 0 | J19: 1.29 | K19: 0 | L19: 1.52 | M19: 0 | N19: 2.09 | O19: 0 | P19: 3.83 | Q19: 0 | R19: 12.136 | S19: 0 | T19: 0 | U19: 0 | V19: 0 | W19: 0 | X19: 0.82 | Y19: 0.27
... A59: 52 | B59: C36+ | C59: Hexatriacontanes plus | D59: =Component_Properties!D56 -> 636.4 | E59: =Component_Properties!E56 -> 0.94 | F59: 0 | G59: 0 | H59: 0 | I59: 0 | J59: 0 | K59: 0 | L59: 0 | M59: 0 | N59: 0 | O59: 0 | P59: 0 | Q59: 0 | R59: 0 | S59: 0 | T59: 0 | U59: 0 | V59: 0 | W59: 0 | X59: 5.94 | Y59: 17.42
B60: TOTAL | F60: =SUM(F8:F59) -> 0 | G60: =SUM(G8:G59) -> 0 | H60: =SUM(H8:H59) -> 100 | I60: =SUM(I8:I59) -> 0 | J60: =SUM(J8:J59) -> 100 | K60: =SUM(K8:K59) -> 0 | L60: =SUM(L8:L59) -> 100 | M60: =SUM(M8:M59) -> 0 | ... Y60: =SUM(Y8:Y59) -> 100
B61: Total QC | F61: =IF(F60=0,"empty",IF(ABS(F60-100)<=0.5,"PASS",IF(ABS(F60-100)<=2,"REVIEW","FAIL"))) -> empty | G61: =IF(G60=0,"empty",IF(ABS(G60-100)<=0.5,"PASS",IF(ABS(G60-100)<=2,"REVIEW","FAIL"))) -> empty | H61: =IF(H60=0,"empty",IF(ABS(H60-100)<=0.5,"PASS",IF(ABS(H60-100)<=2,"REVIEW","FAIL"))) -> PASS | I61: =IF(I60=0,"empty",IF(ABS(I60-100)<=0.5,"PASS",IF(ABS(I60-100)<=2,"REVIEW","FAIL"))) -> empty | J61: =IF(J60=0,"empty",IF(ABS(J60-100)<=0.5,"PASS",IF(ABS(J60-100)<=2,"REVIEW","FAIL"))) -> PASS | K61: =IF(K60=0,"empty",IF(ABS(K60-100)<=0.5,"PASS",IF(ABS(K60-100)<=2,"REVIEW","FAIL"))) -> empty | L61: =IF(L60=0,"empty",IF(ABS(L60-100)<=0.5,"PASS",IF(ABS(L60-100)<=2,"REVIEW","FAIL"))) -> PASS | M61: =IF(M60=0,"empty",IF(ABS(M60-100)<=0.5,"PASS",IF(ABS(M60-100)<=2,"REVIEW","FAIL"))) -> empty | ... Y61: =IF(Y60=0,"empty",IF(ABS(Y60-100)<=0.5,"PASS",IF(ABS(Y60-100)<=2,"REVIEW","FAIL"))) -> PASS
A63: STREAM PROPERTIES (Auto-calculated per stream)
C64: MW from Mol% (g/mol) | F64: =IF(SUM(F8:F59)=0,0,SUMPRODUCT($D$8:$D$59,F8:F59)/SUM(F8:F59)) -> 0 | H64: =IF(SUM(H8:H59)=0,0,SUMPRODUCT($D$8:$D$59,H8:H59)/SUM(H8:H59)) -> 25.626342 | J64: =IF(SUM(J8:J59)=0,0,SUMPRODUCT($D$8:$D$59,J8:J59)/SUM(J8:J59)) -> 26.690922 | L64: =IF(SUM(L8:L59)=0,0,SUMPRODUCT($D$8:$D$59,L8:L59)/SUM(L8:L59)) -> 28.247922 | N64: =IF(SUM(N8:N59)=0,0,SUMPRODUCT($D$8:$D$59,N8:N59)/SUM(N8:N59)) -> 31.40644 | P64: =IF(SUM(P8:P59)=0,0,SUMPRODUCT($D$8:$D$59,P8:P59)/SUM(P8:P59)) -> 39.561286 | R64: =IF(SUM(R8:R59)=0,0,SUMPRODUCT($D$8:$D$59,R8:R59)/SUM(R8:R59)) -> 66.840204 | T64: =IF(SUM(T8:T59)=0,0,SUMPRODUCT($D$8:$D$59,T8:T59)/SUM(T8:T59)) -> 0 | V64: =IF(SUM(V8:V59)=0,0,SUMPRODUCT($D$8:$D$59,V8:V59)/SUM(V8:V59)) -> 0 | X64: =IF(SUM(X8:X59)=0,0,SUMPRODUCT($D$8:$D$59,X8:X59)/SUM(X8:X59)) -> 219.62955
C65: MW from Wt% (g/mol) | F65: =IF(SUM(G8:G59)=0,0,100/SUMPRODUCT(G8:G59,1/$D$8:$D$59)) -> 0 | H65: =IF(SUM(I8:I59)=0,0,100/SUMPRODUCT(I8:I59,1/$D$8:$D$59)) -> 0 | J65: =IF(SUM(K8:K59)=0,0,100/SUMPRODUCT(K8:K59,1/$D$8:$D$59)) -> 0 | L65: =IF(SUM(M8:M59)=0,0,100/SUMPRODUCT(M8:M59,1/$D$8:$D$59)) -> 0 | N65: =IF(SUM(O8:O59)=0,0,100/SUMPRODUCT(O8:O59,1/$D$8:$D$59)) -> 0 | P65: =IF(SUM(Q8:Q59)=0,0,100/SUMPRODUCT(Q8:Q59,1/$D$8:$D$59)) -> 0 | R65: =IF(SUM(S8:S59)=0,0,100/SUMPRODUCT(S8:S59,1/$D$8:$D$59)) -> 0 | T65: =IF(SUM(U8:U59)=0,0,100/SUMPRODUCT(U8:U59,1/$D$8:$D$59)) -> 0 | V65: =IF(SUM(W8:W59)=0,0,100/SUMPRODUCT(W8:W59,1/$D$8:$D$59)) -> 0 | X65: =IF(SUM(Y8:Y59)=0,0,100/SUMPRODUCT(Y8:Y59,1/$D$8:$D$59)) -> 219.54243
C66: Density mixture (g/cc) | F66: =IF(SUMPRODUCT(G8:G59,1/$E$8:$E$59)=0,0,SUM(G8:G59)/SUMPRODUCT(G8:G59,1/$E$8:$E$59)) -> 0 | H66: =IF(SUMPRODUCT(I8:I59,1/$E$8:$E$59)=0,0,SUM(I8:I59)/SUMPRODUCT(I8:I59,1/$E$8:$E$59)) -> 0 | J66: =IF(SUMPRODUCT(K8:K59,1/$E$8:$E$59)=0,0,SUM(K8:K59)/SUMPRODUCT(K8:K59,1/$E$8:$E$59)) -> 0 | L66: =IF(SUMPRODUCT(M8:M59,1/$E$8:$E$59)=0,0,SUM(M8:M59)/SUMPRODUCT(M8:M59,1/$E$8:$E$59)) -> 0 | N66: =IF(SUMPRODUCT(O8:O59,1/$E$8:$E$59)=0,0,SUM(O8:O59)/SUMPRODUCT(O8:O59,1/$E$8:$E$59)) -> 0 | P66: =IF(SUMPRODUCT(Q8:Q59,1/$E$8:$E$59)=0,0,SUM(Q8:Q59)/SUMPRODUCT(Q8:Q59,1/$E$8:$E$59)) -> 0 | R66: =IF(SUMPRODUCT(S8:S59,1/$E$8:$E$59)=0,0,SUM(S8:S59)/SUMPRODUCT(S8:S59,1/$E$8:$E$59)) -> 0 | T66: =IF(SUMPRODUCT(U8:U59,1/$E$8:$E$59)=0,0,SUM(U8:U59)/SUMPRODUCT(U8:U59,1/$E$8:$E$59)) -> 0 | V66: =IF(SUMPRODUCT(W8:W59,1/$E$8:$E$59)=0,0,SUM(W8:W59)/SUMPRODUCT(W8:W59,1/$E$8:$E$59)) -> 0 | X66: =IF(SUMPRODUCT(Y8:Y59,1/$E$8:$E$59)=0,0,SUM(Y8:Y59)/SUMPRODUCT(Y8:Y59,1/$E$8:$E$59)) -> 0.84409943
C67: Gas Gravity (γ vs air) | F67: =IF(SUM(F8:F59)=0,0,SUMPRODUCT($D$8:$D$59,F8:F59)/SUM(F8:F59)/28.964) -> 0 | H67: =IF(SUM(H8:H59)=0,0,SUMPRODUCT($D$8:$D$59,H8:H59)/SUM(H8:H59)/28.964) -> 0.8847653 | J67: =IF(SUM(J8:J59)=0,0,SUMPRODUCT($D$8:$D$59,J8:J59)/SUM(J8:J59)/28.964) -> 0.92152059 | L67: =IF(SUM(L8:L59)=0,0,SUMPRODUCT($D$8:$D$59,L8:L59)/SUM(L8:L59)/28.964) -> 0.97527698 | N67: =IF(SUM(N8:N59)=0,0,SUMPRODUCT($D$8:$D$59,N8:N59)/SUM(N8:N59)/28.964) -> 1.0843268 | P67: =IF(SUM(P8:P59)=0,0,SUMPRODUCT($D$8:$D$59,P8:P59)/SUM(P8:P59)/28.964) -> 1.3658778 | R67: =IF(SUM(R8:R59)=0,0,SUMPRODUCT($D$8:$D$59,R8:R59)/SUM(R8:R59)/28.964) -> 2.3076994 | T67: =IF(SUM(T8:T59)=0,0,SUMPRODUCT($D$8:$D$59,T8:T59)/SUM(T8:T59)/28.964) -> 0 | V67: =IF(SUM(V8:V59)=0,0,SUMPRODUCT($D$8:$D$59,V8:V59)/SUM(V8:V59)/28.964) -> 0 | X67: N/A (liquid)
C68: MW consistency % | F68: =IF(F64=0,0,ABS(F64-F65)/F64*100) -> 0 | H68: =IF(H64=0,0,ABS(H64-H65)/H64*100) -> 100 | J68: =IF(J64=0,0,ABS(J64-J65)/J64*100) -> 100 | L68: =IF(L64=0,0,ABS(L64-L65)/L64*100) -> 100 | N68: =IF(N64=0,0,ABS(N64-N65)/N64*100) -> 100 | P68: =IF(P64=0,0,ABS(P64-P65)/P64*100) -> 100 | R68: =IF(R64=0,0,ABS(R64-R65)/R64*100) -> 100 | T68: =IF(T64=0,0,ABS(T64-T65)/T64*100) -> 0 | V68: =IF(V64=0,0,ABS(V64-V65)/V64*100) -> 0 | X68: =IF(X64=0,0,ABS(X64-X65)/X64*100) -> 0.039669533

Sheet DV_Calc
A1: DIFFERENTIAL VAPORIZATION CALCULATIONS (per-stage Bo, Rs, Bt, Z, ρ_calc + Material Balance)
A2: All live formulas. Row 15 = Bubble Point Psat. Rows 16-40 = depletion stages. V_oil = after gas removal.
A4: BLOCK A — TEST REFERENCE (linked from Sample_Info & DV_Input)
A5: Bubble Point Psat (psig) | B5: =Sample_Info!B13 -> 1156 | D5: Density @ Psat (g/cc) | E5: =Sample_Info!E13 -> 0.6856
A6: Reservoir Temp (°F) | B6: =Sample_Info!E12 -> 256 | D6: STO Density @ 60°F (g/cc) | E6: =Sample_Info!B16 -> 0.8479
A7: Flash Rs_fb (scf/STB) | B7: =Sample_Info!B14 -> 521 | D7: Flash Bo_fb (rb/STB) | E7: =Sample_Info!E14 -> 1.331
A8: V_sto @ 60°F (cc) | B8: =DV_Input!B8 -> 476 | D8: STO MW (g/mol) | E8: =Sample_Info!E16 -> 195
A10: BLOCK B — STAGE-BY-STAGE DV CALCULATIONS
A14: # | B14: P (psia) | C14: T (°F) | D14: V_oil (cc) [after gas removal] | E14: Bo_d | F14: V_gas cc | G14: V_gas scf | H14: Cum gas scf | I14: ΔRs (scf/STB) | J14: Rs_d total | K14: Gas MW | L14: γg | M14: Z | N14: Bg (rcf/scf) | O14: Bt_d | P14: Rs surface | Q14: Bo surface | R14: ρ_oil calc (MB)
A15: =DV_Input!A23 -> 1 | B15: =DV_Input!B23 -> 1156 | C15: =DV_Input!C23 -> 256 | D15: =DV_Input!E23 -> 633.5 | E15: =IF($B$8=0,0,D15/$B$8) -> 1.3308824 | F15: =DV_Input!K23 -> 0 | G15: =DV_Input!L23 -> 0 | H15: =G15 -> 0 | I15: =IF($B$8=0,0,G15*158987.29/$B$8) -> 0 | J15: =$B$7-SUM($I15:I$16) -> 521 | K15: 0 | L15: =IF(DV_Input!M23>0,DV_Input!M23,IF(K15=0,0,K15/28.964)) -> 0 | M15: =IF(DV_Input!N23>0,DV_Input!N23,1) -> 1 | N15: =IF(B15=0,0,14.73*(C15+459.67)*M15/(519.67*B15)) -> 0.017548099 | O15: =E15+H15*28316.85*N15/$B$8 -> 1.3308824 | P15: =IF($E$15=0,0,$B$7-($B$7-J15)*$E$7/$E$15) -> 521 | Q15: =IF($E$15=0,0,E15*$E$7/$E$15) -> 1.331 | R15: =$E$5 -> 0.6856
A16: =DV_Input!A24 -> 2 | B16: =DV_Input!B24 -> 0 | C16: =DV_Input!C24 -> 256 | D16: =DV_Input!E24 -> 0 | E16: =IF($B$8=0,0,D16/$B$8) -> 0 | F16: =DV_Input!K24 -> 0 | G16: =DV_Input!L24 -> 0 | H16: =H15+G16 -> 0 | I16: =IF($B$8=0,0,G16*158987.29/$B$8) -> 0 | J16: =$B$7-SUM($I$16:I16) -> 521 | K16: =Compositions_Master!H64 -> 25.626342 | L16: =IF(DV_Input!M24>0,DV_Input!M24,IF(K16=0,0,K16/28.964)) -> 0.8847653 | M16: =IF(DV_Input!N24>0,DV_Input!N24,1) -> 1 | N16: =IF(B16=0,0,14.73*(C16+459.67)*M16/(519.67*B16)) -> 0 | O16: =E16+H16*28316.85*N16/$B$8 -> 0 | P16: =IF($E$15=0,0,$B$7-($B$7-J16)*$E$7/$E$15) -> 521 | Q16: =IF($E$15=0,0,E16*$E$7/$E$15) -> 0 | R16: =IF(D16=0,0,($E$5*$D$15-SUMPRODUCT($F$16:F16,$L$16:L16)*0.0012255)/D16) -> 0
A17: =DV_Input!A25 -> 3 | B17: =DV_Input!B25 -> 0 | C17: =DV_Input!C25 -> 256 | D17: =DV_Input!E25 -> 0 | E17: =IF($B$8=0,0,D17/$B$8) -> 0 | F17: =DV_Input!K25 -> 0 | G17: =DV_Input!L25 -> 0 | H17: =H16+G17 -> 0 | I17: =IF($B$8=0,0,G17*158987.29/$B$8) -> 0 | J17: =$B$7-SUM($I$16:I17) -> 521 | K17: =Compositions_Master!J64 -> 26.690922 | L17: =IF(DV_Input!M25>0,DV_Input!M25,IF(K17=0,0,K17/28.964)) -> 0.92152059 | M17: =IF(DV_Input!N25>0,DV_Input!N25,1) -> 1 | N17: =IF(B17=0,0,14.73*(C17+459.67)*M17/(519.67*B17)) -> 0 | O17: =E17+H17*28316.85*N17/$B$8 -> 0 | P17: =IF($E$15=0,0,$B$7-($B$7-J17)*$E$7/$E$15) -> 521 | Q17: =IF($E$15=0,0,E17*$E$7/$E$15) -> 0 | R17: =IF(D17=0,0,($E$5*$D$15-SUMPRODUCT($F$16:F17,$L$16:L17)*0.0012255)/D17) -> 0
A18: =DV_Input!A26 -> 4 | B18: =DV_Input!B26 -> 0 | C18: =DV_Input!C26 -> 256 | D18: =DV_Input!E26 -> 0 | E18: =IF($B$8=0,0,D18/$B$8) -> 0 | F18: =DV_Input!K26 -> 0 | G18: =DV_Input!L26 -> 0 | H18: =H17+G18 -> 0 | I18: =IF($B$8=0,0,G18*158987.29/$B$8) -> 0 | J18: =$B$7-SUM($I$16:I18) -> 521 | K18: =Compositions_Master!L64 -> 28.247922 | L18: =IF(DV_Input!M26>0,DV_Input!M26,IF(K18=0,0,K18/28.964)) -> 0.97527698 | M18: =IF(DV_Input!N26>0,DV_Input!N26,1) -> 1 | N18: =IF(B18=0,0,14.73*(C18+459.67)*M18/(519.67*B18)) -> 0 | O18: =E18+H18*28316.85*N18/$B$8 -> 0 | P18: =IF($E$15=0,0,$B$7-($B$7-J18)*$E$7/$E$15) -> 521 | Q18: =IF($E$15=0,0,E18*$E$7/$E$15) -> 0 | R18: =IF(D18=0,0,($E$5*$D$15-SUMPRODUCT($F$16:F18,$L$16:L18)*0.0012255)/D18) -> 0
A19: =DV_Input!A27 -> 5 | B19: =DV_Input!B27 -> 0 | C19: =DV_Input!C27 -> 256 | D19: =DV_Input!E27 -> 0 | E19: =IF($B$8=0,0,D19/$B$8) -> 0 | F19: =DV_Input!K27 -> 0 | G19: =DV_Input!L27 -> 0 | H19: =H18+G19 -> 0 | I19: =IF($B$8=0,0,G19*158987.29/$B$8) -> 0 | J19: =$B$7-SUM($I$16:I19) -> 521 | K19: =Compositions_Master!N64 -> 31.40644 | L19: =IF(DV_Input!M27>0,DV_Input!M27,IF(K19=0,0,K19/28.964)) -> 1.0843268 | M19: =IF(DV_Input!N27>0,DV_Input!N27,1) -> 1 | N19: =IF(B19=0,0,14.73*(C19+459.67)*M19/(519.67*B19)) -> 0 | O19: =E19+H19*28316.85*N19/$B$8 -> 0 | P19: =IF($E$15=0,0,$B$7-($B$7-J19)*$E$7/$E$15) -> 521 | Q19: =IF($E$15=0,0,E19*$E$7/$E$15) -> 0 | R19: =IF(D19=0,0,($E$5*$D$15-SUMPRODUCT($F$16:F19,$L$16:L19)*0.0012255)/D19) -> 0
A20: =DV_Input!A28 -> 6 | B20: =DV_Input!B28 -> 0 | C20: =DV_Input!C28 -> 256 | D20: =DV_Input!E28 -> 0 | E20: =IF($B$8=0,0,D20/$B$8) -> 0 | F20: =DV_Input!K28 -> 0 | G20: =DV_Input!L28 -> 0 | H20: =H19+G20 -> 0 | I20: =IF($B$8=0,0,G20*158987.29/$B$8) -> 0 | J20: =$B$7-SUM($I$16:I20) -> 521 | K20: =Compositions_Master!P64 -> 39.561286 | L20: =IF(DV_Input!M28>0,DV_Input!M28,IF(K20=0,0,K20/28.964)) -> 1.3658778 | M20: =IF(DV_Input!N28>0,DV_Input!N28,1) -> 1 | N20: =IF(B20=0,0,14.73*(C20+459.67)*M20/(519.67*B20)) -> 0 | O20: =E20+H20*28316.85*N20/$B$8 -> 0 | P20: =IF($E$15=0,0,$B$7-($B$7-J20)*$E$7/$E$15) -> 521 | Q20: =IF($E$15=0,0,E20*$E$7/$E$15) -> 0 | R20: =IF(D20=0,0,($E$5*$D$15-SUMPRODUCT($F$16:F20,$L$16:L20)*0.0012255)/D20) -> 0
A21: =DV_Input!A29 -> 7 | B21: =DV_Input!B29 -> 0 | C21: =DV_Input!C29 -> 256 | D21: =DV_Input!E29 -> 0 | E21: =IF($B$8=0,0,D21/$B$8) -> 0 | F21: =DV_Input!K29 -> 0 | G21: =DV_Input!L29 -> 0 | H21: =H20+G21 -> 0 | I21: =IF($B$8=0,0,G21*158987.29/$B$8) -> 0 | J21: =$B$7-SUM($I$16:I21) -> 521 | K21: =Compositions_Master!R64 -> 66.840204 | L21: =IF(DV_Input!M29>0,DV_Input!M29,IF(K21=0,0,K21/28.964)) -> 2.3076994 | M21: =IF(DV_Input!N29>0,DV_Input!N29,1) -> 1 | N21: =IF(B21=0,0,14.73*(C21+459.67)*M21/(519.67*B21)) -> 0 | O21: =E21+H21*28316.85*N21/$B$8 -> 0 | P21: =IF($E$15=0,0,$B$7-($B$7-J21)*$E$7/$E$15) -> 521 | Q21: =IF($E$15=0,0,E21*$E$7/$E$15) -> 0 | R21: =IF(D21=0,0,($E$5*$D$15-SUMPRODUCT($F$16:F21,$L$16:L21)*0.0012255)/D21) -> 0
A22: =DV_Input!A30 -> 8 | B22: =DV_Input!B30 -> 0 | C22: =DV_Input!C30 -> 256 | D22: =DV_Input!E30 -> 0 | E22: =IF($B$8=0,0,D22/$B$8) -> 0 | F22: =DV_Input!K30 -> 0 | G22: =DV_Input!L30 -> 0 | H22: =H21+G22 -> 0 | I22: =IF($B$8=0,0,G22*158987.29/$B$8) -> 0 | J22: =$B$7-SUM($I$16:I22) -> 521 | K22: =Compositions_Master!T64 -> 0 | L22: =IF(DV_Input!M30>0,DV_Input!M30,IF(K22=0,0,K22/28.964)) -> 0 | M22: =IF(DV_Input!N30>0,DV_Input!N30,1) -> 1 | N22: =IF(B22=0,0,14.73*(C22+459.67)*M22/(519.67*B22)) -> 0 | O22: =E22+H22*28316.85*N22/$B$8 -> 0 | P22: =IF($E$15=0,0,$B$7-($B$7-J22)*$E$7/$E$15) -> 521 | Q22: =IF($E$15=0,0,E22*$E$7/$E$15) -> 0 | R22: =IF(D22=0,0,($E$5*$D$15-SUMPRODUCT($F$16:F22,$L$16:L22)*0.0012255)/D22) -> 0
A23: =DV_Input!A31 -> 9 | B23: =DV_Input!B31 -> 0 | C23: =DV_Input!C31 -> 256 | D23: =DV_Input!E31 -> 0 | E23: =IF($B$8=0,0,D23/$B$8) -> 0 | F23: =DV_Input!K31 -> 0 | G23: =DV_Input!L31 -> 0 | H23: =H22+G23 -> 0 | I23: =IF($B$8=0,0,G23*158987.29/$B$8) -> 0 | J23: =$B$7-SUM($I$16:I23) -> 521 | K23: =Compositions_Master!V64 -> 0 | L23: =IF(DV_Input!M31>0,DV_Input!M31,IF(K23=0,0,K23/28.964)) -> 0 | M23: =IF(DV_Input!N31>0,DV_Input!N31,1) -> 1 | N23: =IF(B23=0,0,14.73*(C23+459.67)*M23/(519.67*B23)) -> 0 | O23: =E23+H23*28316.85*N23/$B$8 -> 0 | P23: =IF($E$15=0,0,$B$7-($B$7-J23)*$E$7/$E$15) -> 521 | Q23: =IF($E$15=0,0,E23*$E$7/$E$15) -> 0 | R23: =IF(D23=0,0,($E$5*$D$15-SUMPRODUCT($F$16:F23,$L$16:L23)*0.0012255)/D23) -> 0
A24: =DV_Input!A32 -> 10 | B24: =DV_Input!B32 -> 0 | C24: =DV_Input!C32 -> 256 | D24: =DV_Input!E32 -> 0 | E24: =IF($B$8=0,0,D24/$B$8) -> 0 | F24: =DV_Input!K32 -> 0 | G24: =DV_Input!L32 -> 0 | H24: =H23+G24 -> 0 | I24: =IF($B$8=0,0,G24*158987.29/$B$8) -> 0 | J24: =$B$7-SUM($I$16:I24) -> 521 | K24: 0 | L24: =IF(DV_Input!M32>0,DV_Input!M32,IF(K24=0,0,K24/28.964)) -> 0 | M24: =IF(DV_Input!N32>0,DV_Input!N32,1) -> 1 | N24: =IF(B24=0,0,14.73*(C24+459.67)*M24/(519.67*B24)) -> 0 | O24: =E24+H24*28316.85*N24/$B$8 -> 0 | P24: =IF($E$15=0,0,$B$7-($B$7-J24)*$E$7/$E$15) -> 521 | Q24: =IF($E$15=0,0,E24*$E$7/$E$15) -> 0 | R24: =IF(D24=0,0,($E$5*$D$15-SUMPRODUCT($F$16:F24,$L$16:L24)*0.0012255)/D24) -> 0
A25: =DV_Input!A33 -> 11 | B25: =DV_Input!B33 -> 0 | C25: =DV_Input!C33 -> 256 | D25: =DV_Input!E33 -> 0 | E25: =IF($B$8=0,0,D25/$B$8) -> 0 | F25: =DV_Input!K33 -> 0 | G25: =DV_Input!L33 -> 0 | H25: =H24+G25 -> 0 | I25: =IF($B$8=0,0,G25*158987.29/$B$8) -> 0 | J25: =$B$7-SUM($I$16:I25) -> 521 | K25: 0 | L25: =IF(DV_Input!M33>0,DV_Input!M33,IF(K25=0,0,K25/28.964)) -> 0 | M25: =IF(DV_Input!N33>0,DV_Input!N33,1) -> 1 | N25: =IF(B25=0,0,14.73*(C25+459.67)*M25/(519.67*B25)) -> 0 | O25: =E25+H25*28316.85*N25/$B$8 -> 0 | P25: =IF($E$15=0,0,$B$7-($B$7-J25)*$E$7/$E$15) -> 521 | Q25: =IF($E$15=0,0,E25*$E$7/$E$15) -> 0 | R25: =IF(D25=0,0,($E$5*$D$15-SUMPRODUCT($F$16:F25,$L$16:L25)*0.0012255)/D25) -> 0
A26: =DV_Input!A34 -> 12 | B26: =DV_Input!B34 -> 0 | C26: =DV_Input!C34 -> 256 | D26: =DV_Input!E34 -> 0 | E26: =IF($B$8=0,0,D26/$B$8) -> 0 | F26: =DV_Input!K34 -> 0 | G26: =DV_Input!L34 -> 0 | H26: =H25+G26 -> 0 | I26: =IF($B$8=0,0,G26*158987.29/$B$8) -> 0 | J26: =$B$7-SUM($I$16:I26) -> 521 | K26: 0 | L26: =IF(DV_Input!M34>0,DV_Input!M34,IF(K26=0,0,K26/28.964)) -> 0 | M26: =IF(DV_Input!N34>0,DV_Input!N34,1) -> 1 | N26: =IF(B26=0,0,14.73*(C26+459.67)*M26/(519.67*B26)) -> 0 | O26: =E26+H26*28316.85*N26/$B$8 -> 0 | P26: =IF($E$15=0,0,$B$7-($B$7-J26)*$E$7/$E$15) -> 521 | Q26: =IF($E$15=0,0,E26*$E$7/$E$15) -> 0 | R26: =IF(D26=0,0,($E$5*$D$15-SUMPRODUCT($F$16:F26,$L$16:L26)*0.0012255)/D26) -> 0
A27: =DV_Input!A35 -> 13 | B27: =DV_Input!B35 -> 0 | C27: =DV_Input!C35 -> 256 | D27: =DV_Input!E35 -> 0 | E27: =IF($B$8=0,0,D27/$B$8) -> 0 | F27: =DV_Input!K35 -> 0 | G27: =DV_Input!L35 -> 0 | H27: =H26+G27 -> 0 | I27: =IF($B$8=0,0,G27*158987.29/$B$8) -> 0 | J27: =$B$7-SUM($I$16:I27) -> 521 | K27: 0 | L27: =IF(DV_Input!M35>0,DV_Input!M35,IF(K27=0,0,K27/28.964)) -> 0 | M27: =IF(DV_Input!N35>0,DV_Input!N35,1) -> 1 | N27: =IF(B27=0,0,14.73*(C27+459.67)*M27/(519.67*B27)) -> 0 | O27: =E27+H27*28316.85*N27/$B$8 -> 0 | P27: =IF($E$15=0,0,$B$7-($B$7-J27)*$E$7/$E$15) -> 521 | Q27: =IF($E$15=0,0,E27*$E$7/$E$15) -> 0 | R27: =IF(D27=0,0,($E$5*$D$15-SUMPRODUCT($F$16:F27,$L$16:L27)*0.0012255)/D27) -> 0
A28: =DV_Input!A36 -> 14 | B28: =DV_Input!B36 -> 0 | C28: =DV_Input!C36 -> 256 | D28: =DV_Input!E36 -> 0 | E28: =IF($B$8=0,0,D28/$B$8) -> 0 | F28: =DV_Input!K36 -> 0 | G28: =DV_Input!L36 -> 0 | H28: =H27+G28 -> 0 | I28: =IF($B$8=0,0,G28*158987.29/$B$8) -> 0 | J28: =$B$7-SUM($I$16:I28) -> 521 | K28: 0 | L28: =IF(DV_Input!M36>0,DV_Input!M36,IF(K28=0,0,K28/28.964)) -> 0 | M28: =IF(DV_Input!N36>0,DV_Input!N36,1) -> 1 | N28: =IF(B28=0,0,14.73*(C28+459.67)*M28/(519.67*B28)) -> 0 | O28: =E28+H28*28316.85*N28/$B$8 -> 0 | P28: =IF($E$15=0,0,$B$7-($B$7-J28)*$E$7/$E$15) -> 521 | Q28: =IF($E$15=0,0,E28*$E$7/$E$15) -> 0 | R28: =IF(D28=0,0,($E$5*$D$15-SUMPRODUCT($F$16:F28,$L$16:L28)*0.0012255)/D28) -> 0
A29: =DV_Input!A37 -> 15 | B29: =DV_Input!B37 -> 0 | C29: =DV_Input!C37 -> 256 | D29: =DV_Input!E37 -> 0 | E29: =IF($B$8=0,0,D29/$B$8) -> 0 | F29: =DV_Input!K37 -> 0 | G29: =DV_Input!L37 -> 0 | H29: =H28+G29 -> 0 | I29: =IF($B$8=0,0,G29*158987.29/$B$8) -> 0 | J29: =$B$7-SUM($I$16:I29) -> 521 | K29: 0 | L29: =IF(DV_Input!M37>0,DV_Input!M37,IF(K29=0,0,K29/28.964)) -> 0 | M29: =IF(DV_Input!N37>0,DV_Input!N37,1) -> 1 | N29: =IF(B29=0,0,14.73*(C29+459.67)*M29/(519.67*B29)) -> 0 | O29: =E29+H29*28316.85*N29/$B$8 -> 0 | P29: =IF($E$15=0,0,$B$7-($B$7-J29)*$E$7/$E$15) -> 521 | Q29: =IF($E$15=0,0,E29*$E$7/$E$15) -> 0 | R29: =IF(D29=0,0,($E$5*$D$15-SUMPRODUCT($F$16:F29,$L$16:L29)*0.0012255)/D29) -> 0
A30: =DV_Input!A38 -> 16 | B30: =DV_Input!B38 -> 0 | C30: =DV_Input!C38 -> 256 | D30: =DV_Input!E38 -> 0 | E30: =IF($B$8=0,0,D30/$B$8) -> 0 | F30: =DV_Input!K38 -> 0 | G30: =DV_Input!L38 -> 0 | H30: =H29+G30 -> 0 | I30: =IF($B$8=0,0,G30*158987.29/$B$8) -> 0 | J30: =$B$7-SUM($I$16:I30) -> 521 | K30: 0 | L30: =IF(DV_Input!M38>0,DV_Input!M38,IF(K30=0,0,K30/28.964)) -> 0 | M30: =IF(DV_Input!N38>0,DV_Input!N38,1) -> 1 | N30: =IF(B30=0,0,14.73*(C30+459.67)*M30/(519.67*B30)) -> 0 | O30: =E30+H30*28316.85*N30/$B$8 -> 0 | P30: =IF($E$15=0,0,$B$7-($B$7-J30)*$E$7/$E$15) -> 521 | Q30: =IF($E$15=0,0,E30*$E$7/$E$15) -> 0 | R30: =IF(D30=0,0,($E$5*$D$15-SUMPRODUCT($F$16:F30,$L$16:L30)*0.0012255)/D30) -> 0
A31: =DV_Input!A39 -> 17 | B31: =DV_Input!B39 -> 0 | C31: =DV_Input!C39 -> 256 | D31: =DV_Input!E39 -> 0 | E31: =IF($B$8=0,0,D31/$B$8) -> 0 | F31: =DV_Input!K39 -> 0 | G31: =DV_Input!L39 -> 0 | H31: =H30+G31 -> 0 | I31: =IF($B$8=0,0,G31*158987.29/$B$8) -> 0 | J31: =$B$7-SUM($I$16:I31) -> 521 | K31: 0 | L31: =IF(DV_Input!M39>0,DV_Input!M39,IF(K31=0,0,K31/28.964)) -> 0 | M31: =IF(DV_Input!N39>0,DV_Input!N39,1) -> 1 | N31: =IF(B31=0,0,14.73*(C31+459.67)*M31/(519.67*B31)) -> 0 | O31: =E31+H31*28316.85*N31/$B$8 -> 0 | P31: =IF($E$15=0,0,$B$7-($B$7-J31)*$E$7/$E$15) -> 521 | Q31: =IF($E$15=0,0,E31*$E$7/$E$15) -> 0 | R31: =IF(D31=0,0,($E$5*$D$15-SUMPRODUCT($F$16:F31,$L$16:L31)*0.0012255)/D31) -> 0
A32: =DV_Input!A40 -> 18 | B32: =DV_Input!B40 -> 0 | C32: =DV_Input!C40 -> 256 | D32: =DV_Input!E40 -> 0 | E32: =IF($B$8=0,0,D32/$B$8) -> 0 | F32: =DV_Input!K40 -> 0 | G32: =DV_Input!L40 -> 0 | H32: =H31+G32 -> 0 | I32: =IF($B$8=0,0,G32*158987.29/$B$8) -> 0 | J32: =$B$7-SUM($I$16:I32) -> 521 | K32: 0 | L32: =IF(DV_Input!M40>0,DV_Input!M40,IF(K32=0,0,K32/28.964)) -> 0 | M32: =IF(DV_Input!N40>0,DV_Input!N40,1) -> 1 | N32: =IF(B32=0,0,14.73*(C32+459.67)*M32/(519.67*B32)) -> 0 | O32: =E32+H32*28316.85*N32/$B$8 -> 0 | P32: =IF($E$15=0,0,$B$7-($B$7-J32)*$E$7/$E$15) -> 521 | Q32: =IF($E$15=0,0,E32*$E$7/$E$15) -> 0 | R32: =IF(D32=0,0,($E$5*$D$15-SUMPRODUCT($F$16:F32,$L$16:L32)*0.0012255)/D32) -> 0
A33: =DV_Input!A41 -> 19 | B33: =DV_Input!B41 -> 0 | C33: =DV_Input!C41 -> 256 | D33: =DV_Input!E41 -> 0 | E33: =IF($B$8=0,0,D33/$B$8) -> 0 | F33: =DV_Input!K41 -> 0 | G33: =DV_Input!L41 -> 0 | H33: =H32+G33 -> 0 | I33: =IF($B$8=0,0,G33*158987.29/$B$8) -> 0 | J33: =$B$7-SUM($I$16:I33) -> 521 | K33: 0 | L33: =IF(DV_Input!M41>0,DV_Input!M41,IF(K33=0,0,K33/28.964)) -> 0 | M33: =IF(DV_Input!N41>0,DV_Input!N41,1) -> 1 | N33: =IF(B33=0,0,14.73*(C33+459.67)*M33/(519.67*B33)) -> 0 | O33: =E33+H33*28316.85*N33/$B$8 -> 0 | P33: =IF($E$15=0,0,$B$7-($B$7-J33)*$E$7/$E$15) -> 521 | Q33: =IF($E$15=0,0,E33*$E$7/$E$15) -> 0 | R33: =IF(D33=0,0,($E$5*$D$15-SUMPRODUCT($F$16:F33,$L$16:L33)*0.0012255)/D33) -> 0
A34: =DV_Input!A42 -> 20 | B34: =DV_Input!B42 -> 0 | C34: =DV_Input!C42 -> 256 | D34: =DV_Input!E42 -> 0 | E34: =IF($B$8=0,0,D34/$B$8) -> 0 | F34: =DV_Input!K42 -> 0 | G34: =DV_Input!L42 -> 0 | H34: =H33+G34 -> 0 | I34: =IF($B$8=0,0,G34*158987.29/$B$8) -> 0 | J34: =$B$7-SUM($I$16:I34) -> 521 | K34: 0 | L34: =IF(DV_Input!M42>0,DV_Input!M42,IF(K34=0,0,K34/28.964)) -> 0 | M34: =IF(DV_Input!N42>0,DV_Input!N42,1) -> 1 | N34: =IF(B34=0,0,14.73*(C34+459.67)*M34/(519.67*B34)) -> 0 | O34: =E34+H34*28316.85*N34/$B$8 -> 0 | P34: =IF($E$15=0,0,$B$7-($B$7-J34)*$E$7/$E$15) -> 521 | Q34: =IF($E$15=0,0,E34*$E$7/$E$15) -> 0 | R34: =IF(D34=0,0,($E$5*$D$15-SUMPRODUCT($F$16:F34,$L$16:L34)*0.0012255)/D34) -> 0
A35: =DV_Input!A43 -> 21 | B35: =DV_Input!B43 -> 0 | C35: =DV_Input!C43 -> 256 | D35: =DV_Input!E43 -> 0 | E35: =IF($B$8=0,0,D35/$B$8) -> 0 | F35: =DV_Input!K43 -> 0 | G35: =DV_Input!L43 -> 0 | H35: =H34+G35 -> 0 | I35: =IF($B$8=0,0,G35*158987.29/$B$8) -> 0 | J35: =$B$7-SUM($I$16:I35) -> 521 | K35: 0 | L35: =IF(DV_Input!M43>0,DV_Input!M43,IF(K35=0,0,K35/28.964)) -> 0 | M35: =IF(DV_Input!N43>0,DV_Input!N43,1) -> 1 | N35: =IF(B35=0,0,14.73*(C35+459.67)*M35/(519.67*B35)) -> 0 | O35: =E35+H35*28316.85*N35/$B$8 -> 0 | P35: =IF($E$15=0,0,$B$7-($B$7-J35)*$E$7/$E$15) -> 521 | Q35: =IF($E$15=0,0,E35*$E$7/$E$15) -> 0 | R35: =IF(D35=0,0,($E$5*$D$15-SUMPRODUCT($F$16:F35,$L$16:L35)*0.0012255)/D35) -> 0
... A40: =DV_Input!A48 -> 26 | B40: =DV_Input!B48 -> 0 | C40: =DV_Input!C48 -> 256 | D40: =DV_Input!E48 -> 0 | E40: =IF($B$8=0,0,D40/$B$8) -> 0 | F40: =DV_Input!K48 -> 0 | G40: =DV_Input!L48 -> 0 | H40: =H39+G40 -> 0 | I40: =IF($B$8=0,0,G40*158987.29/$B$8) -> 0 | J40: =$B$7-SUM($I$16:I40) -> 521 | K40: 0 | L40: =IF(DV_Input!M48>0,DV_Input!M48,IF(K40=0,0,K40/28.964)) -> 0 | M40: =IF(DV_Input!N48>0,DV_Input!N48,1) -> 1 | N40: =IF(B40=0,0,14.73*(C40+459.67)*M40/(519.67*B40)) -> 0 | O40: =E40+H40*28316.85*N40/$B$8 -> 0 | P40: =IF($E$15=0,0,$B$7-($B$7-J40)*$E$7/$E$15) -> 521 | Q40: =IF($E$15=0,0,E40*$E$7/$E$15) -> 0 | R40: =IF(D40=0,0,($E$5*$D$15-SUMPRODUCT($F$16:F40,$L$16:L40)*0.0012255)/D40) -> 0
A42: BLOCK C — MASS BALANCE SUMMARY
A43: Mass at Psat (g) | B43: =$E$5*$D$15 -> 434.3276
A44: Cum gas mass removed (g) | B44: =SUMPRODUCT(F16:F40,L16:L40)*0.0012255 -> 0
A45: Mass balance closure (final STO mass, g) | B45: =B43-B44 -> 434.3276
A46: Expected STO mass @ 60°F (g) = ρ_STO × V_sto | B46: =$E$6*$B$8 -> 403.6004
A47: 🟣 Mass balance error (%) | B47: =IF(B46=0,0,ABS(B45-B46)/B46*100) -> 7.6132729
A48: 🟣 Mass balance QC status | B48: =IF(B47<=2,"PASS ≤2%",IF(B47<=3,"REVIEW ≤3%","FAIL >3%")) -> FAIL >3%
A50: MATERIAL BALANCE GUIDANCE — What to adjust if MB fails
A51: If Mass Balance error > 3%, try adjusting these inputs (in order of sensitivity):
...

Sheet Material_Balance_QC
A1: MATERIAL BALANCE QC — MOLAR BALANCE + K-VALUE + HOFFMAN PLOTS
A2: Component-by-component balance. K = y/x. Hoffman plot for equilibrium check.
A4: BLOCK A — REFERENCE CONSTANTS (linked)
A5: V_sto (cc) | B5: =DV_Calc!B8 -> 476
A6: STO Density (g/cc) | B6: =DV_Calc!E6 -> 0.8479
A7: STO MW (g/mol) | B7: =DV_Calc!E8 -> 195
A8: Residual oil mass (g) | B8: =B5*B6 -> 403.6004
A9: Residual oil moles (lbmol) | B9: =B8/(B7*453.59) -> 0.0045630319
A10: scf per lbmol @ std | B10: 379.482
A12: BLOCK B — STAGE GAS MOLES (up to 8 stages)
A13: Stage | B13: P (psia) | C13: V_gas_std (scf) | D13: Gas MW | E13: Gas moles (lbmol)
A14: 1 | B14: =DV_Calc!B16 -> 0 | C14: =DV_Calc!G16 -> 0 | D14: =DV_Calc!K16 -> 25.626342 | E14: =C14/$B$10 -> 0
A15: 2 | B15: =DV_Calc!B17 -> 0 | C15: =DV_Calc!G17 -> 0 | D15: =DV_Calc!K17 -> 26.690922 | E15: =C15/$B$10 -> 0
A16: 3 | B16: =DV_Calc!B18 -> 0 | C16: =DV_Calc!G18 -> 0 | D16: =DV_Calc!K18 -> 28.247922 | E16: =C16/$B$10 -> 0
A17: 4 | B17: =DV_Calc!B19 -> 0 | C17: =DV_Calc!G19 -> 0 | D17: =DV_Calc!K19 -> 31.40644 | E17: =C17/$B$10 -> 0
A18: 5 | B18: =DV_Calc!B20 -> 0 | C18: =DV_Calc!G20 -> 0 | D18: =DV_Calc!K20 -> 39.561286 | E18: =C18/$B$10 -> 0
A19: 6 | B19: =DV_Calc!B21 -> 0 | C19: =DV_Calc!G21 -> 0 | D19: =DV_Calc!K21 -> 66.840204 | E19: =C19/$B$10 -> 0
A20: 7 | B20: =DV_Calc!B22 -> 0 | C20: =DV_Calc!G22 -> 0 | D20: =DV_Calc!K22 -> 0 | E20: =C20/$B$10 -> 0
A21: 8 | B21: =DV_Calc!B23 -> 0 | C21: =DV_Calc!G23 -> 0 | D21: =DV_Calc!K23 -> 0 | E21: =C21/$B$10 -> 0
D22: Total gas moles: | E22: =SUM(E14:E21) -> 0
A24: BLOCK C — COMPONENT MATERIAL BALANCE (Recombined vs Reservoir Fluid Input)
A25: # | B25: Code | C25: Component | D25: MW | E25: STO Mol% | F25: Cum Gas Mol% (recomb) | G25: Total moles (lbmol) | H25: Recomb Mol% | I25: Reservoir Mol% (input) | J25: Dev % | K25: Status
A26: 1 | B26: H2 | C26: Hydrogen | D26: =Component_Properties!D5 -> 2.016 | E26: =Compositions_Master!X8 -> 0 | F26: =IF(SUM($E$14:$E$21)=0,0,(Compositions_Master!H8*$E$14+Compositions_Master!J8*$E$15+Compositions_Master!L8*$E$16+Compositions_Master!N8*$E$17+Compositions_Master!P8*$E$18+Compositions_Master!R8*$E$19+Compositions_Master!T8*$E$20+Compositions_Master!V8*$E$21)/SUM($E$14:$E$21)) -> 0 | G26: =$B$9*E26/100+$E$22*F26/100 -> 0 | H26: =IF(SUM($G$26:$G$77)=0,0,G26/SUM($G$26:$G$77)*100) -> 0 | I26: =Compositions_Master!F8 -> 0 | J26: =IF(I26=0,IF(H26=0,0,100),ABS(H26-I26)/I26*100) -> 0 | K26: =IF(I26=0,IF(H26=0,"N/A","new"),IF(J26<=2,"PASS",IF(J26<=3,"REVIEW","FAIL"))) -> N/A
A27: 2 | B27: H2S | C27: Hydrogen Sulfide | D27: =Component_Properties!D6 -> 34.0809 | E27: =Compositions_Master!X9 -> 0 | F27: =IF(SUM($E$14:$E$21)=0,0,(Compositions_Master!H9*$E$14+Compositions_Master!J9*$E$15+Compositions_Master!L9*$E$16+Compositions_Master!N9*$E$17+Compositions_Master!P9*$E$18+Compositions_Master!R9*$E$19+Compositions_Master!T9*$E$20+Compositions_Master!V9*$E$21)/SUM($E$14:$E$21)) -> 0 | G27: =$B$9*E27/100+$E$22*F27/100 -> 0 | H27: =IF(SUM($G$26:$G$77)=0,0,G27/SUM($G$26:$G$77)*100) -> 0 | I27: =Compositions_Master!F9 -> 0 | J27: =IF(I27=0,IF(H27=0,0,100),ABS(H27-I27)/I27*100) -> 0 | K27: =IF(I27=0,IF(H27=0,"N/A","new"),IF(J27<=2,"PASS",IF(J27<=3,"REVIEW","FAIL"))) -> N/A
A28: 3 | B28: CO2 | C28: Carbon Dioxide | D28: =Component_Properties!D7 -> 44.0095 | E28: =Compositions_Master!X10 -> 0 | F28: =IF(SUM($E$14:$E$21)=0,0,(Compositions_Master!H10*$E$14+Compositions_Master!J10*$E$15+Compositions_Master!L10*$E$16+Compositions_Master!N10*$E$17+Compositions_Master!P10*$E$18+Compositions_Master!R10*$E$19+Compositions_Master!T10*$E$20+Compositions_Master!V10*$E$21)/SUM($E$14:$E$21)) -> 0 | G28: =$B$9*E28/100+$E$22*F28/100 -> 0 | H28: =IF(SUM($G$26:$G$77)=0,0,G28/SUM($G$26:$G$77)*100) -> 0 | I28: =Compositions_Master!F10 -> 0 | J28: =IF(I28=0,IF(H28=0,0,100),ABS(H28-I28)/I28*100) -> 0 | K28: =IF(I28=0,IF(H28=0,"N/A","new"),IF(J28<=2,"PASS",IF(J28<=3,"REVIEW","FAIL"))) -> N/A
A29: 4 | B29: N2 | C29: Nitrogen | D29: =Component_Properties!D8 -> 28.0134 | E29: =Compositions_Master!X11 -> 0 | F29: =IF(SUM($E$14:$E$21)=0,0,(Compositions_Master!H11*$E$14+Compositions_Master!J11*$E$15+Compositions_Master!L11*$E$16+Compositions_Master!N11*$E$17+Compositions_Master!P11*$E$18+Compositions_Master!R11*$E$19+Compositions_Master!T11*$E$20+Compositions_Master!V11*$E$21)/SUM($E$14:$E$21)) -> 0 | G29: =$B$9*E29/100+$E$22*F29/100 -> 0 | H29: =IF(SUM($G$26:$G$77)=0,0,G29/SUM($G$26:$G$77)*100) -> 0 | I29: =Compositions_Master!F11 -> 0 | J29: =IF(I29=0,IF(H29=0,0,100),ABS(H29-I29)/I29*100) -> 0 | K29: =IF(I29=0,IF(H29=0,"N/A","new"),IF(J29<=2,"PASS",IF(J29<=3,"REVIEW","FAIL"))) -> N/A
A30: 5 | B30: C1 | C30: Methane | D30: =Component_Properties!D9 -> 16.043 | E30: =Compositions_Master!X12 -> 0 | F30: =IF(SUM($E$14:$E$21)=0,0,(Compositions_Master!H12*$E$14+Compositions_Master!J12*$E$15+Compositions_Master!L12*$E$16+Compositions_Master!N12*$E$17+Compositions_Master!P12*$E$18+Compositions_Master!R12*$E$19+Compositions_Master!T12*$E$20+Compositions_Master!V12*$E$21)/SUM($E$14:$E$21)) -> 0 | G30: =$B$9*E30/100+$E$22*F30/100 -> 0 | H30: =IF(SUM($G$26:$G$77)=0,0,G30/SUM($G$26:$G$77)*100) -> 0 | I30: =Compositions_Master!F12 -> 0 | J30: =IF(I30=0,IF(H30=0,0,100),ABS(H30-I30)/I30*100) -> 0 | K30: =IF(I30=0,IF(H30=0,"N/A","new"),IF(J30<=2,"PASS",IF(J30<=3,"REVIEW","FAIL"))) -> N/A
A31: 6 | B31: C2 | C31: Ethane | D31: =Component_Properties!D10 -> 30.07 | E31: =Compositions_Master!X13 -> 0.01 | F31: =IF(SUM($E$14:$E$21)=0,0,(Compositions_Master!H13*$E$14+Compositions_Master!J13*$E$15+Compositions_Master!L13*$E$16+Compositions_Master!N13*$E$17+Compositions_Master!P13*$E$18+Compositions_Master!R13*$E$19+Compositions_Master!T13*$E$20+Compositions_Master!V13*$E$21)/SUM($E$14:$E$21)) -> 0 | G31: =$B$9*E31/100+$E$22*F31/100 -> 4.5630319e-07 | H31: =IF(SUM($G$26:$G$77)=0,0,G31/SUM($G$26:$G$77)*100) -> 0.01 | I31: =Compositions_Master!F13 -> 0 | J31: =IF(I31=0,IF(H31=0,0,100),ABS(H31-I31)/I31*100) -> 100 | K31: =IF(I31=0,IF(H31=0,"N/A","new"),IF(J31<=2,"PASS",IF(J31<=3,"REVIEW","FAIL"))) -> new
A32: 7 | B32: C3 | C32: Propane | D32: =Component_Properties!D11 -> 44.097 | E32: =Compositions_Master!X14 -> 0.07 | F32: =IF(SUM($E$14:$E$21)=0,0,(Compositions_Master!H14*$E$14+Compositions_Master!J14*$E$15+Compositions_Master!L14*$E$16+Compositions_Master!N14*$E$17+Compositions_Master!P14*$E$18+Compositions_Master!R14*$E$19+Compositions_Master!T14*$E$20+Compositions_Master!V14*$E$21)/SUM($E$14:$E$21)) -> 0 | G32: =$B$9*E32/100+$E$22*F32/100 -> 3.1941223e-06 | H32: =IF(SUM($G$26:$G$77)=0,0,G32/SUM($G$26:$G$77)*100) -> 0.07 | I32: =Compositions_Master!F14 -> 0 | J32: =IF(I32=0,IF(H32=0,0,100),ABS(H32-I32)/I32*100) -> 100 | K32: =IF(I32=0,IF(H32=0,"N/A","new"),IF(J32<=2,"PASS",IF(J32<=3,"REVIEW","FAIL"))) -> new
A33: 8 | B33: iC4 | C33: i-Butane | D33: =Component_Properties!D12 -> 58.123 | E33: =Compositions_Master!X15 -> 0.1 | F33: =IF(SUM($E$14:$E$21)=0,0,(Compositions_Master!H15*$E$14+Compositions_Master!J15*$E$15+Compositions_Master!L15*$E$16+Compositions_Master!N15*$E$17+Compositions_Master!P15*$E$18+Compositions_Master!R15*$E$19+Compositions_Master!T15*$E$20+Compositions_Master!V15*$E$21)/SUM($E$14:$E$21)) -> 0 | G33: =$B$9*E33/100+$E$22*F33/100 -> 4.5630319e-06 | H33: =IF(SUM($G$26:$G$77)=0,0,G33/SUM($G$26:$G$77)*100) -> 0.1 | I33: =Compositions_Master!F15 -> 0 | J33: =IF(I33=0,IF(H33=0,0,100),ABS(H33-I33)/I33*100) -> 100 | K33: =IF(I33=0,IF(H33=0,"N/A","new"),IF(J33<=2,"PASS",IF(J33<=3,"REVIEW","FAIL"))) -> new
A34: 9 | B34: nC4 | C34: n-Butane | D34: =Component_Properties!D13 -> 58.123 | E34: =Compositions_Master!X16 -> 0.45 | F34: =IF(SUM($E$14:$E$21)=0,0,(Compositions_Master!H16*$E$14+Compositions_Master!J16*$E$15+Compositions_Master!L16*$E$16+Compositions_Master!N16*$E$17+Compositions_Master!P16*$E$18+Compositions_Master!R16*$E$19+Compositions_Master!T16*$E$20+Compositions_Master!V16*$E$21)/SUM($E$14:$E$21)) -> 0 | G34: =$B$9*E34/100+$E$22*F34/100 -> 2.0533644e-05 | H34: =IF(SUM($G$26:$G$77)=0,0,G34/SUM($G$26:$G$77)*100) -> 0.45 | I34: =Compositions_Master!F16 -> 0 | J34: =IF(I34=0,IF(H34=0,0,100),ABS(H34-I34)/I34*100) -> 100 | K34: =IF(I34=0,IF(H34=0,"N/A","new"),IF(J34<=2,"PASS",IF(J34<=3,"REVIEW","FAIL"))) -> new
A35: 10 | B35: NeoC5 | C35: Neo-Pentane | D35: =Component_Properties!D14 -> 72.151 | E35: =Compositions_Master!X17 -> 0 | F35: =IF(SUM($E$14:$E$21)=0,0,(Compositions_Master!H17*$E$14+Compositions_Master!J17*$E$15+Compositions_Master!L17*$E$16+Compositions_Master!N17*$E$17+Compositions_Master!P17*$E$18+Compositions_Master!R17*$E$19+Compositions_Master!T17*$E$20+Compositions_Master!V17*$E$21)/SUM($E$14:$E$21)) -> 0 | G35: =$B$9*E35/100+$E$22*F35/100 -> 0 | H35: =IF(SUM($G$26:$G$77)=0,0,G35/SUM($G$26:$G$77)*100) -> 0 | I35: =Compositions_Master!F17 -> 0 | J35: =IF(I35=0,IF(H35=0,0,100),ABS(H35-I35)/I35*100) -> 0 | K35: =IF(I35=0,IF(H35=0,"N/A","new"),IF(J35<=2,"PASS",IF(J35<=3,"REVIEW","FAIL"))) -> N/A
A36: 11 | B36: iC5 | C36: i-Pentane | D36: =Component_Properties!D15 -> 72.151 | E36: =Compositions_Master!X18 -> 0.44 | F36: =IF(SUM($E$14:$E$21)=0,0,(Compositions_Master!H18*$E$14+Compositions_Master!J18*$E$15+Compositions_Master!L18*$E$16+Compositions_Master!N18*$E$17+Compositions_Master!P18*$E$18+Compositions_Master!R18*$E$19+Compositions_Master!T18*$E$20+Compositions_Master!V18*$E$21)/SUM($E$14:$E$21)) -> 0 | G36: =$B$9*E36/100+$E$22*F36/100 -> 2.007734e-05 | H36: =IF(SUM($G$26:$G$77)=0,0,G36/SUM($G$26:$G$77)*100) -> 0.44 | I36: =Compositions_Master!F18 -> 0 | J36: =IF(I36=0,IF(H36=0,0,100),ABS(H36-I36)/I36*100) -> 100 | K36: =IF(I36=0,IF(H36=0,"N/A","new"),IF(J36<=2,"PASS",IF(J36<=3,"REVIEW","FAIL"))) -> new
A37: 12 | B37: nC5 | C37: n-Pentane | D37: =Component_Properties!D16 -> 72.151 | E37: =Compositions_Master!X19 -> 0.82 | F37: =IF(SUM($E$14:$E$21)=0,0,(Compositions_Master!H19*$E$14+Compositions_Master!J19*$E$15+Compositions_Master!L19*$E$16+Compositions_Master!N19*$E$17+Compositions_Master!P19*$E$18+Compositions_Master!R19*$E$19+Compositions_Master!T19*$E$20+Compositions_Master!V19*$E$21)/SUM($E$14:$E$21)) -> 0 | G37: =$B$9*E37/100+$E$22*F37/100 -> 3.7416862e-05 | H37: =IF(SUM($G$26:$G$77)=0,0,G37/SUM($G$26:$G$77)*100) -> 0.82 | I37: =Compositions_Master!F19 -> 0 | J37: =IF(I37=0,IF(H37=0,0,100),ABS(H37-I37)/I37*100) -> 100 | K37: =IF(I37=0,IF(H37=0,"N/A","new"),IF(J37<=2,"PASS",IF(J37<=3,"REVIEW","FAIL"))) -> new
... A77: 52 | B77: C36+ | C77: Hexatriacontanes plus | D77: =Component_Properties!D56 -> 636.4 | E77: =Compositions_Master!X59 -> 5.94 | F77: =IF(SUM($E$14:$E$21)=0,0,(Compositions_Master!H59*$E$14+Compositions_Master!J59*$E$15+Compositions_Master!L59*$E$16+Compositions_Master!N59*$E$17+Compositions_Master!P59*$E$18+Compositions_Master!R59*$E$19+Compositions_Master!T59*$E$20+Compositions_Master!V59*$E$21)/SUM($E$14:$E$21)) -> 0 | G77: =$B$9*E77/100+$E$22*F77/100 -> 0.0002710441 | H77: =IF(SUM($G$26:$G$77)=0,0,G77/SUM($G$26:$G$77)*100) -> 5.94 | I77: =Compositions_Master!F59 -> 0 | J77: =IF(I77=0,IF(H77=0,0,100),ABS(H77-I77)/I77*100) -> 100 | K77: =IF(I77=0,IF(H77=0,"N/A","new"),IF(J77<=2,"PASS",IF(J77<=3,"REVIEW","FAIL"))) -> new
B78: TOTAL | E78: =SUM(E26:E77) -> 100 | F78: =SUM(F26:F77) -> 0 | G78: =SUM(G26:G77) -> 0.0045630319 | H78: =SUM(H26:H77) -> 100 | I78: =SUM(I26:I77) -> 0
A80: OVERALL MATERIAL BALANCE QC
A81: Max Dev % (any component) | B81: =MAX(J26:J77) -> 100
A82: Components PASS (≤2%) | B82: =COUNTIF(K26:K77,"PASS") -> 0
A83: Components REVIEW (2-3%) | B83: =COUNTIF(K26:K77,"REVIEW") -> 0
...

Sheet Plots
A1: DV PLOTS — Bo, Rs, rho_oil (calc), Z, gamma_g vs Pressure
A2: 5 embedded charts referencing DV_Calc data. Compare trends to identify measurement issues.
A4: DATA (linked from DV_Calc)
A5: Stage | B5: P (psia) | C5: Bo_d | D5: Rs_d | E5: rho_oil calc (MB) | F5: Z | G5: gamma_g
A6: =DV_Calc!A15 -> 1 | B6: =DV_Calc!B15 -> 1156 | C6: =DV_Calc!E15 -> 1.3308824 | D6: =DV_Calc!J15 -> 521 | E6: =DV_Calc!R15 -> 0.6856 | F6: =DV_Calc!M15 -> 1 | G6: =DV_Calc!L15 -> 0
A7: =DV_Calc!A16 -> 2 | B7: =DV_Calc!B16 -> 0 | C7: =DV_Calc!E16 -> 0 | D7: =DV_Calc!J16 -> 521 | E7: =DV_Calc!R16 -> 0 | F7: =DV_Calc!M16 -> 1 | G7: =DV_Calc!L16 -> 0.8847653
A8: =DV_Calc!A17 -> 3 | B8: =DV_Calc!B17 -> 0 | C8: =DV_Calc!E17 -> 0 | D8: =DV_Calc!J17 -> 521 | E8: =DV_Calc!R17 -> 0 | F8: =DV_Calc!M17 -> 1 | G8: =DV_Calc!L17 -> 0.92152059
A9: =DV_Calc!A18 -> 4 | B9: =DV_Calc!B18 -> 0 | C9: =DV_Calc!E18 -> 0 | D9: =DV_Calc!J18 -> 521 | E9: =DV_Calc!R18 -> 0 | F9: =DV_Calc!M18 -> 1 | G9: =DV_Calc!L18 -> 0.97527698
A10: =DV_Calc!A19 -> 5 | B10: =DV_Calc!B19 -> 0 | C10: =DV_Calc!E19 -> 0 | D10: =DV_Calc!J19 -> 521 | E10: =DV_Calc!R19 -> 0 | F10: =DV_Calc!M19 -> 1 | G10: =DV_Calc!L19 -> 1.0843268
A11: =DV_Calc!A20 -> 6 | B11: =DV_Calc!B20 -> 0 | C11: =DV_Calc!E20 -> 0 | D11: =DV_Calc!J20 -> 521 | E11: =DV_Calc!R20 -> 0 | F11: =DV_Calc!M20 -> 1 | G11: =DV_Calc!L20 -> 1.3658778
A12: =DV_Calc!A21 -> 7 | B12: =DV_Calc!B21 -> 0 | C12: =DV_Calc!E21 -> 0 | D12: =DV_Calc!J21 -> 521 | E12: =DV_Calc!R21 -> 0 | F12: =DV_Calc!M21 -> 1 | G12: =DV_Calc!L21 -> 2.3076994
A13: =DV_Calc!A22 -> 8 | B13: =DV_Calc!B22 -> 0 | C13: =DV_Calc!E22 -> 0 | D13: =DV_Calc!J22 -> 521 | E13: =DV_Calc!R22 -> 0 | F13: =DV_Calc!M22 -> 1 | G13: =DV_Calc!L22 -> 0
A14: =DV_Calc!A23 -> 9 | B14: =DV_Calc!B23 -> 0 | C14: =DV_Calc!E23 -> 0 | D14: =DV_Calc!J23 -> 521 | E14: =DV_Calc!R23 -> 0 | F14: =DV_Calc!M23 -> 1 | G14: =DV_Calc!L23 -> 0
A15: =DV_Calc!A24 -> 10 | B15: =DV_Calc!B24 -> 0 | C15: =DV_Calc!E24 -> 0 | D15: =DV_Calc!J24 -> 521 | E15: =DV_Calc!R24 -> 0 | F15: =DV_Calc!M24 -> 1 | G15: =DV_Calc!L24 -> 0
A16: =DV_Calc!A25 -> 11 | B16: =DV_Calc!B25 -> 0 | C16: =DV_Calc!E25 -> 0 | D16: =DV_Calc!J25 -> 521 | E16: =DV_Calc!R25 -> 0 | F16: =DV_Calc!M25 -> 1 | G16: =DV_Calc!L25 -> 0
A17: =DV_Calc!A26 -> 12 | B17: =DV_Calc!B26 -> 0 | C17: =DV_Calc!E26 -> 0 | D17: =DV_Calc!J26 -> 521 | E17: =DV_Calc!R26 -> 0 | F17: =DV_Calc!M26 -> 1 | G17: =DV_Calc!L26 -> 0
... A31: =DV_Calc!A40 -> 26 | B31: =DV_Calc!B40 -> 0 | C31: =DV_Calc!E40 -> 0 | D31: =DV_Calc!J40 -> 521 | E31: =DV_Calc!R40 -> 0 | F31: =DV_Calc!M40 -> 1 | G31: =DV_Calc!L40 -> 0

Sheet Report
A1: DIFFERENTIAL VAPORIZATION AT 256F — FINAL REPORT (Client Format)
A2: DV Data + Corrected to Surface Conditions + Full Compositional Analysis + Plus-Fraction Properties
A4: SAMPLE INFORMATION
A5: Client | B5: =Sample_Info!B5 -> ADNOC Onshore | D5: Sample ID | E5: =Sample_Info!B7 -> SA-372 | G5: Depth (MD ft) | H5: =Sample_Info!B8 -> 9105
A6: Well/Field | B6: =Sample_Info!E5 -> Upper Zakum | D6: Chamber No. | E6: =Sample_Info!E7 -> RF1168636 | G6: Reservoir T (F) | H6: =Sample_Info!E12 -> 256
A7: Reservoir | B7: =Sample_Info!E6 -> Kharaib-2 | D7: Fluid Type | E7: =Sample_Info!B10 -> 0 | G7: Psat (psig) | H7: =Sample_Info!B13 -> 1156
A9: DIFFERENTIAL VAPORIZATION DATA (from DV_Calc)
B10: Pressure (psia) | C10: Oil Density (g/cc, calc) | D10: Solution GOR Rs (scf/bbl) | E10: Rel Oil Vol Bo_d | F10: Rel Total Vol Bt_d | G10: Deviation Factor Z | H10: Gas FVF Bg (rcf/scf) | I10: Gas Gravity
A11: 1 | B11: =DV_Calc!B15 -> 1156 | C11: =DV_Calc!R15 -> 0.6856 | D11: =DV_Calc!J15 -> 521 | E11: =DV_Calc!E15 -> 1.3308824 | F11: =DV_Calc!O15 -> 1.3308824 | G11: =DV_Calc!M15 -> 1 | H11: =DV_Calc!N15 -> 0.017548099 | I11: =DV_Calc!L15 -> 0
A12: 2 | B12: =DV_Calc!B16 -> 0 | C12: =DV_Calc!R16 -> 0 | D12: =DV_Calc!J16 -> 521 | E12: =DV_Calc!E16 -> 0 | F12: =DV_Calc!O16 -> 0 | G12: =DV_Calc!M16 -> 1 | H12: =DV_Calc!N16 -> 0 | I12: =DV_Calc!L16 -> 0.8847653
A13: 3 | B13: =DV_Calc!B17 -> 0 | C13: =DV_Calc!R17 -> 0 | D13: =DV_Calc!J17 -> 521 | E13: =DV_Calc!E17 -> 0 | F13: =DV_Calc!O17 -> 0 | G13: =DV_Calc!M17 -> 1 | H13: =DV_Calc!N17 -> 0 | I13: =DV_Calc!L17 -> 0.92152059
A14: 4 | B14: =DV_Calc!B18 -> 0 | C14: =DV_Calc!R18 -> 0 | D14: =DV_Calc!J18 -> 521 | E14: =DV_Calc!E18 -> 0 | F14: =DV_Calc!O18 -> 0 | G14: =DV_Calc!M18 -> 1 | H14: =DV_Calc!N18 -> 0 | I14: =DV_Calc!L18 -> 0.97527698
A15: 5 | B15: =DV_Calc!B19 -> 0 | C15: =DV_Calc!R19 -> 0 | D15: =DV_Calc!J19 -> 521 | E15: =DV_Calc!E19 -> 0 | F15: =DV_Calc!O19 -> 0 | G15: =DV_Calc!M19 -> 1 | H15: =DV_Calc!N19 -> 0 | I15: =DV_Calc!L19 -> 1.0843268
A16: 6 | B16: =DV_Calc!B20 -> 0 | C16: =DV_Calc!R20 -> 0 | D16: =DV_Calc!J20 -> 521 | E16: =DV_Calc!E20 -> 0 | F16: =DV_Calc!O20 -> 0 | G16: =DV_Calc!M20 -> 1 | H16: =DV_Calc!N20 -> 0 | I16: =DV_Calc!L20 -> 1.3658778
A17: 7 | B17: =DV_Calc!B21 -> 0 | C17: =DV_Calc!R21 -> 0 | D17: =DV_Calc!J21 -> 521 | E17: =DV_Calc!E21 -> 0 | F17: =DV_Calc!O21 -> 0 | G17: =DV_Calc!M21 -> 1 | H17: =DV_Calc!N21 -> 0 | I17: =DV_Calc!L21 -> 2.3076994
A18: 8 | B18: =DV_Calc!B22 -> 0 | C18: =DV_Calc!R22 -> 0 | D18: =DV_Calc!J22 -> 521 | E18: =DV_Calc!E22 -> 0 | F18: =DV_Calc!O22 -> 0 | G18: =DV_Calc!M22 -> 1 | H18: =DV_Calc!N22 -> 0 | I18: =DV_Calc!L22 -> 0
A19: 9 | B19: =DV_Calc!B23 -> 0 | C19: =DV_Calc!R23 -> 0 | D19: =DV_Calc!J23 -> 521 | E19: =DV_Calc!E23 -> 0 | F19: =DV_Calc!O23 -> 0 | G19: =DV_Calc!M23 -> 1 | H19: =DV_Calc!N23 -> 0 | I19: =DV_Calc!L23 -> 0
A20: 10 | B20: =DV_Calc!B24 -> 0 | C20: =DV_Calc!R24 -> 0 | D20: =DV_Calc!J24 -> 521 | E20: =DV_Calc!E24 -> 0 | F20: =DV_Calc!O24 -> 0 | G20: =DV_Calc!M24 -> 1 | H20: =DV_Calc!N24 -> 0 | I20: =DV_Calc!L24 -> 0
A21: 11 | B21: =DV_Calc!B25 -> 0 | C21: =DV_Calc!R25 -> 0 | D21: =DV_Calc!J25 -> 521 | E21: =DV_Calc!E25 -> 0 | F21: =DV_Calc!O25 -> 0 | G21: =DV_Calc!M25 -> 1 | H21: =DV_Calc!N25 -> 0 | I21: =DV_Calc!L25 -> 0
A22: 12 | B22: =DV_Calc!B26 -> 0 | C22: =DV_Calc!R26 -> 0 | D22: =DV_Calc!J26 -> 521 | E22: =DV_Calc!E26 -> 0 | F22: =DV_Calc!O26 -> 0 | G22: =DV_Calc!M26 -> 1 | H22: =DV_Calc!N26 -> 0 | I22: =DV_Calc!L26 -> 0
... A36: 26 | B36: =DV_Calc!B40 -> 0 | C36: =DV_Calc!R40 -> 0 | D36: =DV_Calc!J40 -> 521 | E36: =DV_Calc!E40 -> 0 | F36: =DV_Calc!O40 -> 0 | G36: =DV_Calc!M40 -> 1 | H36: =DV_Calc!N40 -> 0 | I36: =DV_Calc!L40 -> 0
A38: DV DATA CORRECTED TO SURFACE SEPARATOR CONDITIONS
A39: Rs = Rs_fb - (Rs_db - Rs_d) x (Bo_fb / Bo_db) | Bo = Bo_d x (Bo_fb / Bo_db)
A40: Test Stage | B40: Stage Pressure (psia) | C40: Rs (scf/STB) | D40: Bo (rb/STB) | E40: Bt (rb/STB) | F40: Gas Gravity
A41: 1 | B41: =DV_Calc!B16 -> 0 | C41: =DV_Calc!P16 -> 521 | D41: =DV_Calc!Q16 -> 0 | E41: =DV_Calc!O16*DV_Calc!$E$7/DV_Calc!$E$15 -> 0 | F41: =DV_Calc!L16 -> 0.8847653
A42: 2 | B42: =DV_Calc!B17 -> 0 | C42: =DV_Calc!P17 -> 521 | D42: =DV_Calc!Q17 -> 0 | E42: =DV_Calc!O17*DV_Calc!$E$7/DV_Calc!$E$15 -> 0 | F42: =DV_Calc!L17 -> 0.92152059
A43: 3 | B43: =DV_Calc!B18 -> 0 | C43: =DV_Calc!P18 -> 521 | D43: =DV_Calc!Q18 -> 0 | E43: =DV_Calc!O18*DV_Calc!$E$7/DV_Calc!$E$15 -> 0 | F43: =DV_Calc!L18 -> 0.97527698
A44: 4 | B44: =DV_Calc!B19 -> 0 | C44: =DV_Calc!P19 -> 521 | D44: =DV_Calc!Q19 -> 0 | E44: =DV_Calc!O19*DV_Calc!$E$7/DV_Calc!$E$15 -> 0 | F44: =DV_Calc!L19 -> 1.0843268
A45: 5 | B45: =DV_Calc!B20 -> 0 | C45: =DV_Calc!P20 -> 521 | D45: =DV_Calc!Q20 -> 0 | E45: =DV_Calc!O20*DV_Calc!$E$7/DV_Calc!$E$15 -> 0 | F45: =DV_Calc!L20 -> 1.3658778
A46: 6 | B46: =DV_Calc!B21 -> 0 | C46: =DV_Calc!P21 -> 521 | D46: =DV_Calc!Q21 -> 0 | E46: =DV_Calc!O21*DV_Calc!$E$7/DV_Calc!$E$15 -> 0 | F46: =DV_Calc!L21 -> 2.3076994
A47: 7 | B47: =DV_Calc!B22 -> 0 | C47: =DV_Calc!P22 -> 521 | D47: =DV_Calc!Q22 -> 0 | E47: =DV_Calc!O22*DV_Calc!$E$7/DV_Calc!$E$15 -> 0 | F47: =DV_Calc!L22 -> 0
A48: 8 | B48: =DV_Calc!B23 -> 0 | C48: =DV_Calc!P23 -> 521 | D48: =DV_Calc!Q23 -> 0 | E48: =DV_Calc!O23*DV_Calc!$E$7/DV_Calc!$E$15 -> 0 | F48: =DV_Calc!L23 -> 0
A51: COMPOSITIONAL ANALYSIS OF RESERVOIR FLUID SAMPLE TO C36+
A52: # | B52: Code | C52: Component | D52: Reservoir Mol% | E52: Reservoir Wt% | F52: STO Mol% | G52: STO Wt%
A53: 1 | B53: H2 | C53: Hydrogen | D53: =Compositions_Master!F8 -> 0 | E53: =Compositions_Master!G8 -> 0 | F53: =Compositions_Master!X8 -> 0 | G53: =Compositions_Master!Y8 -> 0
A54: 2 | B54: H2S | C54: Hydrogen Sulfide | D54: =Compositions_Master!F9 -> 0 | E54: =Compositions_Master!G9 -> 0 | F54: =Compositions_Master!X9 -> 0 | G54: =Compositions_Master!Y9 -> 0
A55: 3 | B55: CO2 | C55: Carbon Dioxide | D55: =Compositions_Master!F10 -> 0 | E55: =Compositions_Master!G10 -> 0 | F55: =Compositions_Master!X10 -> 0 | G55: =Compositions_Master!Y10 -> 0
A56: 4 | B56: N2 | C56: Nitrogen | D56: =Compositions_Master!F11 -> 0 | E56: =Compositions_Master!G11 -> 0 | F56: =Compositions_Master!X11 -> 0 | G56: =Compositions_Master!Y11 -> 0
A57: 5 | B57: C1 | C57: Methane | D57: =Compositions_Master!F12 -> 0 | E57: =Compositions_Master!G12 -> 0 | F57: =Compositions_Master!X12 -> 0 | G57: =Compositions_Master!Y12 -> 0
A58: 6 | B58: C2 | C58: Ethane | D58: =Compositions_Master!F13 -> 0 | E58: =Compositions_Master!G13 -> 0 | F58: =Compositions_Master!X13 -> 0.01 | G58: =Compositions_Master!Y13 -> 0
...
