Workbook
Name API_Gravity: Volumetrics_Master!$B$37
Name Bo: Volumetrics_Master!$B$33
Name GOR_cc_cc: Volumetrics_Master!$B$31
Name GOR_scf_bbl: Volumetrics_Master!$B$32
Name MW_ConventionA: Recombination!$B$21
Name MW_ConventionB: Volumetrics_Master!$B$99
Name Oil_Density_60F: Volumetrics_Master!$B$36
Name Shrinkage: Volumetrics_Master!$B$34
Name wf_gas: Recombination!$B$18
Name wf_oil: Recombination!$B$19

Sheet Volumetrics_Master
A1: ATMOSPHERIC FLASH SEPARATION - WATER PUMP METHOD (v6.1)
A2: Master input page. Yellow = entries. All calcs link from here to Component_Properties, Recombination, Plus_Properties_Report.
A4: BLOCK A - PROJECT & SAMPLE INFORMATION
A5: Client | B5: ADNOC Onshore | D5: Reservoir Temperature (F) | E5: 256 | G5: Sample ID | H5: SA-372
A6: Well / Field | B6: WELL-X / Upper Zakum | D6: Reservoir Pressure (psig) | E6: 3939 | G6: Chamber / Cylinder | H6: RF1168636
A7: Sampling Depth (MD ft) | B7: 9105 | D7: Saturation Pressure (psig) | E7: 1156 | G7: Analyst | H7: M. Athif
A8: Sampling Date | B8: 2026-04-12 | D8: Fluid Type | E8: Black Oil | G8: Project No. | H8: ADRIC-PVT-2026-014
A10: BLOCK B - VOLUMETRIC MEASUREMENTS (Enter in yellow)
A11: Pump constant | B11: 1 | D11: Volume correction factor (VCF) | E11: 1
A12: Initial pump reading (cc) | B12: 50 | D12: Final pump reading (cc) | E12: 70.8945
A13: V_press (cc, computed) | B13: =(E12-B12)*B11*E11 -> 20.8945
A14: Stock tank oil volume V_sto (cc) | B14: 15.7576
A15: Oil tare weight (g) | B15: 100 | D15: Final oil + tare weight (g) | E15: 113.71
A16: m_oil (g, computed) | B16: =E15-B15 -> 13.71
A17: Gasometer factor | B17: 1 | D17: Barometric pressure (mbar) | E17: 1013.25
A18: Initial gasometer reading (cc) | B18: 500 | D18: Final gasometer reading (cc) | E18: 1458.2037
A19: V_meas gas (cc, computed) | B19: =(E18-B18)*B17 -> 958.2037
A20: Gas temperature (C) | B20: 20 | D20: Back pressure (mbar) | E20: 1
A21: Measured gas abs. pressure (mbar) | B21: 1012.25 | D21: Gas gravity (Air=1) | E21: 1.146
A22: Air density @ base (g/cc) | B22: 0.0012255
A24: BLOCK C - CALCULATED PROPERTIES (Auto, PURPLE = key results)
A25: Base pressure P_base (mbar) | B25: =E17+E20 -> 1014.25 | D25: Base temperature T_base (K, 60F) | E25: 288.7056
A26: Measured gas T (K) | B26: =B20+273.15 -> 293.15 | D26: Standard pressure (mbar) | E26: 1015.5981
A27: V_gas @ base (cc) | B27: =B19*(B21/E26)*(E25/B26) -> 940.56553
A28: Gas density @ base (g/cc) | B28: =E21*B22 -> 0.001404423
A29: Gas mass m_gas (g) | B29: =B27*B28 -> 1.3209519
A31: GOR (cc/cc) | B31: =B27/B14 -> 59.689644
A32: GOR (scf/bbl) | B32: =B31*5.61458 -> 335.13228
A33: Formation Volume Factor Bo | B33: =B13/B14 -> 1.3259951
A34: Shrinkage factor (V_sto/V_press) | B34: =B14/B13 -> 0.75415061
A35: Gas/Oil weight ratio (g/g) | B35: =B29/B16 -> 0.096349516
A36: Oil density @ 60F (g/cc) | B36: =B16/B14 -> 0.87005635
A37: API gravity | B37: =141.5/B36-131.5 -> 31.133144
A39: BLOCK D - GC COMPOSITIONS (Enter Mol% AND Wt% for Flashed Gas and Flashed Oil)
A40: # | B40: Code | C40: Component | D40: MW (KF) | E40: Gas Mol% (INPUT) | F40: Gas Wt% (INPUT) | G40: Oil Mol% (INPUT) | H40: Oil Wt% (INPUT) | I40: Norm Gas Mol% | J40: Norm Gas Wt% | K40: Norm Oil Mol% | L40: Norm Oil Wt%
A41: 1 | B41: H2 | C41: Hydrogen | D41: =Component_Properties!D5 -> 2.016 | E41: 0 | F41: 0 | G41: 0 | H41: 0 | I41: =IF(SUM($E$41:$E$92)=0,0,E41/SUM($E$41:$E$92)*100) -> 0 | J41: =IF(SUM($F$41:$F$92)=0,0,F41/SUM($F$41:$F$92)*100) -> 0 | K41: =IF(SUM($G$41:$G$92)=0,0,G41/SUM($G$41:$G$92)*100) -> 0 | L41: =IF(SUM($H$41:$H$92)=0,0,H41/SUM($H$41:$H$92)*100) -> 0
A42: 2 | B42: H2S | C42: Hydrogen Sulfide | D42: =Component_Properties!D6 -> 34.0809 | E42: 0.075 | F42: 0.078 | G42: 0 | H42: 0 | I42: =IF(SUM($E$41:$E$92)=0,0,E42/SUM($E$41:$E$92)*100) -> 0.075 | J42: =IF(SUM($F$41:$F$92)=0,0,F42/SUM($F$41:$F$92)*100) -> 0.078 | K42: =IF(SUM($G$41:$G$92)=0,0,G42/SUM($G$41:$G$92)*100) -> 0 | L42: =IF(SUM($H$41:$H$92)=0,0,H42/SUM($H$41:$H$92)*100) -> 0
A43: 3 | B43: CO2 | C43: Carbon Dioxide | D43: =Component_Properties!D7 -> 44.0095 | E43: 3.925 | F43: 5.251 | G43: 0 | H43: 0 | I43: =IF(SUM($E$41:$E$92)=0,0,E43/SUM($E$41:$E$92)*100) -> 3.925 | J43: =IF(SUM($F$41:$F$92)=0,0,F43/SUM($F$41:$F$92)*100) -> 5.251 | K43: =IF(SUM($G$41:$G$92)=0,0,G43/SUM($G$41:$G$92)*100) -> 0 | L43: =IF(SUM($H$41:$H$92)=0,0,H43/SUM($H$41:$H$92)*100) -> 0
A44: 4 | B44: N2 | C44: Nitrogen | D44: =Component_Properties!D8 -> 28.0134 | E44: 0.588 | F44: 0.501 | G44: 0 | H44: 0 | I44: =IF(SUM($E$41:$E$92)=0,0,E44/SUM($E$41:$E$92)*100) -> 0.588 | J44: =IF(SUM($F$41:$F$92)=0,0,F44/SUM($F$41:$F$92)*100) -> 0.501 | K44: =IF(SUM($G$41:$G$92)=0,0,G44/SUM($G$41:$G$92)*100) -> 0 | L44: =IF(SUM($H$41:$H$92)=0,0,H44/SUM($H$41:$H$92)*100) -> 0
A45: 5 | B45: C1 | C45: Methane | D45: =Component_Properties!D9 -> 16.043 | E45: 47.656 | F45: 23.242 | G45: 0.012 | H45: 0.001 | I45: =IF(SUM($E$41:$E$92)=0,0,E45/SUM($E$41:$E$92)*100) -> 47.656 | J45: =IF(SUM($F$41:$F$92)=0,0,F45/SUM($F$41:$F$92)*100) -> 23.242 | K45: =IF(SUM($G$41:$G$92)=0,0,G45/SUM($G$41:$G$92)*100) -> 0.012 | L45: =IF(SUM($H$41:$H$92)=0,0,H45/SUM($H$41:$H$92)*100) -> 0.001
...

Sheet Component_Properties
A1: COMPONENT PROPERTIES - KATZ-FIROOZABADI STANDARDS (52 components to C36+)
A2: Reference values from KF/GPA 2145. All properties locked (grey). Molar volume = MW/Density (cc/gmol).
A4: # | B4: Code | C4: Name | D4: MW (g/mol) | E4: Density (g/cc) | F4: Tb (R) | G4: Pc (psia) | H4: Tc (R) | I4: Molar Vol (cc/gmol)
A5: 1 | B5: H2 | C5: Hydrogen | D5: 2.016 | E5: 0.0711 | F5: 36.7 | G5: 188 | H5: 59.4 | I5: =D5/E5 -> 28.35443
A6: 2 | B6: H2S | C6: Hydrogen Sulfide | D6: 34.0809 | E6: 0.8006 | F6: 383.1 | G6: 1300 | H6: 672.4 | I6: =D6/E6 -> 42.569198
A7: 3 | B7: CO2 | C7: Carbon Dioxide | D7: 44.0095 | E7: 0.818 | F7: 350 | G7: 1071 | H7: 547.6 | I7: =D7/E7 -> 53.801345
A8: 4 | B8: N2 | C8: Nitrogen | D8: 28.0134 | E8: 0.8094 | F8: 139.3 | G8: 493 | H8: 227.2 | I8: =D8/E8 -> 34.610082
A9: 5 | B9: C1 | C9: Methane | D9: 16.043 | E9: 0.3 | F9: 200.7 | G9: 666.4 | H9: 343 | I9: =D9/E9 -> 53.476667
A10: 6 | B10: C2 | C10: Ethane | D10: 30.07 | E10: 0.3562 | F10: 332.2 | G10: 706.5 | H10: 549.6 | I10: =D10/E10 -> 84.418866
A11: 7 | B11: C3 | C11: Propane | D11: 44.097 | E11: 0.507 | F11: 415.9 | G11: 616 | H11: 665.7 | I11: =D11/E11 -> 86.976331
A12: 8 | B12: iC4 | C12: i-Butane | D12: 58.123 | E12: 0.5629 | F12: 470.6 | G12: 527.9 | H12: 734.1 | I12: =D12/E12 -> 103.25635
A13: 9 | B13: nC4 | C13: n-Butane | D13: 58.123 | E13: 0.584 | F13: 490.7 | G13: 550.6 | H13: 765.3 | I13: =D13/E13 -> 99.525685
A14: 10 | B14: NeoC5 | C14: Neo-Pentane | D14: 72.151 | E14: 0.5967 | F14: 482.6 | G14: 464 | H14: 734.6 | I14: =D14/E14 -> 120.91671
A15: 11 | B15: iC5 | C15: i-Pentane | D15: 72.151 | E15: 0.6244 | F15: 541.7 | G15: 490.4 | H15: 828.7 | I15: =D15/E15 -> 115.55253
A16: 12 | B16: nC5 | C16: n-Pentane | D16: 72.151 | E16: 0.6311 | F16: 556.6 | G16: 488.6 | H16: 845.5 | I16: =D16/E16 -> 114.32578
... A56: 52 | B56: C36+ | C56: Hexatriacontanes plus | D56: 636.4 | E56: 0.94 | F56: 1490 | G56: 80 | H56: 1700 | I56: =D56/E56 -> 677.02128

Sheet Recombination
A1: FLASH RECOMBINATION - RESERVOIR FLUID COMPOSITION FROM FLASH GAS + FLASH OIL
A2: Live-fluid technique. Mass-basis recombination: wf_gas = m_gas/(m_gas+m_oil). Mole% back-calc from wt%/MW.
A4: BLOCK A - LINKED FROM VOLUMETRICS_MASTER
A5: m_oil (g) | B5: =Volumetrics_Master!B16 -> 13.71
A6: m_gas (g) | B6: =Volumetrics_Master!B29 -> 1.3209519
A7: V_sto (cc) | B7: =Volumetrics_Master!B14 -> 15.7576
A8: V_gas @ base (cc) | B8: =Volumetrics_Master!B27 -> 940.56553
A9: GOR (cc/cc) | B9: =Volumetrics_Master!B31 -> 59.689644
A10: GOR (scf/bbl) | B10: =Volumetrics_Master!B32 -> 335.13228
A11: Oil density measured (g/cc) | B11: =Volumetrics_Master!B36 -> 0.87005635
A12: Gas gravity (Air=1) | B12: =Volumetrics_Master!E21 -> 1.146
A13: Flash Pressure (psia) | B13: 15
A14: Flash Temperature (F) | B14: 60
A15: Flash T (R) = T_F + 459.67 | B15: =B14+459.67 -> 519.67
A17: BLOCK B - MASS FRACTION CALCULATIONS
A18: wf_gas (gas mass fraction) | B18: =B6/(B5+B6) -> 0.087882117
A19: wf_oil (oil mass fraction) | B19: =1-B18 -> 0.91211788
A20: Whole sample mass (g) | B20: =B5+B6 -> 15.030952
A21: Whole Sample MW (from recomb Wt%) | B21: =IF(SUM(I25:I76)=0,0,100/SUMPRODUCT(I25:I76,1/D25:D76)) -> 135.04261
A22: Whole Sample MW (from recomb Mol%) | B22: =SUMPRODUCT(D25:D76,J25:J76)/100 -> 135.04261
A23: BLOCK C - WELLSTREAM COMPOSITION (Recombined) + K-VALUE VALIDATION
A24: # | B24: Code | C24: Component | D24: MW | E24: Gas Norm Mol% | F24: Gas Norm Wt% | G24: Oil Norm Mol% | H24: Oil Norm Wt% | I24: Recomb Wt% | J24: Recomb Mol% | K24: K = y/x | L24: log10(K*P) | M24: Hoffman F
A25: 1 | B25: =Volumetrics_Master!B41 -> H2 | C25: =Volumetrics_Master!C41 -> Hydrogen | D25: =Component_Properties!D5 -> 2.016 | E25: =Volumetrics_Master!I41 -> 0 | F25: =Volumetrics_Master!J41 -> 0 | G25: =Volumetrics_Master!K41 -> 0 | H25: =Volumetrics_Master!L41 -> 0 | I25: =$B$18*F25+$B$19*H25 -> 0 | J25: =IF(SUMPRODUCT($I$25:$I$76,1/$D$25:$D$76)=0,0,(I25/D25)/SUMPRODUCT($I$25:$I$76,1/$D$25:$D$76)*100) -> 0 | K25: =IF(G25=0,"",E25/G25) | L25: =IF(OR(K25="",K25=0),"",LOG10(K25*$B$13)) | M25: =IF(OR(Component_Properties!F5=0,Component_Properties!H5=Component_Properties!F5),"",(LOG10(Component_Properties!G5/14.7)/(1/Component_Properties!F5-1/Component_Properties!H5))*(1/Component_Properties!F5-1/$B$15)) -> 2.6917712
A26: 2 | B26: =Volumetrics_Master!B42 -> H2S | C26: =Volumetrics_Master!C42 -> Hydrogen Sulfide | D26: =Component_Properties!D6 -> 34.0809 | E26: =Volumetrics_Master!I42 -> 0.075 | F26: =Volumetrics_Master!J42 -> 0.078 | G26: =Volumetrics_Master!K42 -> 0 | H26: =Volumetrics_Master!L42 -> 0 | I26: =$B$18*F26+$B$19*H26 -> 0.0068548051 | J26: =IF(SUMPRODUCT($I$25:$I$76,1/$D$25:$D$76)=0,0,(I26/D26)/SUMPRODUCT($I$25:$I$76,1/$D$25:$D$76)*100) -> 0.027161571 | K26: =IF(G26=0,"",E26/G26) | L26: =IF(OR(K26="",K26=0),"",LOG10(K26*$B$13)) | M26: =IF(OR(Component_Properties!F6=0,Component_Properties!H6=Component_Properties!F6),"",(LOG10(Component_Properties!G6/14.7)/(1/Component_Properties!F6-1/Component_Properties!H6))*(1/Component_Properties!F6-1/$B$15)) -> 1.1890208
A27: 3 | B27: =Volumetrics_Master!B43 -> CO2 | C27: =Volumetrics_Master!C43 -> Carbon Dioxide | D27: =Component_Properties!D7 -> 44.0095 | E27: =Volumetrics_Master!I43 -> 3.925 | F27: =Volumetrics_Master!J43 -> 5.251 | G27: =Volumetrics_Master!K43 -> 0 | H27: =Volumetrics_Master!L43 -> 0 | I27: =$B$18*F27+$B$19*H27 -> 0.46146899 | J27: =IF(SUMPRODUCT($I$25:$I$76,1/$D$25:$D$76)=0,0,(I27/D27)/SUMPRODUCT($I$25:$I$76,1/$D$25:$D$76)*100) -> 1.416012 | K27: =IF(G27=0,"",E27/G27) | L27: =IF(OR(K27="",K27=0),"",LOG10(K27*$B$13)) | M27: =IF(OR(Component_Properties!F7=0,Component_Properties!H7=Component_Properties!F7),"",(LOG10(Component_Properties!G7/14.7)/(1/Component_Properties!F7-1/Component_Properties!H7))*(1/Component_Properties!F7-1/$B$15)) -> 1.6851699
A28: 4 | B28: =Volumetrics_Master!B44 -> N2 | C28: =Volumetrics_Master!C44 -> Nitrogen | D28: =Component_Properties!D8 -> 28.0134 | E28: =Volumetrics_Master!I44 -> 0.588 | F28: =Volumetrics_Master!J44 -> 0.501 | G28: =Volumetrics_Master!K44 -> 0 | H28: =Volumetrics_Master!L44 -> 0 | I28: =$B$18*F28+$B$19*H28 -> 0.04402894 | J28: =IF(SUMPRODUCT($I$25:$I$76,1/$D$25:$D$76)=0,0,(I28/D28)/SUMPRODUCT($I$25:$I$76,1/$D$25:$D$76)*100) -> 0.21224782 | K28: =IF(G28=0,"",E28/G28) | L28: =IF(OR(K28="",K28=0),"",LOG10(K28*$B$13)) | M28: =IF(OR(Component_Properties!F8=0,Component_Properties!H8=Component_Properties!F8),"",(LOG10(Component_Properties!G8/14.7)/(1/Component_Properties!F8-1/Component_Properties!H8))*(1/Component_Properties!F8-1/$B$15)) -> 2.8861487
A29: 5 | B29: =Volumetrics_Master!B45 -> C1 | C29: =Volumetrics_Master!C45 -> Methane | D29: =Component_Properties!D9 -> 16.043 | E29: =Volumetrics_Master!I45 -> 47.656 | F29: =Volumetrics_Master!J45 -> 23.242 | G29: =Volumetrics_Master!K45 -> 0.012 | H29: =Volumetrics_Master!L45 -> 0.001 | I29: =$B$18*F29+$B$19*H29 -> 2.0434683 | J29: =IF(SUMPRODUCT($I$25:$I$76,1/$D$25:$D$76)=0,0,(I29/D29)/SUMPRODUCT($I$25:$I$76,1/$D$25:$D$76)*100) -> 17.200978 | K29: =IF(G29=0,"",E29/G29) -> 3971.3333 | L29: =IF(OR(K29="",K29=0),"",LOG10(K29*$B$13)) -> 4.7750276 | M29: =IF(OR(Component_Properties!F9=0,Component_Properties!H9=Component_Properties!F9),"",(LOG10(Component_Properties!G9/14.7)/(1/Component_Properties!F9-1/Component_Properties!H9))*(1/Component_Properties!F9-1/$B$15)) -> 2.4506498
A30: 6 | B30: =Volumetrics_Master!B46 -> C2 | C30: =Volumetrics_Master!C46 -> Ethane | D30: =Component_Properties!D10 -> 30.07 | E30: =Volumetrics_Master!I46 -> 14.083 | F30: =Volumetrics_Master!J46 -> 12.874 | G30: =Volumetrics_Master!K46 -> 0.126 | H30: =Volumetrics_Master!L46 -> 0.02 | I30: =$B$18*F30+$B$19*H30 -> 1.1496367 | J30: =IF(SUMPRODUCT($I$25:$I$76,1/$D$25:$D$76)=0,0,(I30/D30)/SUMPRODUCT($I$25:$I$76,1/$D$25:$D$76)*100) -> 5.1629513 | K30: =IF(G30=0,"",E30/G30) -> 111.76984 | L30: =IF(OR(K30="",K30=0),"",LOG10(K30*$B$13)) -> 3.2244159 | M30: =IF(OR(Component_Properties!F10=0,Component_Properties!H10=Component_Properties!F10),"",(LOG10(Component_Properties!G10/14.7)/(1/Component_Properties!F10-1/Component_Properties!H10))*(1/Component_Properties!F10-1/$B$15)) -> 1.5337845
A31: 7 | B31: =Volumetrics_Master!B47 -> C3 | C31: =Volumetrics_Master!C47 -> Propane | D31: =Component_Properties!D11 -> 44.097 | E31: =Volumetrics_Master!I47 -> 14.82 | F31: =Volumetrics_Master!J47 -> 19.867 | G31: =Volumetrics_Master!K47 -> 0.939 | H31: =Volumetrics_Master!L47 -> 0.218 | I31: =$B$18*F31+$B$19*H31 -> 1.9447957 | J31: =IF(SUMPRODUCT($I$25:$I$76,1/$D$25:$D$76)=0,0,(I31/D31)/SUMPRODUCT($I$25:$I$76,1/$D$25:$D$76)*100) -> 5.9557406 | K31: =IF(G31=0,"",E31/G31) -> 15.782748 | L31: =IF(OR(K31="",K31=0),"",LOG10(K31*$B$13)) -> 2.3742739 | M31: =IF(OR(Component_Properties!F11=0,Component_Properties!H11=Component_Properties!F11),"",(LOG10(Component_Properties!G11/14.7)/(1/Component_Properties!F11-1/Component_Properties!H11))*(1/Component_Properties!F11-1/$B$15)) -> 0.86327996
A32: 8 | B32: =Volumetrics_Master!B48 -> iC4 | C32: =Volumetrics_Master!C48 -> i-Butane | D32: =Component_Properties!D12 -> 58.123 | E32: =Volumetrics_Master!I48 -> 3.6 | F32: =Volumetrics_Master!J48 -> 6.361 | G32: =Volumetrics_Master!K48 -> 0.765 | H32: =Volumetrics_Master!L48 -> 0.234 | I32: =$B$18*F32+$B$19*H32 -> 0.77245373 | J32: =IF(SUMPRODUCT($I$25:$I$76,1/$D$25:$D$76)=0,0,(I32/D32)/SUMPRODUCT($I$25:$I$76,1/$D$25:$D$76)*100) -> 1.7947141 | K32: =IF(G32=0,"",E32/G32) -> 4.7058824 | L32: =IF(OR(K32="",K32=0),"",LOG10(K32*$B$13)) -> 1.8487323 | M32: =IF(OR(Component_Properties!F12=0,Component_Properties!H12=Component_Properties!F12),"",(LOG10(Component_Properties!G12/14.7)/(1/Component_Properties!F12-1/Component_Properties!H12))*(1/Component_Properties!F12-1/$B$15)) -> 0.40912767
A33: 9 | B33: =Volumetrics_Master!B49 -> nC4 | C33: =Volumetrics_Master!C49 -> n-Butane | D33: =Component_Properties!D13 -> 58.123 | E33: =Volumetrics_Master!I49 -> 7.465 | F33: =Volumetrics_Master!J49 -> 13.19 | G33: =Volumetrics_Master!K49 -> 2.745 | H33: =Volumetrics_Master!L49 -> 0.84 | I33: =$B$18*F33+$B$19*H33 -> 1.9253441 | J33: =IF(SUMPRODUCT($I$25:$I$76,1/$D$25:$D$76)=0,0,(I33/D33)/SUMPRODUCT($I$25:$I$76,1/$D$25:$D$76)*100) -> 4.4733325 | K33: =IF(G33=0,"",E33/G33) -> 2.71949 | L33: =IF(OR(K33="",K33=0),"",LOG10(K33*$B$13)) -> 1.6105787 | M33: =IF(OR(Component_Properties!F13=0,Component_Properties!H13=Component_Properties!F13),"",(LOG10(Component_Properties!G13/14.7)/(1/Component_Properties!F13-1/Component_Properties!H13))*(1/Component_Properties!F13-1/$B$15)) -> 0.24446911
A34: 10 | B34: =Volumetrics_Master!B50 -> NeoC5 | C34: =Volumetrics_Master!C50 -> Neo-Pentane | D34: =Component_Properties!D14 -> 72.151 | E34: =Volumetrics_Master!I50 -> 0.033 | F34: =Volumetrics_Master!J50 -> 0.072 | G34: =Volumetrics_Master!K50 -> 0 | H34: =Volumetrics_Master!L50 -> 0 | I34: =$B$18*F34+$B$19*H34 -> 0.0063275124 | J34: =IF(SUMPRODUCT($I$25:$I$76,1/$D$25:$D$76)=0,0,(I34/D34)/SUMPRODUCT($I$25:$I$76,1/$D$25:$D$76)*100) -> 0.011842993 | K34: =IF(G34=0,"",E34/G34) | L34: =IF(OR(K34="",K34=0),"",LOG10(K34*$B$13)) | M34: =IF(OR(Component_Properties!F14=0,Component_Properties!H14=Component_Properties!F14),"",(LOG10(Component_Properties!G14/14.7)/(1/Component_Properties!F14-1/Component_Properties!H14))*(1/Component_Properties!F14-1/$B$15)) -> 0.31174901
A35: 11 | B35: =Volumetrics_Master!B51 -> iC5 | C35: =Volumetrics_Master!C51 -> i-Pentane | D35: =Component_Properties!D15 -> 72.151 | E35: =Volumetrics_Master!I51 -> 2.482 | F35: =Volumetrics_Master!J51 -> 5.443 | G35: =Volumetrics_Master!K51 -> 2.496 | H35: =Volumetrics_Master!L51 -> 0.948 | I35: =$B$18*F35+$B$19*H35 -> 1.3430301 | J35: =IF(SUMPRODUCT($I$25:$I$76,1/$D$25:$D$76)=0,0,(I35/D35)/SUMPRODUCT($I$25:$I$76,1/$D$25:$D$76)*100) -> 2.5137045 | K35: =IF(G35=0,"",E35/G35) -> 0.99439103 | L35: =IF(OR(K35="",K35=0),"",LOG10(K35*$B$13)) -> 1.1736485 | M35: =IF(OR(Component_Properties!F15=0,Component_Properties!H15=Component_Properties!F15),"",(LOG10(Component_Properties!G15/14.7)/(1/Component_Properties!F15-1/Component_Properties!H15))*(1/Component_Properties!F15-1/$B$15)) -> -0.1864527
A36: 12 | B36: =Volumetrics_Master!B52 -> nC5 | C36: =Volumetrics_Master!C52 -> n-Pentane | D36: =Component_Properties!D16 -> 72.151 | E36: =Volumetrics_Master!I52 -> 2.587 | F36: =Volumetrics_Master!J52 -> 5.675 | G36: =Volumetrics_Master!K52 -> 3.775 | H36: =Volumetrics_Master!L52 -> 1.434 | I36: =$B$18*F36+$B$19*H36 -> 1.8067081 | J36: =IF(SUMPRODUCT($I$25:$I$76,1/$D$25:$D$76)=0,0,(I36/D36)/SUMPRODUCT($I$25:$I$76,1/$D$25:$D$76)*100) -> 3.381555 | K36: =IF(G36=0,"",E36/G36) -> 0.68529801 | L36: =IF(OR(K36="",K36=0),"",LOG10(K36*$B$13)) -> 1.0119707 | M36: =IF(OR(Component_Properties!F16=0,Component_Properties!H16=Component_Properties!F16),"",(LOG10(Component_Properties!G16/14.7)/(1/Component_Properties!F16-1/Component_Properties!H16))*(1/Component_Properties!F16-1/$B$15)) -> -0.31646708
... A76: 52 | B76: =Volumetrics_Master!B92 -> C36+ | C76: =Volumetrics_Master!C92 -> Hexatriacontanes plus | D76: =Component_Properties!D56 -> 636.4 | E76: =Volumetrics_Master!I92 -> 0 | F76: =Volumetrics_Master!J92 -> 0 | G76: =Volumetrics_Master!K92 -> 4.912 | H76: =Volumetrics_Master!L92 -> 16.456 | I76: =$B$18*F76+$B$19*H76 -> 15.009812 | J76: =IF(SUMPRODUCT($I$25:$I$76,1/$D$25:$D$76)=0,0,(I76/D76)/SUMPRODUCT($I$25:$I$76,1/$D$25:$D$76)*100) -> 3.1850475 | K76: =IF(G76=0,"",E76/G76) -> 0 | L76: =IF(OR(K76="",K76=0),"",LOG10(K76*$B$13)) | M76: =IF(OR(Component_Properties!F56=0,Component_Properties!H56=Component_Properties!F56),"",(LOG10(Component_Properties!G56/14.7)/(1/Component_Properties!F56-1/Component_Properties!H56))*(1/Component_Properties!F56-1/$B$15)) -> -11.121544
B77: TOTAL | E77: =SUM(E25:E76) -> 100 | F77: =SUM(F25:F76) -> 100 | G77: =SUM(G25:G76) -> 100 | H77: =SUM(H25:H76) -> 100 | I77: =SUM(I25:I76) -> 100 | J77: =SUM(J25:J76) -> 100
B78: Recomb Total QC | I78: =IF(ABS(I77-100)<=0.5,"PASS",IF(ABS(I77-100)<=2,"REVIEW","FAIL")) -> PASS | J78: =IF(ABS(J77-100)<=0.5,"PASS",IF(ABS(J77-100)<=2,"REVIEW","FAIL")) -> PASS

Sheet Plus_Properties_Report
A1: PLUS-FRACTION PROPERTIES REPORT - C7+, C11+, C20+, C36+
A2: Two whole-sample conventions shown. Cut properties are on Recombined Reservoir Fluid basis.
A4: WHOLE SAMPLE PROPERTIES - TWO CONVENTIONS
A5: Convention A = Recombined Reservoir Fluid (gas + oil back together, mass-balance correct). Convention B = Flashed Liquid / Stock Tank Oil (gas removed, matches client-report labeling).
B6: Property | C6: Unit | D6: Convention A: Recombined Reservoir Fluid | E6: Convention B: Flashed Liquid (STO) | F6: Notes
B7: Average Molecular Weight | C7: g/mol | D7: =Recombination!B21 -> 135.04261 | E7: =Volumetrics_Master!B99 -> 192.97769 | F7: A: 100/S(w/MW). B: Flashed Liquid MW.
B8: Density @ 60 F | C8: g/cc | D8: =IF(SUMPRODUCT(Recombination!I25:I76,1/Component_Properties!E5:E56)=0,0,SUM(Recombination!I25:I76)/SUMPRODUCT(Recombination!I25:I76,1/Component_Properties!E5:E56)) -> 0.76992435 | E8: =Volumetrics_Master!B36 -> 0.87005635 | F8: A: mixture from Recomb Wt%. B: measured lab.
B9: API Gravity (from Convention B density) | C9: deg | D9: - | E9: =Volumetrics_Master!B37 -> 31.133144 | F9: 141.5/rho - 131.5 (STO)
A10: PHYSICS NOTE: Convention A (Recombined ~133.75) = total mass of gas + oil / total moles = mass-balance correct. Convention B (Flashed Liquid ~192.98) = STO alone after the gas is removed by atmospheric flash. Some lab reports label Convention B as 'Whole Sample' - this is a labeling convention, not a math error. Cut properties (C7+, C11+, C20+, C36+) below are computed on Convention A (Recombined) basis - you can verify each cut MW is HIGHER than the whole (133.75), as physically expected.
A13: CUTS SUMMARY (Recombined Reservoir Fluid basis - Convention A)
A14: Cut | B14: Property | C14: Unit | D14: Flashed Liquid | E14: Flashed Gas | F14: Recombined (Convention A)
A15: C7+ | B15: Mol% | C15: mol% | D15: =SUM(Volumetrics_Master!K57:K92) -> 79.873 | E15: =SUM(Volumetrics_Master!I57:I92) -> 0.696 | F15: =SUM(Recombination!J41:J76) -> 51.119149
B16: Wt% | C16: wt% | D16: =SUM(Volumetrics_Master!L57:L92) -> 92.134 | E16: =SUM(Volumetrics_Master!J57:J92) -> 2.263 | F16: =SUM(Recombination!I41:I76) -> 84.235946
B17: MW | C17: g/mol | D17: =IF(SUM(Volumetrics_Master!K57:K92)=0,0,SUMPRODUCT(Volumetrics_Master!D57:D92,Volumetrics_Master!K57:K92)/SUM(Volumetrics_Master!K57:K92)) -> 222.90246 | E17: =IF(SUM(Volumetrics_Master!I57:I92)=0,0,SUMPRODUCT(Volumetrics_Master!D57:D92,Volumetrics_Master!I57:I92)/SUM(Volumetrics_Master!I57:I92)) -> 107.14847 | F17: =IF(SUM(Recombination!J41:J76)=0,0,SUMPRODUCT(Recombination!D41:D76,Recombination!J41:J76)/SUM(Recombination!J41:J76)) -> 222.52801
B18: Density | C18: g/cc | D18: =IF(SUMPRODUCT(Volumetrics_Master!L57:L92,1/Component_Properties!E21:E56)=0,0,SUM(Volumetrics_Master!L57:L92)/SUMPRODUCT(Volumetrics_Master!L57:L92,1/Component_Properties!E21:E56)) -> 0.84686621 | E18: =IF(SUMPRODUCT(Volumetrics_Master!J57:J92,1/Component_Properties!E21:E56)=0,0,SUM(Volumetrics_Master!J57:J92)/SUMPRODUCT(Volumetrics_Master!J57:J92,1/Component_Properties!E21:E56)) -> 0.74984104 | F18: =IF(SUMPRODUCT(Recombination!I41:I76,1/Component_Properties!E21:E56)=0,0,SUM(Recombination!I41:I76)/SUMPRODUCT(Recombination!I41:I76,1/Component_Properties!E21:E56)) -> 0.84660758
A20: C11+ | B20: Mol% | C20: mol% | D20: =SUM(Volumetrics_Master!K67:K92) -> 49.83 | E20: =SUM(Volumetrics_Master!I67:I92) -> 0.013 | F20: =SUM(Recombination!J51:J76) -> 31.391596
B21: Wt% | C21: wt% | D21: =SUM(Volumetrics_Master!L67:L92) -> 73.54 | E21: =SUM(Volumetrics_Master!J67:J92) -> 0.059 | F21: =SUM(Recombination!I51:I76) -> 67.082334
B22: MW | C22: g/mol | D22: =IF(SUM(Volumetrics_Master!K67:K92)=0,0,SUMPRODUCT(Volumetrics_Master!D67:D92,Volumetrics_Master!K67:K92)/SUM(Volumetrics_Master!K67:K92)) -> 286.4115 | E22: =IF(SUM(Volumetrics_Master!I67:I92)=0,0,SUMPRODUCT(Volumetrics_Master!D67:D92,Volumetrics_Master!I67:I92)/SUM(Volumetrics_Master!I67:I92)) -> 161.38462 | F22: =IF(SUM(Recombination!J51:J76)=0,0,SUMPRODUCT(Recombination!D51:D76,Recombination!J51:J76)/SUM(Recombination!J51:J76)) -> 288.57958
B23: Density | C23: g/cc | D23: =IF(SUMPRODUCT(Volumetrics_Master!L67:L92,1/Component_Properties!E31:E56)=0,0,SUM(Volumetrics_Master!L67:L92)/SUMPRODUCT(Volumetrics_Master!L67:L92,1/Component_Properties!E31:E56)) -> 0.86936671 | E23: =IF(SUMPRODUCT(Volumetrics_Master!J67:J92,1/Component_Properties!E31:E56)=0,0,SUM(Volumetrics_Master!J67:J92)/SUMPRODUCT(Volumetrics_Master!J67:J92,1/Component_Properties!E31:E56)) -> 0.79325196 | F23: =IF(SUMPRODUCT(Recombination!I51:I76,1/Component_Properties!E31:E56)=0,0,SUM(Recombination!I51:I76)/SUMPRODUCT(Recombination!I51:I76,1/Component_Properties!E31:E56)) -> 0.86936026
A25: C20+ | B25: Mol% | C25: mol% | D25: =SUM(Volumetrics_Master!K76:K92) -> 18.73 | E25: =SUM(Volumetrics_Master!I76:I92) -> 0 | F25: =SUM(Recombination!J60:J76) -> 11.98759
B26: Wt% | C26: wt% | D26: =SUM(Volumetrics_Master!L76:L92) -> 42.073 | E26: =SUM(Volumetrics_Master!J76:J92) -> 0 | F26: =SUM(Recombination!I60:I76) -> 38.375536
B27: MW | C27: g/mol | D27: =IF(SUM(Volumetrics_Master!K76:K92)=0,0,SUMPRODUCT(Volumetrics_Master!D76:D92,Volumetrics_Master!K76:K92)/SUM(Volumetrics_Master!K76:K92)) -> 431.22279 | E27: =IF(SUM(Volumetrics_Master!I76:I92)=0,0,SUMPRODUCT(Volumetrics_Master!D76:D92,Volumetrics_Master!I76:I92)/SUM(Volumetrics_Master!I76:I92)) -> 0 | F27: =IF(SUM(Recombination!J60:J76)=0,0,SUMPRODUCT(Recombination!D60:D76,Recombination!J60:J76)/SUM(Recombination!J60:J76)) -> 432.30812
B28: Density | C28: g/cc | D28: =IF(SUMPRODUCT(Volumetrics_Master!L76:L92,1/Component_Properties!E40:E56)=0,0,SUM(Volumetrics_Master!L76:L92)/SUMPRODUCT(Volumetrics_Master!L76:L92,1/Component_Properties!E40:E56)) -> 0.90735313 | E28: =IF(SUMPRODUCT(Volumetrics_Master!J76:J92,1/Component_Properties!E40:E56)=0,0,SUM(Volumetrics_Master!J76:J92)/SUMPRODUCT(Volumetrics_Master!J76:J92,1/Component_Properties!E40:E56)) -> 0 | F28: =IF(SUMPRODUCT(Recombination!I60:I76,1/Component_Properties!E40:E56)=0,0,SUM(Recombination!I60:I76)/SUMPRODUCT(Recombination!I60:I76,1/Component_Properties!E40:E56)) -> 0.90735313
A30: C36+ | B30: Mol% | C30: mol% | D30: =SUM(Volumetrics_Master!K92:K92) -> 4.912 | E30: =SUM(Volumetrics_Master!I92:I92) -> 0 | F30: =SUM(Recombination!J76:J76) -> 3.1850475
B31: Wt% | C31: wt% | D31: =SUM(Volumetrics_Master!L92:L92) -> 16.456 | E31: =SUM(Volumetrics_Master!J92:J92) -> 0 | F31: =SUM(Recombination!I76:I76) -> 15.009812
B32: MW | C32: g/mol | D32: =IF(SUM(Volumetrics_Master!K92:K92)=0,0,SUMPRODUCT(Volumetrics_Master!D92:D92,Volumetrics_Master!K92:K92)/SUM(Volumetrics_Master!K92:K92)) -> 636.4 | E32: =IF(SUM(Volumetrics_Master!I92:I92)=0,0,SUMPRODUCT(Volumetrics_Master!D92:D92,Volumetrics_Master!I92:I92)/SUM(Volumetrics_Master!I92:I92)) -> 0 | F32: =IF(SUM(Recombination!J76:J76)=0,0,SUMPRODUCT(Recombination!D76:D76,Recombination!J76:J76)/SUM(Recombination!J76:J76)) -> 636.4
B33: Density | C33: g/cc | D33: =IF(SUMPRODUCT(Volumetrics_Master!L92:L92,1/Component_Properties!E56:E56)=0,0,SUM(Volumetrics_Master!L92:L92)/SUMPRODUCT(Volumetrics_Master!L92:L92,1/Component_Properties!E56:E56)) -> 0.94 | E33: =IF(SUMPRODUCT(Volumetrics_Master!J92:J92,1/Component_Properties!E56:E56)=0,0,SUM(Volumetrics_Master!J92:J92)/SUMPRODUCT(Volumetrics_Master!J92:J92,1/Component_Properties!E56:E56)) -> 0 | F33: =IF(SUMPRODUCT(Recombination!I76:I76,1/Component_Properties!E56:E56)=0,0,SUM(Recombination!I76:I76)/SUMPRODUCT(Recombination!I76:I76,1/Component_Properties!E56:E56)) -> 0.94
A36: KEY DELIVERABLES (Linked from other sheets)
A38: GOR (cc/cc) | D38: =Volumetrics_Master!B31 -> 59.689644
A39: GOR (scf/bbl) | D39: =Volumetrics_Master!B32 -> 335.13228
A40: Formation Volume Factor Bo | D40: =Volumetrics_Master!B33 -> 1.3259951
A41: Shrinkage factor | D41: =Volumetrics_Master!B34 -> 0.75415061
A42: Oil density @ 60F (g/cc, measured) | D42: =Volumetrics_Master!B36 -> 0.87005635
A43: API gravity | D43: =Volumetrics_Master!B37 -> 31.133144
A44: Gas gravity (Air=1) | D44: =Volumetrics_Master!E21 -> 1.146
A45: Gas MW (from Mol%) | D45: =Volumetrics_Master!B97 -> 32.895962
A46: Oil MW (from Mol%) - Convention B | D46: =Volumetrics_Master!B99 -> 192.97769
A47: Whole Sample MW (Convention A) | D47: =Recombination!B21 -> 135.04261
A48: wf_gas (mass fraction) | D48: =Recombination!B18 -> 0.087882117
A49: wf_oil (mass fraction) | D49: =Recombination!B19 -> 0.91211788
