Workbook
Name ActualGOR: Loading_Volumes!$B$47
Name Fgas: Recombination!$B$29
Name Foil: Recombination!$B$30
Name GasChargeVol: Loading_Volumes!$B$32
Name GOR_input: Recombination!$B$5
Name GOR_type: Recombination!$B$6
Name OilChargeVol: Loading_Volumes!$B$22
Name TargetGOR: Recombination!$B$8
Name WellstreamMW: Recombination!$B$33

Sheet Sample_Info
A1: ADRIC — LIVE OIL PREPARATION CALCULATION (v4.1, MG-0180 methodology, live formulas + physics notes)
A2: Recombine STO + Gas at target GOR to prepare live reservoir fluid. Component properties from Katz-Firoozabadi.
A4: BLOCK A — PROJECT & SAMPLE INFORMATION
A5: Company / Client | B5: ADNOC Onshore | D5: Field | E5: Upper Zakum
A6: Well | B6: WELL-X | D6: Reservoir | E6: Kharaib-2
A7: Sample ID | B7: SA-372 | D7: Chamber / Cylinder No. | E7: RF1168636
A8: Sampling Depth (MD ft) | B8: 9105 | D8: Sampling Date | E8: 2026-04-12
A9: Fluid Type | B9: Black Oil | D9: Project No. | E9: ADRIC-PVT-2026-014
A11: BLOCK B — FLUID & RESERVOIR DATA
A12: Reservoir Pressure (psig) | B12: 3939 | D12: Reservoir Temperature (°F) | E12: 256
A13: Bubble Point (psig) | B13: 1156 | D13: Density @ Psat (g/cc) | E13: 0.6856
A14: Field GOR (scf/STB) | B14: 985 | D14: Stock Tank API (°) | E14: 38.2
A16: BLOCK C — PREPARATION TEAM
A17: Analyst | B17: M. Athif | D17: Reviewer | E17: xxx
A18: Approver | B18: xxx | D18: Preparation Date | E18: 2026-07-04

Sheet STO_Composition
A1: STOCK TANK OIL — COMPOSITION & PROPERTIES (to C36+, Katz-Firoozabadi reference)
A2: KF properties (MW, Density, Tb, Pc, Tc) are LOCKED grey — reference values. C36+ MW (D65) stays editable (yellow) as it varies per sample. Enter Mol% and Wt% from GC in the yellow columns.
A4: STO PROPERTIES (Reported by lab)
A5: STO Density @ 60°F reported (g/cc) | B5: 0.8196 | D5: Water Content (vol%) | E5: 0.3 | G5: API Gravity | H5: =141.5/B5-131.5 -> 41.145193
A6: STO MW reported (g/mol) | B6: 183.66 | D6: Calc'd Density from Wt% (ideal mix) | E6: =IF(SUM(L15:L65)=0,0,100/SUMPRODUCT(L15:L65,1/E15:E65)) -> 0.82098399 | G6: Density Consistency % | H6: =IF(B5=0,0,ABS(B5-E6)/B5*100) -> 0.16886158
A7: Calc'd MW from Mol% (Σx·MW/Σx) | B7: =IF(SUM(K15:K65)=0,0,SUMPRODUCT(D15:D65,K15:K65)/SUM(K15:K65)) -> 187.05427 | D7: Calc'd MW from Wt% (100/Σ(w/MW)) | E7: =IF(SUM(L15:L65)=0,0,100/SUMPRODUCT(L15:L65,1/D15:D65)) -> 186.57764 | G7: MW Consistency % | H7: =IF(B6=0,0,ABS(B6-B7)/B6*100) -> 1.8481291
A8: C7+ MW (g/mol) | B8: =IF(SUM(K31:K65)=0,0,SUMPRODUCT(D31:D65,K31:K65)/SUM(K31:K65)) -> 223.18579 | D8: C11+ MW (g/mol) | E8: =IF(SUM(K40:K65)=0,0,SUMPRODUCT(D40:D65,K40:K65)/SUM(K40:K65)) -> 286.3012 | G8: C36+ MW (g/mol) | H8: =D65 -> 635
A9: Mol%↔Wt% max cross-check dev (%) | B9: =MAX(N15:N65) -> 4.7383353 | D9: Water QC | E9: =IF(E5<=0.5,"PASS","REVIEW") -> PASS | G9: Overall STO QC | H9: =IF(AND(B9<=5,H7<=5,H6<=5),"PASS",IF(AND(B9<=10,H7<=10,H6<=10),"REVIEW","FAIL")) -> PASS
A12: COMPOSITION TO C36+ — KF Reference Properties are locked (grey). Enter Mol% and Wt% in yellow. C36+ MW (D65) is editable.
A14: # | B14: Code | C14: Component | D14: MW (g/mol) | E14: Density (g/cc) | F14: Tb (°R) | G14: Pc (psia) | H14: Tc (°R) | I14: Mol% (INPUT) | J14: Wt% (INPUT) | K14: Norm Mol% (calc) | L14: Norm Wt% (calc) | M14: Calc'd Wt% from Mol% | N14: Dev (%)
A15: 1 | B15: H2 | C15: Hydrogen | D15: 2.016 | E15: 0.0711 | F15: 36.7 | G15: 188 | H15: 59.4 | I15: 0 | J15: 0 | K15: =IF(SUM($I$15:$I$65)=0,0,I15/SUM($I$15:$I$65)*100) -> 0 | L15: =IF(SUM($J$15:$J$65)=0,0,J15/SUM($J$15:$J$65)*100) -> 0 | M15: =IF(SUMPRODUCT($D$15:$D$65,$I$15:$I$65)=0,0,I15*D15/SUMPRODUCT($D$15:$D$65,$I$15:$I$65)*100) -> 0 | N15: =IF(J15=0,0,ABS(M15-J15)/J15*100) -> 0
A16: 2 | B16: H2S | C16: Hydrogen Sulfide | D16: 34.082 | E16: 0.8006 | F16: 383.1 | G16: 1300 | H16: 672.4 | I16: 0 | J16: 0 | K16: =IF(SUM($I$15:$I$65)=0,0,I16/SUM($I$15:$I$65)*100) -> 0 | L16: =IF(SUM($J$15:$J$65)=0,0,J16/SUM($J$15:$J$65)*100) -> 0 | M16: =IF(SUMPRODUCT($D$15:$D$65,$I$15:$I$65)=0,0,I16*D16/SUMPRODUCT($D$15:$D$65,$I$15:$I$65)*100) -> 0 | N16: =IF(J16=0,0,ABS(M16-J16)/J16*100) -> 0
A17: 3 | B17: CO2 | C17: Carbon Dioxide | D17: 44.01 | E17: 0.818 | F17: 350 | G17: 1071 | H17: 547.6 | I17: 0 | J17: 0 | K17: =IF(SUM($I$15:$I$65)=0,0,I17/SUM($I$15:$I$65)*100) -> 0 | L17: =IF(SUM($J$15:$J$65)=0,0,J17/SUM($J$15:$J$65)*100) -> 0 | M17: =IF(SUMPRODUCT($D$15:$D$65,$I$15:$I$65)=0,0,I17*D17/SUMPRODUCT($D$15:$D$65,$I$15:$I$65)*100) -> 0 | N17: =IF(J17=0,0,ABS(M17-J17)/J17*100) -> 0
A18: 4 | B18: N2 | C18: Nitrogen | D18: 28.014 | E18: 0.8094 | F18: 139.3 | G18: 493 | H18: 227.2 | I18: 0 | J18: 0 | K18: =IF(SUM($I$15:$I$65)=0,0,I18/SUM($I$15:$I$65)*100) -> 0 | L18: =IF(SUM($J$15:$J$65)=0,0,J18/SUM($J$15:$J$65)*100) -> 0 | M18: =IF(SUMPRODUCT($D$15:$D$65,$I$15:$I$65)=0,0,I18*D18/SUMPRODUCT($D$15:$D$65,$I$15:$I$65)*100) -> 0 | N18: =IF(J18=0,0,ABS(M18-J18)/J18*100) -> 0
A19: 5 | B19: C1 | C19: Methane | D19: 16.043 | E19: 0.3 | F19: 200.7 | G19: 666.4 | H19: 343 | I19: 0 | J19: 0 | K19: =IF(SUM($I$15:$I$65)=0,0,I19/SUM($I$15:$I$65)*100) -> 0 | L19: =IF(SUM($J$15:$J$65)=0,0,J19/SUM($J$15:$J$65)*100) -> 0 | M19: =IF(SUMPRODUCT($D$15:$D$65,$I$15:$I$65)=0,0,I19*D19/SUMPRODUCT($D$15:$D$65,$I$15:$I$65)*100) -> 0 | N19: =IF(J19=0,0,ABS(M19-J19)/J19*100) -> 0
A20: 6 | B20: C2 | C20: Ethane | D20: 30.07 | E20: 0.3562 | F20: 332.2 | G20: 706.5 | H20: 549.6 | I20: 0.18 | J20: 0.03 | K20: =IF(SUM($I$15:$I$65)=0,0,I20/SUM($I$15:$I$65)*100) -> 0.18125063 | L20: =IF(SUM($J$15:$J$65)=0,0,J20/SUM($J$15:$J$65)*100) -> 0.03013561 | M20: =IF(SUMPRODUCT($D$15:$D$65,$I$15:$I$65)=0,0,I20*D20/SUMPRODUCT($D$15:$D$65,$I$15:$I$65)*100) -> 0.029137032 | N20: =IF(J20=0,0,ABS(M20-J20)/J20*100) -> 2.8765589
A21: 7 | B21: C3 | C21: Propane | D21: 44.097 | E21: 0.507 | F21: 415.9 | G21: 616 | H21: 665.7 | I21: 1.65 | J21: 0.4 | K21: =IF(SUM($I$15:$I$65)=0,0,I21/SUM($I$15:$I$65)*100) -> 1.6614641 | L21: =IF(SUM($J$15:$J$65)=0,0,J21/SUM($J$15:$J$65)*100) -> 0.40180814 | M21: =IF(SUMPRODUCT($D$15:$D$65,$I$15:$I$65)=0,0,I21*D21/SUMPRODUCT($D$15:$D$65,$I$15:$I$65)*100) -> 0.39168088 | N21: =IF(J21=0,0,ABS(M21-J21)/J21*100) -> 2.0797801
A22: 8 | B22: iC4 | C22: i-Butane | D22: 58.124 | E22: 0.5629 | F22: 470.6 | G22: 527.9 | H22: 734.1 | I22: 1.2 | J22: 0.38 | K22: =IF(SUM($I$15:$I$65)=0,0,I22/SUM($I$15:$I$65)*100) -> 1.2083375 | L22: =IF(SUM($J$15:$J$65)=0,0,J22/SUM($J$15:$J$65)*100) -> 0.38171773 | M22: =IF(SUMPRODUCT($D$15:$D$65,$I$15:$I$65)=0,0,I22*D22/SUMPRODUCT($D$15:$D$65,$I$15:$I$65)*100) -> 0.37547076 | N22: =IF(J22=0,0,ABS(M22-J22)/J22*100) -> 1.191905
A23: 9 | B23: nC4 | C23: n-Butane | D23: 58.124 | E23: 0.584 | F23: 490.7 | G23: 550.6 | H23: 765.3 | I23: 3.98 | J23: 1.26 | K23: =IF(SUM($I$15:$I$65)=0,0,I23/SUM($I$15:$I$65)*100) -> 4.0076528 | L23: =IF(SUM($J$15:$J$65)=0,0,J23/SUM($J$15:$J$65)*100) -> 1.2656956 | M23: =IF(SUMPRODUCT($D$15:$D$65,$I$15:$I$65)=0,0,I23*D23/SUMPRODUCT($D$15:$D$65,$I$15:$I$65)*100) -> 1.2453114 | N23: =IF(J23=0,0,ABS(M23-J23)/J23*100) -> 1.1657653
A24: 10 | B24: Neo-C5 | C24: Neo-Pentane | D24: 72.151 | E24: 0.5967 | F24: 482.6 | G24: 464 | H24: 734.6 | I24: 0 | J24: 0 | K24: =IF(SUM($I$15:$I$65)=0,0,I24/SUM($I$15:$I$65)*100) -> 0 | L24: =IF(SUM($J$15:$J$65)=0,0,J24/SUM($J$15:$J$65)*100) -> 0 | M24: =IF(SUMPRODUCT($D$15:$D$65,$I$15:$I$65)=0,0,I24*D24/SUMPRODUCT($D$15:$D$65,$I$15:$I$65)*100) -> 0 | N24: =IF(J24=0,0,ABS(M24-J24)/J24*100) -> 0
A25: 11 | B25: iC5 | C25: i-Pentane | D25: 72.151 | E25: 0.6244 | F25: 541.7 | G25: 490.4 | H25: 828.7 | I25: 2.99 | J25: 1.18 | K25: =IF(SUM($I$15:$I$65)=0,0,I25/SUM($I$15:$I$65)*100) -> 3.0107743 | L25: =IF(SUM($J$15:$J$65)=0,0,J25/SUM($J$15:$J$65)*100) -> 1.185334 | M25: =IF(SUMPRODUCT($D$15:$D$65,$I$15:$I$65)=0,0,I25*D25/SUMPRODUCT($D$15:$D$65,$I$15:$I$65)*100) -> 1.1613227 | N25: =IF(J25=0,0,ABS(M25-J25)/J25*100) -> 1.5828197
A26: 12 | B26: nC5 | C26: n-Pentane | D26: 72.151 | E26: 0.6311 | F26: 556.6 | G26: 488.6 | H26: 845.5 | I26: 4.33 | J26: 1.7 | K26: =IF(SUM($I$15:$I$65)=0,0,I26/SUM($I$15:$I$65)*100) -> 4.3600846 | L26: =IF(SUM($J$15:$J$65)=0,0,J26/SUM($J$15:$J$65)*100) -> 1.7076846 | M26: =IF(SUMPRODUCT($D$15:$D$65,$I$15:$I$65)=0,0,I26*D26/SUMPRODUCT($D$15:$D$65,$I$15:$I$65)*100) -> 1.6817817 | N26: =IF(J26=0,0,ABS(M26-J26)/J26*100) -> 1.0716622
... A65: 51 | B65: C36+ | C65: C36+ | D65: 635 | E65: 0.94 | F65: 1490 | G65: 80 | H65: 1700 | I65: 4.69 | J65: 16.19 | K65: =IF(SUM($I$15:$I$65)=0,0,I65/SUM($I$15:$I$65)*100) -> 4.7225858 | L65: =IF(SUM($J$15:$J$65)=0,0,J65/SUM($J$15:$J$65)*100) -> 16.263184 | M65: =IF(SUMPRODUCT($D$15:$D$65,$I$15:$I$65)=0,0,I65*D65/SUMPRODUCT($D$15:$D$65,$I$15:$I$65)*100) -> 16.031935 | N65: =IF(J65=0,0,ABS(M65-J65)/J65*100) -> 0.97631091
B66: TOTAL | I66: =SUM(I15:I65) -> 99.31 | J66: =SUM(J15:J65) -> 99.55 | K66: =SUM(K15:K65) -> 100 | L66: =SUM(L15:L65) -> 100 | M66: =SUM(M15:M65) -> 100
B67: Total QC | I67: =IF(ABS(I66-100)<=0.5,"PASS",IF(ABS(I66-100)<=2,"REVIEW","FAIL")) -> REVIEW | J67: =IF(ABS(J66-100)<=0.5,"PASS",IF(ABS(J66-100)<=2,"REVIEW","FAIL")) -> PASS
A70: PHYSICS NOTE — WHAT CHANGES WHEN AN MW CHANGES
A71: Changing an MW (e.g., C36+ MW in D65) does NOT change Norm Mol% (column K) or Norm Wt% (column L) — those depend only on your GC input columns I (Mol%) and J (Wt%).
A72: The 'Calc'd Wt% from Mol%' (column M) IS a QC cross-check: it recomputes Wt% from Mol% and the current MW set. If M diverges from your input Wt% J, the Dev% (N) grows — a signal that your MW set is inconsistent with the reported composition.
A73: This is by design and is mass-conservation correct. If the lab updates C36+ MW, also request updated GC-reported Mol% and Wt% so all three stay consistent.

Sheet Gas_Composition
A1: SEPARATOR GAS — COMPOSITION & PROPERTIES (to C36+, Katz-Firoozabadi reference)
A2: KF properties (MW, Density, Tb, Pc, Tc) are LOCKED grey — reference values. C36+ MW (D65) stays editable (yellow). Enter Mol% and Wt% from gas GC in the yellow columns.
A4: GAS PROPERTIES (Reported by lab)
A5: Gas MW reported (g/mol) | B5: 25.42 | D5: Gas Gravity (γg vs air) | E5: =B5/28.964 -> 0.87764121 | G5: Gas Analysis Method | H5: GPA 2286
A6: Calc'd MW from Mol% | B6: =IF(SUM(K15:K65)=0,0,SUMPRODUCT(D15:D65,K15:K65)/SUM(K15:K65)) -> 26.102136 | D6: Calc'd MW from Wt% | E6: =IF(SUM(L15:L65)=0,0,100/SUMPRODUCT(L15:L65,1/D15:D65)) -> 31.727752 | G6: MW Consistency % | H6: =IF(B5=0,0,ABS(B5-B6)/B5*100) -> 2.6834638
A7: Calc'd Gas Density @ STC (g/cc) | B7: =B5*14.73/(1205.91*288.7056) -> 0.0010754945 | D7: Gas Density @ STC (kg/m³) | E7: =B7*1000 -> 1.0754945 | G7: Mol%↔Wt% max dev % | H7: =MAX(N15:N65) -> 1067.1545
A8: Overall Gas QC | B8: =IF(AND(H7<=5,H6<=5),"PASS",IF(AND(H7<=10,H6<=10),"REVIEW","FAIL")) -> FAIL
A12: COMPOSITION TO C36+ — KF Reference Properties are locked (grey). Enter Mol% and Wt% in yellow. C36+ MW (D65) is editable.
A14: # | B14: Code | C14: Component | D14: MW (g/mol) | E14: Density (g/cc) | F14: Tb (°R) | G14: Pc (psia) | H14: Tc (°R) | I14: Mol% (INPUT) | J14: Wt% (INPUT) | K14: Norm Mol% (calc) | L14: Norm Wt% (calc) | M14: Calc'd Wt% from Mol% | N14: Dev (%)
A15: 1 | B15: H2 | C15: Hydrogen | D15: 2.016 | E15: 0.0711 | F15: 36.7 | G15: 188 | H15: 59.4 | I15: 0 | J15: 0 | K15: =IF(SUM($I$15:$I$65)=0,0,I15/SUM($I$15:$I$65)*100) -> 0 | L15: =IF(SUM($J$15:$J$65)=0,0,J15/SUM($J$15:$J$65)*100) -> 0 | M15: =IF(SUMPRODUCT($D$15:$D$65,$I$15:$I$65)=0,0,I15*D15/SUMPRODUCT($D$15:$D$65,$I$15:$I$65)*100) -> 0 | N15: =IF(J15=0,0,ABS(M15-J15)/J15*100) -> 0
A16: 2 | B16: H2S | C16: Hydrogen Sulfide | D16: 34.082 | E16: 0.8006 | F16: 383.1 | G16: 1300 | H16: 672.4 | I16: 0 | J16: 0 | K16: =IF(SUM($I$15:$I$65)=0,0,I16/SUM($I$15:$I$65)*100) -> 0 | L16: =IF(SUM($J$15:$J$65)=0,0,J16/SUM($J$15:$J$65)*100) -> 0 | M16: =IF(SUMPRODUCT($D$15:$D$65,$I$15:$I$65)=0,0,I16*D16/SUMPRODUCT($D$15:$D$65,$I$15:$I$65)*100) -> 0 | N16: =IF(J16=0,0,ABS(M16-J16)/J16*100) -> 0
A17: 3 | B17: CO2 | C17: Carbon Dioxide | D17: 44.01 | E17: 0.818 | F17: 350 | G17: 1071 | H17: 547.6 | I17: 4.71 | J17: 3.54 | K17: =IF(SUM($I$15:$I$65)=0,0,I17/SUM($I$15:$I$65)*100) -> 4.71 | L17: =IF(SUM($J$15:$J$65)=0,0,J17/SUM($J$15:$J$65)*100) -> 3.54 | M17: =IF(SUMPRODUCT($D$15:$D$65,$I$15:$I$65)=0,0,I17*D17/SUMPRODUCT($D$15:$D$65,$I$15:$I$65)*100) -> 7.9413844 | N17: =IF(J17=0,0,ABS(M17-J17)/J17*100) -> 124.33289
A18: 4 | B18: N2 | C18: Nitrogen | D18: 28.014 | E18: 0.8094 | F18: 139.3 | G18: 493 | H18: 227.2 | I18: 0.87 | J18: 0.08 | K18: =IF(SUM($I$15:$I$65)=0,0,I18/SUM($I$15:$I$65)*100) -> 0.87 | L18: =IF(SUM($J$15:$J$65)=0,0,J18/SUM($J$15:$J$65)*100) -> 0.08 | M18: =IF(SUMPRODUCT($D$15:$D$65,$I$15:$I$65)=0,0,I18*D18/SUMPRODUCT($D$15:$D$65,$I$15:$I$65)*100) -> 0.93372357 | N18: =IF(J18=0,0,ABS(M18-J18)/J18*100) -> 1067.1545
A19: 5 | B19: C1 | C19: Methane | D19: 16.043 | E19: 0.3 | F19: 200.7 | G19: 666.4 | H19: 343 | I19: 62.51 | J19: 21.43 | K19: =IF(SUM($I$15:$I$65)=0,0,I19/SUM($I$15:$I$65)*100) -> 62.51 | L19: =IF(SUM($J$15:$J$65)=0,0,J19/SUM($J$15:$J$65)*100) -> 21.43 | M19: =IF(SUMPRODUCT($D$15:$D$65,$I$15:$I$65)=0,0,I19*D19/SUMPRODUCT($D$15:$D$65,$I$15:$I$65)*100) -> 38.420147 | N19: =IF(J19=0,0,ABS(M19-J19)/J19*100) -> 79.282069
A20: 6 | B20: C2 | C20: Ethane | D20: 30.07 | E20: 0.3562 | F20: 332.2 | G20: 706.5 | H20: 549.6 | I20: 14.17 | J20: 20.73 | K20: =IF(SUM($I$15:$I$65)=0,0,I20/SUM($I$15:$I$65)*100) -> 14.17 | L20: =IF(SUM($J$15:$J$65)=0,0,J20/SUM($J$15:$J$65)*100) -> 20.73 | M20: =IF(SUMPRODUCT($D$15:$D$65,$I$15:$I$65)=0,0,I20*D20/SUMPRODUCT($D$15:$D$65,$I$15:$I$65)*100) -> 16.324024 | N20: =IF(J20=0,0,ABS(M20-J20)/J20*100) -> 21.254106
A21: 7 | B21: C3 | C21: Propane | D21: 44.097 | E21: 0.507 | F21: 415.9 | G21: 616 | H21: 665.7 | I21: 9.98 | J21: 27.41 | K21: =IF(SUM($I$15:$I$65)=0,0,I21/SUM($I$15:$I$65)*100) -> 9.98 | L21: =IF(SUM($J$15:$J$65)=0,0,J21/SUM($J$15:$J$65)*100) -> 27.41 | M21: =IF(SUMPRODUCT($D$15:$D$65,$I$15:$I$65)=0,0,I21*D21/SUMPRODUCT($D$15:$D$65,$I$15:$I$65)*100) -> 16.860231 | N21: =IF(J21=0,0,ABS(M21-J21)/J21*100) -> 38.488758
A22: 8 | B22: iC4 | C22: i-Butane | D22: 58.124 | E22: 0.5629 | F22: 470.6 | G22: 527.9 | H22: 734.1 | I22: 1.77 | J22: 5.98 | K22: =IF(SUM($I$15:$I$65)=0,0,I22/SUM($I$15:$I$65)*100) -> 1.77 | L22: =IF(SUM($J$15:$J$65)=0,0,J22/SUM($J$15:$J$65)*100) -> 5.98 | M22: =IF(SUMPRODUCT($D$15:$D$65,$I$15:$I$65)=0,0,I22*D22/SUMPRODUCT($D$15:$D$65,$I$15:$I$65)*100) -> 3.9414199 | N22: =IF(J22=0,0,ABS(M22-J22)/J22*100) -> 34.089968
A23: 9 | B23: nC4 | C23: n-Butane | D23: 58.124 | E23: 0.584 | F23: 490.7 | G23: 550.6 | H23: 765.3 | I23: 3.25 | J23: 11.41 | K23: =IF(SUM($I$15:$I$65)=0,0,I23/SUM($I$15:$I$65)*100) -> 3.25 | L23: =IF(SUM($J$15:$J$65)=0,0,J23/SUM($J$15:$J$65)*100) -> 11.41 | M23: =IF(SUMPRODUCT($D$15:$D$65,$I$15:$I$65)=0,0,I23*D23/SUMPRODUCT($D$15:$D$65,$I$15:$I$65)*100) -> 7.2370704 | N23: =IF(J23=0,0,ABS(M23-J23)/J23*100) -> 36.572564
A24: 10 | B24: Neo-C5 | C24: Neo-Pentane | D24: 72.151 | E24: 0.5967 | F24: 482.6 | G24: 464 | H24: 734.6 | I24: 0.01 | J24: 0.05 | K24: =IF(SUM($I$15:$I$65)=0,0,I24/SUM($I$15:$I$65)*100) -> 0.01 | L24: =IF(SUM($J$15:$J$65)=0,0,J24/SUM($J$15:$J$65)*100) -> 0.05 | M24: =IF(SUMPRODUCT($D$15:$D$65,$I$15:$I$65)=0,0,I24*D24/SUMPRODUCT($D$15:$D$65,$I$15:$I$65)*100) -> 0.027641799 | N24: =IF(J24=0,0,ABS(M24-J24)/J24*100) -> 44.716403
A25: 11 | B25: iC5 | C25: i-Pentane | D25: 72.151 | E25: 0.6244 | F25: 541.7 | G25: 490.4 | H25: 828.7 | I25: 0.86 | J25: 3.2 | K25: =IF(SUM($I$15:$I$65)=0,0,I25/SUM($I$15:$I$65)*100) -> 0.86 | L25: =IF(SUM($J$15:$J$65)=0,0,J25/SUM($J$15:$J$65)*100) -> 3.2 | M25: =IF(SUMPRODUCT($D$15:$D$65,$I$15:$I$65)=0,0,I25*D25/SUMPRODUCT($D$15:$D$65,$I$15:$I$65)*100) -> 2.3771947 | N25: =IF(J25=0,0,ABS(M25-J25)/J25*100) -> 25.712666
A26: 12 | B26: nC5 | C26: n-Pentane | D26: 72.151 | E26: 0.6311 | F26: 556.6 | G26: 488.6 | H26: 845.5 | I26: 0.88 | J26: 3.2 | K26: =IF(SUM($I$15:$I$65)=0,0,I26/SUM($I$15:$I$65)*100) -> 0.88 | L26: =IF(SUM($J$15:$J$65)=0,0,J26/SUM($J$15:$J$65)*100) -> 3.2 | M26: =IF(SUMPRODUCT($D$15:$D$65,$I$15:$I$65)=0,0,I26*D26/SUMPRODUCT($D$15:$D$65,$I$15:$I$65)*100) -> 2.4324783 | N26: =IF(J26=0,0,ABS(M26-J26)/J26*100) -> 23.985054
... A65: 51 | B65: C36+ | C65: C36+ | D65: 635 | E65: 0.94 | F65: 1490 | G65: 80 | H65: 1700 | I65: 0 | J65: 0 | K65: =IF(SUM($I$15:$I$65)=0,0,I65/SUM($I$15:$I$65)*100) -> 0 | L65: =IF(SUM($J$15:$J$65)=0,0,J65/SUM($J$15:$J$65)*100) -> 0 | M65: =IF(SUMPRODUCT($D$15:$D$65,$I$15:$I$65)=0,0,I65*D65/SUMPRODUCT($D$15:$D$65,$I$15:$I$65)*100) -> 0 | N65: =IF(J65=0,0,ABS(M65-J65)/J65*100) -> 0
B66: TOTAL | I66: =SUM(I15:I65) -> 100 | J66: =SUM(J15:J65) -> 100 | K66: =SUM(K15:K65) -> 100 | L66: =SUM(L15:L65) -> 100 | M66: =SUM(M15:M65) -> 100
B67: Total QC | I67: =IF(ABS(I66-100)<=0.5,"PASS",IF(ABS(I66-100)<=2,"REVIEW","FAIL")) -> PASS | J67: =IF(ABS(J66-100)<=0.5,"PASS",IF(ABS(J66-100)<=2,"REVIEW","FAIL")) -> PASS

Sheet Recombination
A1: RECOMBINATION — WELLSTREAM COMPOSITION & K-VALUE VALIDATION
A2: MG-0180 method. K_i = y_i (gas mol%) / x_i (STO mol%). Hoffman F factor & log10(K·P) for equilibrium QC. All live formulas.
A4: BLOCK A — INPUTS
A5: GOR (scf/STB) | B5: 339
A6: GOR Type | B6: Separator
A7: Shrinkage Factor B_st (Stock Tank mode only) | B7: 1
A8: Effective GOR (scf/STB) | B8: =IF(B6="Stock Tank",B5/B7,B5) -> 339
A9: STO Density @ 60°F (linked) | B9: =STO_Composition!B5 -> 0.8196
A10: STO MW (linked, calc'd from Mol%) | B10: =STO_Composition!B7 -> 187.05427
A11: Gas MW (linked, calc'd from Mol%) | B11: =Gas_Composition!B6 -> 26.102136
A12: Z at Standard Conditions | B12: 0.99
A13: Separator Pressure (psia) [for K-value plot] | B13: 248
A14: Separator Temperature (°F) [for Hoffman F] | B14: 118
A16: BLOCK B — CONSTANTS (do not edit)
A17: R (psia·cc/mol·K) | B17: 1205.91
A18: T_std (K) [60 °F] | B18: 288.7056
A19: P_std (psia) [14.73] | B19: 14.73
A20: scf → cc conversion | B20: 28316.846
A21: STB → cc conversion | B21: 158987.29
A22: Separator T (°R) [T_F+459.67] | B22: =B14+459.67 -> 577.67
A24: BLOCK C — MOLE & MASS FRACTION CALCULATIONS
A25: GOR (cc/cc) | B25: =B8*B20/B21 -> 60.378479
A26: n_gas per cc STO (mol/cc) | B26: =B19*B25/(B12*B17*B18) -> 0.0025803559
A27: n_oil per cc STO (mol/cc) | B27: =B9/B10 -> 0.004381616
A28: Mole ratio n_gas / n_oil | B28: =B26/B27 -> 0.58890508
A29: F_gas (gas mole fraction) | B29: =B26/(B26+B27) -> 0.37063579
A30: F_oil (oil mole fraction) | B30: =1-B29 -> 0.62936421
A31: W_gas (gas mass fraction) | B31: =B29*B11/(B29*B11+B30*B10) -> 0.075937302
A32: W_oil (oil mass fraction) | B32: =1-B31 -> 0.9240627
A33: Wellstream MW (g/mol) | B33: =B29*B11+B30*B10 -> 127.39965
A35: BLOCK D — WELLSTREAM COMPOSITION + K-VALUES (Hoffman F for equilibrium QC)
A36: # | B36: Code | C36: Component | D36: MW | E36: Density | F36: Gas y_i mol% | G36: STO x_i mol% | H36: Gas y_i wt% | I36: STO x_i wt% | J36: z_i mol% | K36: z_i wt% | L36: K_i = y/x | M36: log10(K·P_sep) | N36: Hoffman F
A37: 1 | B37: =STO_Composition!B15 -> H2 | C37: =STO_Composition!C15 -> Hydrogen | D37: =STO_Composition!D15 -> 2.016 | E37: =STO_Composition!E15 -> 0.0711 | F37: =Gas_Composition!K15 -> 0 | G37: =STO_Composition!K15 -> 0 | H37: =Gas_Composition!L15 -> 0 | I37: =STO_Composition!L15 -> 0 | J37: =$B$29*F37+$B$30*G37 -> 0 | K37: =$B$31*H37+$B$32*I37 -> 0 | L37: =IF(G37=0,"",F37/G37) | M37: =IF(OR(L37="",L37=0),"",LOG10(L37*$B$13)) | N37: =IF(OR(STO_Composition!F15=0,STO_Composition!H15=0,STO_Composition!F15=STO_Composition!H15),"",(LOG10(STO_Composition!G15/14.7)/(1/STO_Composition!F15-1/STO_Composition!H15))*(1/STO_Composition!F15-1/$B$22)) -> 2.712308
A38: 2 | B38: =STO_Composition!B16 -> H2S | C38: =STO_Composition!C16 -> Hydrogen Sulfide | D38: =STO_Composition!D16 -> 34.082 | E38: =STO_Composition!E16 -> 0.8006 | F38: =Gas_Composition!K16 -> 0 | G38: =STO_Composition!K16 -> 0 | H38: =Gas_Composition!L16 -> 0 | I38: =STO_Composition!L16 -> 0 | J38: =$B$29*F38+$B$30*G38 -> 0 | K38: =$B$31*H38+$B$32*I38 -> 0 | L38: =IF(G38=0,"",F38/G38) | M38: =IF(OR(L38="",L38=0),"",LOG10(L38*$B$13)) | N38: =IF(OR(STO_Composition!F16=0,STO_Composition!H16=0,STO_Composition!F16=STO_Composition!H16),"",(LOG10(STO_Composition!G16/14.7)/(1/STO_Composition!F16-1/STO_Composition!H16))*(1/STO_Composition!F16-1/$B$22)) -> 1.5239049
A39: 3 | B39: =STO_Composition!B17 -> CO2 | C39: =STO_Composition!C17 -> Carbon Dioxide | D39: =STO_Composition!D17 -> 44.01 | E39: =STO_Composition!E17 -> 0.818 | F39: =Gas_Composition!K17 -> 4.71 | G39: =STO_Composition!K17 -> 0 | H39: =Gas_Composition!L17 -> 3.54 | I39: =STO_Composition!L17 -> 0 | J39: =$B$29*F39+$B$30*G39 -> 1.7456946 | K39: =$B$31*H39+$B$32*I39 -> 0.26881805 | L39: =IF(G39=0,"",F39/G39) | M39: =IF(OR(L39="",L39=0),"",LOG10(L39*$B$13)) | N39: =IF(OR(STO_Composition!F17=0,STO_Composition!H17=0,STO_Composition!F17=STO_Composition!H17),"",(LOG10(STO_Composition!G17/14.7)/(1/STO_Composition!F17-1/STO_Composition!H17))*(1/STO_Composition!F17-1/$B$22)) -> 2.0341936
A40: 4 | B40: =STO_Composition!B18 -> N2 | C40: =STO_Composition!C18 -> Nitrogen | D40: =STO_Composition!D18 -> 28.014 | E40: =STO_Composition!E18 -> 0.8094 | F40: =Gas_Composition!K18 -> 0.87 | G40: =STO_Composition!K18 -> 0 | H40: =Gas_Composition!L18 -> 0.08 | I40: =STO_Composition!L18 -> 0 | J40: =$B$29*F40+$B$30*G40 -> 0.32245313 | K40: =$B$31*H40+$B$32*I40 -> 0.0060749842 | L40: =IF(G40=0,"",F40/G40) | M40: =IF(OR(L40="",L40=0),"",LOG10(L40*$B$13)) | N40: =IF(OR(STO_Composition!F18=0,STO_Composition!H18=0,STO_Composition!F18=STO_Composition!H18),"",(LOG10(STO_Composition!G18/14.7)/(1/STO_Composition!F18-1/STO_Composition!H18))*(1/STO_Composition!F18-1/$B$22)) -> 2.9922722
A41: 5 | B41: =STO_Composition!B19 -> C1 | C41: =STO_Composition!C19 -> Methane | D41: =STO_Composition!D19 -> 16.043 | E41: =STO_Composition!E19 -> 0.3 | F41: =Gas_Composition!K19 -> 62.51 | G41: =STO_Composition!K19 -> 0 | H41: =Gas_Composition!L19 -> 21.43 | I41: =STO_Composition!L19 -> 0 | J41: =$B$29*F41+$B$30*G41 -> 23.168443 | K41: =$B$31*H41+$B$32*I41 -> 1.6273364 | L41: =IF(G41=0,"",F41/G41) | M41: =IF(OR(L41="",L41=0),"",LOG10(L41*$B$13)) | N41: =IF(OR(STO_Composition!F19=0,STO_Composition!H19=0,STO_Composition!F19=STO_Composition!H19),"",(LOG10(STO_Composition!G19/14.7)/(1/STO_Composition!F19-1/STO_Composition!H19))*(1/STO_Composition!F19-1/$B$22)) -> 2.6054698
A42: 6 | B42: =STO_Composition!B20 -> C2 | C42: =STO_Composition!C20 -> Ethane | D42: =STO_Composition!D20 -> 30.07 | E42: =STO_Composition!E20 -> 0.3562 | F42: =Gas_Composition!K20 -> 14.17 | G42: =STO_Composition!K20 -> 0.18125063 | H42: =Gas_Composition!L20 -> 20.73 | I42: =STO_Composition!L20 -> 0.03013561 | J42: =$B$29*F42+$B$30*G42 -> 5.3659817 | K42: =$B$31*H42+$B$32*I42 -> 1.6020275 | L42: =IF(G42=0,"",F42/G42) -> 78.179039 | M42: =IF(OR(L42="",L42=0),"",LOG10(L42*$B$13)) -> 4.287542 | N42: =IF(OR(STO_Composition!F20=0,STO_Composition!H20=0,STO_Composition!F20=STO_Composition!H20),"",(LOG10(STO_Composition!G20/14.7)/(1/STO_Composition!F20-1/STO_Composition!H20))*(1/STO_Composition!F20-1/$B$22)) -> 1.8066699
A43: 7 | B43: =STO_Composition!B21 -> C3 | C43: =STO_Composition!C21 -> Propane | D43: =STO_Composition!D21 -> 44.097 | E43: =STO_Composition!E21 -> 0.507 | F43: =Gas_Composition!K21 -> 9.98 | G43: =STO_Composition!K21 -> 1.6614641 | H43: =Gas_Composition!L21 -> 27.41 | I43: =STO_Composition!L21 -> 0.40180814 | J43: =$B$29*F43+$B$30*G43 -> 4.7446112 | K43: =$B$31*H43+$B$32*I43 -> 2.4527374 | L43: =IF(G43=0,"",F43/G43) -> 6.0067503 | M43: =IF(OR(L43="",L43=0),"",LOG10(L43*$B$13)) -> 3.1730913 | N43: =IF(OR(STO_Composition!F21=0,STO_Composition!H21=0,STO_Composition!F21=STO_Composition!H21),"",(LOG10(STO_Composition!G21/14.7)/(1/STO_Composition!F21-1/STO_Composition!H21))*(1/STO_Composition!F21-1/$B$22)) -> 1.2106697
A44: 8 | B44: =STO_Composition!B22 -> iC4 | C44: =STO_Composition!C22 -> i-Butane | D44: =STO_Composition!D22 -> 58.124 | E44: =STO_Composition!E22 -> 0.5629 | F44: =Gas_Composition!K22 -> 1.77 | G44: =STO_Composition!K22 -> 1.2083375 | H44: =Gas_Composition!L22 -> 5.98 | I44: =STO_Composition!L22 -> 0.38171773 | J44: =$B$29*F44+$B$30*G44 -> 1.4165097 | K44: =$B$31*H44+$B$32*I44 -> 0.80683618 | L44: =IF(G44=0,"",F44/G44) -> 1.4648225 | M44: =IF(OR(L44="",L44=0),"",LOG10(L44*$B$13)) -> 2.5602367 | N44: =IF(OR(STO_Composition!F22=0,STO_Composition!H22=0,STO_Composition!F22=STO_Composition!H22),"",(LOG10(STO_Composition!G22/14.7)/(1/STO_Composition!F22-1/STO_Composition!H22))*(1/STO_Composition!F22-1/$B$22)) -> 0.80307929
...

Sheet Loading_Volumes
A1: LOADING VOLUMES — CYLINDER CHARGING FOR LIVE OIL PREPARATION
A2: MG-0180 method. Change any P or T and the PURPLE charge volumes recalculate live.
A3: 🟠 AMBER inputs → drive 🟣 OIL charge volume (B22) | 🟢 TEAL inputs → drive 🟣 GAS charge volume (B32)
A4: BLOCK A — LOADING CONDITIONS (Color-coded input groups)
A5: Cylinder Volume (cc) | B5: 1000
A6: Target STO to charge into cylinder AT LOAD P&T (cc) | B6: 150
A7: 🟠 Oil Loading Pressure (psig) | B7: 2000
A8: 🟠 Oil Loading Temperature (°F) | B8: 75
A9: 🟢 Gas Loading Pressure (psig) | B9: 5000
A10: 🟢 Gas Loading Temperature (°F) | B10: 75
A11: 🟢 Z of gas at loading P&T | B11: 0.85
A12: 🟠 STO Density at loading P&T (g/cc, measured) | B12: 0.885
A13: BSW / Water content of loaded oil (vol%) | B13: 0
A15: BLOCK B — UNIT CONVERSIONS
A16: Oil Loading P (psia) | B16: =B7+14.73 -> 2014.73
A17: Gas Loading P (psia) | B17: =B9+14.73 -> 5014.73
A18: Oil Loading T (K) | B18: =(B8-32)*5/9+273.15 -> 297.03889
A19: Gas Loading T (K) | B19: =(B10-32)*5/9+273.15 -> 297.03889
A21: BLOCK C — OIL VOLUME CALCULATIONS
A22: 🟣 OIL VOLUME TO CHARGE at load P&T (cc) | B22: =B6 -> 150
A23: Equivalent STO volume at STC (cc) [mass conservation] | B23: =B22*B12/Recombination!B9 -> 161.96925
A24: Oil mass (g) | B24: =B23*Recombination!B9 -> 132.75
A25: Oil moles (mol) | B25: =B24/Recombination!B10 -> 0.70968707
A27: BLOCK D — GAS VOLUME CALCULATIONS
A28: n_gas per cc STO (linked) | B28: =Recombination!B26 -> 0.0025803559
A29: Gas moles required (mol) | B29: =B28*B23 -> 0.41793833
A30: Gas volume at STC (cc) | B30: =B29*Recombination!B12*Recombination!B17*Recombination!B18/Recombination!B19 -> 9779.4572
A31: Std cc / cc at loading P&T [PV=ZnRT ratio] | B31: =B17*Recombination!B12*Recombination!B18/(B11*B19*Recombination!B19) -> 385.39225
A32: 🟣 GAS VOLUME TO CHARGE at load P&T (cc) | B32: =B30/B31 -> 25.375335
A34: BLOCK E — LOADING SUMMARY
A35: Cylinder mix ratio (V_gas / V_oil at load) | B35: =B32/B22 -> 0.1691689
A36: Total volume required in cylinder (cc) | B36: =B22+B32 -> 175.37533
A37: Cylinder capacity (cc) | B37: =B5 -> 1000
A38: Fits in cylinder? | B38: =IF(B36<=B5*0.95,"FITS ✓","REDUCE LOADING") -> FITS ✓
A39: Cylinder utilization (%) | B39: =B36/B5*100 -> 17.537533
A41: BLOCK F — ACTUAL LOADING RECORD (Enter measured volumes)
A42: Actual STO charged at load P&T (cc) | B42: 108.96
A43: Actual Gas charged at load P&T (cc) | B43: 27.47
A44: Actual gas moles | B44: =B43*B17/(B11*Recombination!B17*B19) -> 0.45243801
A45: Actual gas volume at STC (cc) | B45: =B44*Recombination!B12*Recombination!B17*Recombination!B18/Recombination!B19 -> 10586.725
...
